Workbook

Sheet 项目预算表
A1: 关键指标 | B1: 三年合计（万元） | C1: 第1年(万元) | F1: 第2年(万元) | G1: 第3年(万元)
C2: 合计 | D2: POC前段 | E2: POC后段
A3: 平台交易总额 | B3: =SUM(C3,F3:G3) -> 26498.4 | C3: =SUM(D3:E3) -> 1002 | D3: =D31 -> 0 | E3: =E31 -> 1002 | F3: =F31 -> 4158 | G3: =G31 -> 21338.4
A4: 净收入 | B4: =SUM(C4,F4:G4) -> 4999.6981 | C4: =SUM(D4:E4) -> 189.0566 | D4: =D32 -> 0 | E4: =E32 -> 189.0566 | F4: =F32 -> 784.5283 | G4: =G32 -> 4026.1132
A5: 营业利润 | B5: =SUM(C5,F5:G5) -> -1149.8451 | C5: =C34 -> -647.72485 | D5: =D34 -> -251.07155 | E5: =E34 -> -396.65331 | F5: =F34 -> -687.39978 | G5: =G34 -> 185.27957
A6: 毛利率 | B6: =(B32-B35)/B32 -> 0.31051969 | C6: =(C32-C35)/C32 -> -1.543014 | E6: =(E32-E35)/E32 -> -0.60800898 | F6: =(F32-F35)/F32 -> 0.042652718 | G6: =(G32-G35)/G32 -> 0.44975373
A7: 净利率 | B7: =B34/B32 -> -0.2299829 | C7: =C34/C32 -> -3.4260895 | E7: =E34/E32 -> -2.0980664 | F7: =F34/F32 -> -0.87619501 | G7: =G34/G32 -> 0.046019463
A10: 关键假设 | C10: 第1年 | F10: 第2年 | G10: 第3年 | H10: 第4年
C11: 合计 | D11: POC前段 | E11: POC后段
A12: 收入仅考虑平台交易佣金，按广告主GMV计收；对外归因分析等增值技术服务暂未考虑
A13: 每个月收取广告主充值款，月末支付流量方费用；目前项目测算仅考虑moloco合作分账模式
A14: 平均日均广告请求次数（万次） | C14: =C31*1.06/(C20*365/1000) -> 145.49589 | D14: =D31*1.06/(D20*365/1000) -> 0 | E14: =E31*1.06/(E20*365/1000) -> 145.49589 | F14: =F31*1.06/(F20*365/1000) -> 402.50959 | G14: =G31*1.06/(G20*365/1000) -> 1549.2263 | H14: =H17*H18 -> 3098.4526 | I14: 预计第四年用户规模较第三年扩张1倍
A15: 黄金时段时长（小时） | C15: 14 | D15: 14 | E15: 14 | F15: 14 | G15: 14 | J15: 早8-晚10，每15分钟一次，第三年提升频次
A16: 广告间隔时长（分钟） | C16: 15 | D16: 15 | E16: 15 | F16: 10 | G16: 10
A17: 日均活跃用户数（万户） | C17: =C14/C18 -> 29.099178 | D17: =D14/D18 -> 0 | E17: =E14/E18 -> 29.099178 | F17: =F14/F18 -> 40.250959 | G17: =G14/G18 -> 154.92263 | H17: =G17*2 -> 309.84526
A18: 日均曝光次数（次） | C18: 5 | D18: 5 | E18: 5 | F18: 10 | G18: 10 | H18: 10
A19: 广告填充率 | C19: 1 | D19: 1 | E19: 1 | F19: 1 | G19: 1 | H19: 1
A20: CPM单价（元） | C20: 20 | D20: 20 | E20: 20 | F20: 30 | G20: 40 | H20: 50
A21: 平台交易佣金比例（占总流水） | C21: 0.2 | D21: 0.2 | E21: 0.2 | F21: 0.2 | G21: 0.2 | H21: 0.2
A22: 技术提供方分账比 | C22: 0.3 | D22: 0.3 | E22: 0.3 | F22: 0.3 | G22: 0.3 | H22: 0.3
A23: 市场推广费收入占比 | C23: 0.05 | D23: 0 | E23: 0 | F23: 0.05 | G23: 0.05 | H23: 0.05
A24: 团队规模（人） | C24: =C75 -> 10 | D24: =D75 -> 7 | E24: =E75 -> 10 | F24: =F75 -> 15 | G24: =G75 -> 25 | H24: =SUM(H70:H72) -> 13
A25: 其中：55万/年含社保薪酬（人） | C25: =SUM(C71:C73) -> 9 | D25: =SUM(D71:D73) -> 6 | E25: =SUM(E71:E73) -> 9 | F25: =SUM(F71:F73) -> 13 | G25: =SUM(G71:G73) -> 22 | H25: =H73 -> 20 | I25: =MID(A25,FIND("：",A25)+1,2) -> 55
A26: 40万/年含社保薪酬（人） | C26: =C74 -> 1 | D26: =D74 -> 1 | E26: =E74 -> 1 | F26: =F74 -> 2 | G26: =G74 -> 3 | H26: =H74 -> 4 | I26: =LEFT(A26,FIND("万",A26)-1) -> 40
A29: 损益项目（不含税） | B29: 三年合计（万元） | C29: 第1年(万元) | F29: 第2年(万元) | G29: 第3年(万元) | H29: 第四年(万元)
C30: 合计 | D30: POC前段 | E30: POC后段
A31: 全年收入流水(含税) | B31: =C31+F31+G31 -> 26498.4 | C31: =SUM(D31:E31) -> 1002 | D31: =SUM(月度资金计划!B4:D4)*1.06 -> 0 | E31: =SUM(月度资金计划!E4:M4)*1.06 -> 1002 | F31: =月度资金计划!AA4*1.06 -> 4158 | G31: =月度资金计划!AN4*1.06 -> 21338.4 | H31: =1780000*5% -> 89000
A32: 净收入（不含税） | B32: =C32+F32+G32 -> 4999.6981 | C32: =D32+E32 -> 189.0566 | D32: =SUM(月度资金计划!B4:D4)*D21 -> 0 | E32: =SUM(月度资金计划!E4:M4)*E21 -> 189.0566 | F32: =月度资金计划!AA4*F21 -> 784.5283 | G32: =月度资金计划!AN4*G21 -> 4026.1132 | H32: =H31*H21 -> 17800
A33: 总成本费用 | B33: =SUM(B35,B41,B44,B47) -> 6149.5432 | C33: =SUM(C35,C41,C44,C47) -> 836.78146 | D33: =SUM(D35,D41,D44,D47) -> 251.07155 | E33: =SUM(E35,E41,E44,E47) -> 585.70991 | F33: =SUM(F35,F41,F44,F47) -> 1471.9281 | G33: =SUM(G35,G41,G44,G47) -> 3840.8336 | H33: =SUM(H35,H41,H44,H47) -> 12096.9
A34: 营业利润 | B34: =B32-B33 -> -1149.8451 | C34: =C32-C33 -> -647.72485 | D34: =D32-D33 -> -251.07155 | E34: =E32-E33 -> -396.65331 | F34: =F32-F33 -> -687.39978 | G34: =G32-G33 -> 185.27957 | H34: =H32-H33 -> 5703.1004
A35: 营业成本 | B35: =B36+B37+B40 -> 3447.1934 | C35: =C36+C37+C40 -> 480.77358 | D35: =D36+D37+D40 -> 176.76887 | E35: =E36+E37+E40 -> 304.00472 | F35: =F36+F37+F40 -> 751.06604 | G35: =G36+G37+G40 -> 2215.3538 | H35: =H36+H37+H40 -> 7075.8596
A36: 1. 广告位采购成本 | B36: =C36+F36+G36 -> 94.339623 | C36: =年度运营成本测算明细!D18 -> 94.339623 | D36: =年度运营成本测算明细!D18 -> 94.339623 | E36: =年度运营成本测算明细!E18 -> 0 | F36: =年度运营成本测算明细!F18 -> 0 | G36: =年度运营成本测算明细!G18 -> 0 | H36: 0
A37: 2. 技术成本 | B37: =B38+B39 -> 1852.9443 | C37: =C38+C39 -> 329.71698 | D37: =D38+D39 -> 82.429245 | E37: =E38+E39 -> 247.28774 | F37: =F38+F39 -> 515.70755 | G37: =G38+G39 -> 1007.5198 | H37: =H38+H39 -> 1735.8596
A38: 其中：技术设备类成本 | B38: =C38+F38+G38 -> 815.09434 | C38: =D38+E38 -> 54.716981 | D38: =年度运营成本测算明细!D15 -> 13.679245 | E38: =年度运营成本测算明细!E15 -> 41.037736 | F38: =年度运营成本测算明细!F15 -> 213.20755 | G38: =年度运营成本测算明细!G15 -> 547.16981 | H38: =G38*2 -> 1094.3396
A39: 技术人员成本 | B39: =C39+F39+G39 -> 1037.85 | C39: =D39+E39 -> 275 | D39: =$I$25*E72/12*3 -> 68.75 | E39: =$I$25*E72/12*6+$I$25*F72/12*3 -> 206.25 | F39: =$I$25*F72/12*9+$I$25*G72/12*3 -> 302.5 | G39: =($I$25*G72/12*9+$I$25*H72/12*3)*1.08 -> 460.35 | H39: =$I$25*1.08*1.08*H72 -> 641.52
A40: 3. 技术平台合作分账(净收入30%) | B40: =C40+F40+G40 -> 1499.9094 | C40: =D40+E40 -> 56.716981 | D40: =D32*D22 -> 0 | E40: =E32*E22 -> 56.716981 | F40: =F32*F22 -> 235.35849 | G40: =G32*G22 -> 1207.834 | H40: =H32*H22 -> 5340 | I40: =I32*I22 -> 0
A41: 销售费用 | B41: =B42+B43 -> 1594.6321 | C41: =C42+C43 -> 151.25 | D41: =D42+D43 -> 27.5 | E41: =E42+E43 -> 123.75 | F41: =F42+F43 -> 410.47642 | G41: =G42+G43 -> 1032.9057 | H41: =H42+H43 -> 2173.04
A42: 1. 商务合作与其他运营成本 | B42: =C42+F42+G42 -> 240.53208 | C42: =D42+E42 -> 0 | D42: =D32*D23 -> 0 | E42: =E32*E23 -> 0 | F42: =F32*F23 -> 39.226415 | G42: =G32*G23 -> 201.30566 | H42: =H32*H23 -> 890
A43: 2. 商务人员成本 | B43: =C43+F43+G43 -> 1354.1 | C43: =D43+E43 -> 151.25 | D43: =$I$25*E73/12*3 -> 27.5 | E43: =$I$25*E73/12*6+$I$25*F73/12*3 -> 123.75 | F43: =$I$25*F73/12*9+$I$25*G73/12*3 -> 371.25 | G43: =($I$25*G73/12*9+$I$25*H73/12*3)*1.08 -> 831.6 | H43: =$I$25*H73*1.08*1.08 -> 1283.04
A44: 管理费用 | B44: =B45+B46 -> 1080.4071 | C44: =C45+C46 -> 204.28218 | D44: =D45+D46 -> 46.794097 | E44: =E45+E46 -> 157.48808 | F44: =F45+F46 -> 306.79284 | G44: =G45+G46 -> 569.33204
...

Sheet 月度资金计划
B1: 第一年 | O1: 第二年 | AB1: 第三年
B2: 46204 | C2: 46235 | D2: 46266 | E2: 46296 | F2: 46327 | G2: 46357 | H2: 46388 | I2: 46419 | J2: 46447 | K2: 46478 | L2: 46508 | M2: 46539 | N2: 合计 | O2: 46569 | P2: 46600 | Q2: 46631 | R2: 46661 | S2: 46692 | T2: 46722 | U2: 46753 | V2: 46784 | W2: 46813 | X2: 46844 | Y2: 46874 | Z2: 46905 | AA2: 合计 | AB2: 46935 | AC2: 46966 | AD2: 46997 | AE2: 47027 | AF2: 47058 | AG2: 47088 | AH2: 47119 | AI2: 47150 | AJ2: 47178 | AK2: 47209 | AL2: 47239 | AM2: 47270 | AN2: 合计 | AO2: 三年加总
A3: 现金流入（万元） | B3: =B4+B5 -> 1000 | C3: =C4+C5 -> 0 | D3: =D4+D5 -> 0 | E3: =E4+E5 -> 16.981132 | F3: =F4+F5 -> 33.962264 | G3: =G4+G5 -> 67.924528 | H3: =H4+H5 -> 90.566038 | I3: =I4+I5 -> 113.20755 | ... M3: =M4+M5 -> 181.13208 | N3: =SUM(B3:M3) -> 1945.283 | O3: =O4+O5 -> 1780.1887 | P3: =P4+P5 -> 288.67925 | Q3: =Q4+Q5 -> 297.16981 | R3: =R4+R5 -> 305.66038 | S3: =S4+S5 -> 314.15094 | T3: =T4+T5 -> 322.64151 | U3: =U4+U5 -> 331.13208 | V3: =V4+V5 -> 339.62264 | ... Z3: =Z4+Z5 -> 373.58491 | AA3: =SUM(O3:Z3) -> 5422.6415 | AB3: =AB4+AB5 -> 1543.3962 | AC3: =AC4+AC5 -> 701.88679 | AD3: =AD4+AD5 -> 860.37736 | AE3: =AE4+AE5 -> 1018.8679 | AF3: =AF4+AF5 -> 1245.283 | AG3: =AG4+AG5 -> 1471.6981 | AH3: =AH4+AH5 -> 1698.1132 | AI3: =AI4+AI5 -> 1924.5283 | ... AM3: =AM4+AM5 -> 3421.1321 | AN3: =SUM(AB3:AM3) -> 21130.566 | AO3: =N3+AA3+AN3 -> 28498.491
A4: 1. 自有业务流量程序化广告收入流入 | E4: =E36*E37*30/1000/1.06 -> 16.981132 | F4: =F36*F37*30/1000/1.06 -> 33.962264 | G4: =G36*G37*30/1000/1.06 -> 67.924528 | H4: =H36*H37*30/1000/1.06 -> 90.566038 | I4: =I36*I37*30/1000/1.06 -> 113.20755 | J4: =J36*J37*30/1000/1.06 -> 130.18868 | K4: =K36*K37*30/1000/1.06 -> 147.16981 | L4: =L36*L37*30/1000/1.06 -> 164.15094 | M4: =M36*M37*30/1000/1.06 -> 181.13208 | N4: =SUM(B4:M4) -> 945.28302 | O4: =O36*O37*30/1000/1.06 -> 280.18868 | P4: =P36*P37*30/1000/1.06 -> 288.67925 | Q4: =Q36*Q37*30/1000/1.06 -> 297.16981 | R4: =R36*R37*30/1000/1.06 -> 305.66038 | S4: =S36*S37*30/1000/1.06 -> 314.15094 | T4: =T36*T37*30/1000/1.06 -> 322.64151 | U4: =U36*U37*30/1000/1.06 -> 331.13208 | V4: =V36*V37*30/1000/1.06 -> 339.62264 | ... Z4: =Z36*Z37*30/1000/1.06 -> 373.58491 | AA4: =SUM(O4:Z4) -> 3922.6415 | AB4: =AB36*AB37*30/1000/1.06 -> 543.39623 | AC4: =AC36*AC37*30/1000/1.06 -> 701.88679 | AD4: =AD36*AD37*30/1000/1.06 -> 860.37736 | AE4: =AE36*AE37*30/1000/1.06 -> 1018.8679 | AF4: =AF36*AF37*30/1000/1.06 -> 1245.283 | AG4: =AG36*AG37*30/1000/1.06 -> 1471.6981 | AH4: =AH36*AH37*30/1000/1.06 -> 1698.1132 | AI4: =AI36*AI37*30/1000/1.06 -> 1924.5283 | ... AM4: =AM36*AM37*30/1000/1.06 -> 3421.1321 | AN4: =SUM(AB4:AM4) -> 20130.566 | AO4: =N4+AA4+AN4 -> 24998.491 | AP4: =AO4*1.06 -> 26498.4
A5: 2. 创新项目资金流入 | B5: 1000 | N5: =SUM(B5:M5) -> 1000 | O5: 1500 | AA5: =SUM(O5:Z5) -> 1500 | AB5: 1000 | AN5: =SUM(AB5:AM5) -> 1000 | AO5: =N5+AA5+AN5 -> 3500
A6: 现金流出（万元） | B6: =SUM(B7,B12,B17,B19,B22,B27) -> 58.883922 | C6: =SUM(C7,C12,C17,C19,C22,C27) -> 58.883922 | D6: =SUM(D7,D12,D17,D19,D22,D27) -> 60.65279 | E6: =SUM(E7,E12,E17,E19,E22,E27) -> 73.487695 | F6: =SUM(F7,F12,F17,F19,F22,F27) -> 88.091469 | G6: =SUM(G7,G12,G17,G19,G22,G27) -> 117.29902 | H6: =SUM(H7,H12,H17,H19,H22,H27) -> 137.10061 | I6: =SUM(I7,I12,I17,I19,I22,I27) -> 156.57231 | ... M6: =SUM(M7,M12,M17,M19,M22,M27) -> 237.27907 | N6: =SUM(B6:M6) -> 1592.5322 | O6: =SUM(O7,O12,O17,O19,O22,O27) -> 331.3428 | P6: =SUM(P7,P12,P17,P19,P22,P27) -> 338.72959 | Q6: =SUM(Q7,Q12,Q17,Q19,Q22,Q27) -> 346.11638 | R6: =SUM(R7,R12,R17,R19,R22,R27) -> 353.50318 | S6: =SUM(S7,S12,S17,S19,S22,S27) -> 360.88997 | T6: =SUM(T7,T12,T17,T19,T22,T27) -> 368.27676 | U6: =SUM(U7,U12,U17,U19,U22,U27) -> 375.66355 | V6: =SUM(V7,V12,V17,V19,V22,V27) -> 383.05035 | ... Z6: =SUM(Z7,Z12,Z17,Z19,Z22,Z27) -> 458.43085 | AA6: =SUM(O6:Z6) -> 4606.4485 | AB6: =SUM(AB7,AB12,AB17,AB19,AB22,AB27) -> 688.64819 | AC6: =SUM(AC7,AC12,AC17,AC19,AC22,AC27) -> 784.08215 | AD6: =SUM(AD7,AD12,AD17,AD19,AD22,AD27) -> 921.96894 | AE6: =SUM(AE7,AE12,AE17,AE19,AE22,AE27) -> 1059.8557 | AF6: =SUM(AF7,AF12,AF17,AF19,AF22,AF27) -> 1256.8369 | AG6: =SUM(AG7,AG12,AG17,AG19,AG22,AG27) -> 1524.5727 | AH6: =SUM(AH7,AH12,AH17,AH19,AH22,AH27) -> 1650.7991 | AI6: =SUM(AI7,AI12,AI17,AI19,AI22,AI27) -> 1847.7803 | ... AM6: =SUM(AM7,AM12,AM17,AM19,AM22,AM27) -> 3237.6774 | AN6: =SUM(AB6:AM6) -> 19922.044 | AO6: =N6+AA6+AN6 -> 26121.025
A7: 一、人力成本流出 | B7: =SUM(B8:B11) -> 44.583333 | C7: =SUM(C8:C11) -> 44.583333 | D7: =SUM(D8:D11) -> 44.583333 | E7: =SUM(E8:E11) -> 44.583333 | F7: =SUM(F8:F11) -> 44.583333 | G7: =SUM(G8:G11) -> 44.583333 | H7: =SUM(H8:H11) -> 44.583333 | I7: =SUM(I8:I11) -> 44.583333 | ... M7: =SUM(M8:M11) -> 66.25 | N7: =SUM(B7:M7) -> 600 | O7: =SUM(O8:O11) -> 66.25 | P7: =SUM(P8:P11) -> 66.25 | Q7: =SUM(Q8:Q11) -> 66.25 | R7: =SUM(R8:R11) -> 66.25 | S7: =SUM(S8:S11) -> 66.25 | T7: =SUM(T8:T11) -> 66.25 | U7: =SUM(U8:U11) -> 66.25 | V7: =SUM(V8:V11) -> 66.25 | ... Z7: =SUM(Z8:Z11) -> 110.83333 | AA7: =SUM(O7:Z7) -> 928.75 | AB7: =SUM(AB8:AB11) -> 119.7 | AC7: =SUM(AC8:AC11) -> 119.7 | AD7: =SUM(AD8:AD11) -> 119.7 | AE7: =SUM(AE8:AE11) -> 119.7 | AF7: =SUM(AF8:AF11) -> 119.7 | AG7: =SUM(AG8:AG11) -> 119.7 | AH7: =SUM(AH8:AH11) -> 119.7 | AI7: =SUM(AI8:AI11) -> 119.7 | ... AM7: =SUM(AM8:AM11) -> 177.75 | AN7: =SUM(AB7:AM7) -> 1610.55 | AO7: =N7+AA7+AN7 -> 3139.3
A8: 1. 管理团队（项目负责人、技术负责人、财务负责人） | B8: =项目预算表!$E$71*项目预算表!$I$25/12 -> 9.1666667 | C8: =项目预算表!$E$71*项目预算表!$I$25/12 -> 9.1666667 | D8: =项目预算表!$E$71*项目预算表!$I$25/12 -> 9.1666667 | E8: =项目预算表!$E$71*项目预算表!$I$25/12 -> 9.1666667 | F8: =项目预算表!$E$71*项目预算表!$I$25/12 -> 9.1666667 | G8: =项目预算表!$E$71*项目预算表!$I$25/12 -> 9.1666667 | H8: =项目预算表!$E$71*项目预算表!$I$25/12 -> 9.1666667 | I8: =项目预算表!$E$71*项目预算表!$I$25/12 -> 9.1666667 | J8: =项目预算表!$E$71*项目预算表!$I$25/12 -> 9.1666667 | K8: =项目预算表!$F$71*项目预算表!$I$25/12 -> 13.75 | L8: =项目预算表!$F$71*项目预算表!$I$25/12 -> 13.75 | M8: =项目预算表!$F$71*项目预算表!$I$25/12 -> 13.75 | N8: =SUM(B8:M8) -> 123.75 | O8: =项目预算表!$F$71*项目预算表!$I$25/12 -> 13.75 | P8: =项目预算表!$F$71*项目预算表!$I$25/12 -> 13.75 | Q8: =项目预算表!$F$71*项目预算表!$I$25/12 -> 13.75 | R8: =项目预算表!$F$71*项目预算表!$I$25/12 -> 13.75 | S8: =项目预算表!$F$71*项目预算表!$I$25/12 -> 13.75 | T8: =项目预算表!$F$71*项目预算表!$I$25/12 -> 13.75 | U8: =项目预算表!$F$71*项目预算表!$I$25/12 -> 13.75 | V8: =项目预算表!$F$71*项目预算表!$I$25/12 -> 13.75 | W8: =项目预算表!$F$71*项目预算表!$I$25/12 -> 13.75 | X8: =项目预算表!$G$71*项目预算表!$I$25/12 -> 13.75 | Y8: =项目预算表!$G$71*项目预算表!$I$25/12 -> 13.75 | Z8: =项目预算表!$G$71*项目预算表!$I$25/12 -> 13.75 | AA8: =SUM(O8:Z8) -> 165 | AB8: =项目预算表!$G$71*项目预算表!$I$25/12*1.08 -> 14.85 | AC8: =项目预算表!$G$71*项目预算表!$I$25/12*1.08 -> 14.85 | AD8: =项目预算表!$G$71*项目预算表!$I$25/12*1.08 -> 14.85 | AE8: =项目预算表!$G$71*项目预算表!$I$25/12*1.08 -> 14.85 | AF8: =项目预算表!$G$71*项目预算表!$I$25/12*1.08 -> 14.85 | AG8: =项目预算表!$G$71*项目预算表!$I$25/12*1.08 -> 14.85 | AH8: =项目预算表!$G$71*项目预算表!$I$25/12*1.08 -> 14.85 | AI8: =项目预算表!$G$71*项目预算表!$I$25/12*1.08 -> 14.85 | AJ8: =项目预算表!$G$71*项目预算表!$I$25/12*1.08 -> 14.85 | AK8: =项目预算表!$H$71*项目预算表!$I$25/12*1.08 -> 14.85 | AL8: =项目预算表!$H$71*项目预算表!$I$25/12*1.08 -> 14.85 | AM8: =项目预算表!$H$71*项目预算表!$I$25/12*1.08 -> 14.85 | AN8: =SUM(AB8:AM8) -> 178.2 | AO8: =N8+AA8+AN8 -> 466.95
A9: 2. 技术团队（DSP/SSP开发、运维等） | B9: =项目预算表!$E$72*项目预算表!$I$25/12 -> 22.916667 | C9: =项目预算表!$E$72*项目预算表!$I$25/12 -> 22.916667 | D9: =项目预算表!$E$72*项目预算表!$I$25/12 -> 22.916667 | E9: =项目预算表!$E$72*项目预算表!$I$25/12 -> 22.916667 | F9: =项目预算表!$E$72*项目预算表!$I$25/12 -> 22.916667 | G9: =项目预算表!$E$72*项目预算表!$I$25/12 -> 22.916667 | H9: =项目预算表!$E$72*项目预算表!$I$25/12 -> 22.916667 | I9: =项目预算表!$E$72*项目预算表!$I$25/12 -> 22.916667 | J9: =项目预算表!$E$72*项目预算表!$I$25/12 -> 22.916667 | K9: =项目预算表!$F$72*项目预算表!$I$25/12 -> 22.916667 | L9: =项目预算表!$F$72*项目预算表!$I$25/12 -> 22.916667 | M9: =项目预算表!$F$72*项目预算表!$I$25/12 -> 22.916667 | N9: =SUM(B9:M9) -> 275 | O9: =项目预算表!$F$72*项目预算表!$I$25/12 -> 22.916667 | P9: =项目预算表!$F$72*项目预算表!$I$25/12 -> 22.916667 | Q9: =项目预算表!$F$72*项目预算表!$I$25/12 -> 22.916667 | R9: =项目预算表!$F$72*项目预算表!$I$25/12 -> 22.916667 | S9: =项目预算表!$F$72*项目预算表!$I$25/12 -> 22.916667 | T9: =项目预算表!$F$72*项目预算表!$I$25/12 -> 22.916667 | U9: =项目预算表!$F$72*项目预算表!$I$25/12 -> 22.916667 | V9: =项目预算表!$F$72*项目预算表!$I$25/12 -> 22.916667 | W9: =项目预算表!$F$72*项目预算表!$I$25/12 -> 22.916667 | X9: =项目预算表!$G$72*项目预算表!$I$25/12 -> 32.083333 | Y9: =项目预算表!$G$72*项目预算表!$I$25/12 -> 32.083333 | Z9: =项目预算表!$G$72*项目预算表!$I$25/12 -> 32.083333 | AA9: =SUM(O9:Z9) -> 302.5 | AB9: =项目预算表!$G$72*项目预算表!$I$25/12*1.08 -> 34.65 | AC9: =项目预算表!$G$72*项目预算表!$I$25/12*1.08 -> 34.65 | AD9: =项目预算表!$G$72*项目预算表!$I$25/12*1.08 -> 34.65 | AE9: =项目预算表!$G$72*项目预算表!$I$25/12*1.08 -> 34.65 | AF9: =项目预算表!$G$72*项目预算表!$I$25/12*1.08 -> 34.65 | AG9: =项目预算表!$G$72*项目预算表!$I$25/12*1.08 -> 34.65 | AH9: =项目预算表!$G$72*项目预算表!$I$25/12*1.08 -> 34.65 | AI9: =项目预算表!$G$72*项目预算表!$I$25/12*1.08 -> 34.65 | AJ9: =项目预算表!$G$72*项目预算表!$I$25/12*1.08 -> 34.65 | AK9: =项目预算表!$H$72*项目预算表!$I$25/12*1.08 -> 49.5 | AL9: =项目预算表!$H$72*项目预算表!$I$25/12*1.08 -> 49.5 | AM9: =项目预算表!$H$72*项目预算表!$I$25/12*1.08 -> 49.5 | AN9: =SUM(AB9:AM9) -> 460.35 | AO9: =N9+AA9+AN9 -> 1037.85
A10: 3. 商务与运营团队 | B10: =项目预算表!$E$73*项目预算表!$I$25/12 -> 9.1666667 | C10: =项目预算表!$E$73*项目预算表!$I$25/12 -> 9.1666667 | D10: =项目预算表!$E$73*项目预算表!$I$25/12 -> 9.1666667 | E10: =项目预算表!$E$73*项目预算表!$I$25/12 -> 9.1666667 | F10: =项目预算表!$E$73*项目预算表!$I$25/12 -> 9.1666667 | G10: =项目预算表!$E$73*项目预算表!$I$25/12 -> 9.1666667 | H10: =项目预算表!$E$73*项目预算表!$I$25/12 -> 9.1666667 | I10: =项目预算表!$E$73*项目预算表!$I$25/12 -> 9.1666667 | J10: =项目预算表!$E$73*项目预算表!$I$25/12 -> 9.1666667 | K10: =项目预算表!$F$73*项目预算表!$I$25/12 -> 22.916667 | L10: =项目预算表!$F$73*项目预算表!$I$25/12 -> 22.916667 | M10: =项目预算表!$F$73*项目预算表!$I$25/12 -> 22.916667 | N10: =SUM(B10:M10) -> 151.25 | O10: =项目预算表!$F$73*项目预算表!$I$25/12 -> 22.916667 | P10: =项目预算表!$F$73*项目预算表!$I$25/12 -> 22.916667 | Q10: =项目预算表!$F$73*项目预算表!$I$25/12 -> 22.916667 | R10: =项目预算表!$F$73*项目预算表!$I$25/12 -> 22.916667 | S10: =项目预算表!$F$73*项目预算表!$I$25/12 -> 22.916667 | T10: =项目预算表!$F$73*项目预算表!$I$25/12 -> 22.916667 | U10: =项目预算表!$F$73*项目预算表!$I$25/12 -> 22.916667 | V10: =项目预算表!$F$73*项目预算表!$I$25/12 -> 22.916667 | W10: =项目预算表!$F$73*项目预算表!$I$25/12 -> 22.916667 | X10: =项目预算表!$G$73*项目预算表!$I$25/12 -> 55 | Y10: =项目预算表!$G$73*项目预算表!$I$25/12 -> 55 | Z10: =项目预算表!$G$73*项目预算表!$I$25/12 -> 55 | AA10: =SUM(O10:Z10) -> 371.25 | AB10: =项目预算表!$G$73*项目预算表!$I$25/12*1.08 -> 59.4 | AC10: =项目预算表!$G$73*项目预算表!$I$25/12*1.08 -> 59.4 | AD10: =项目预算表!$G$73*项目预算表!$I$25/12*1.08 -> 59.4 | AE10: =项目预算表!$G$73*项目预算表!$I$25/12*1.08 -> 59.4 | AF10: =项目预算表!$G$73*项目预算表!$I$25/12*1.08 -> 59.4 | AG10: =项目预算表!$G$73*项目预算表!$I$25/12*1.08 -> 59.4 | AH10: =项目预算表!$G$73*项目预算表!$I$25/12*1.08 -> 59.4 | AI10: =项目预算表!$G$73*项目预算表!$I$25/12*1.08 -> 59.4 | AJ10: =项目预算表!$G$73*项目预算表!$I$25/12*1.08 -> 59.4 | AK10: =项目预算表!$H$73*项目预算表!$I$25/12*1.08 -> 99 | AL10: =项目预算表!$H$73*项目预算表!$I$25/12*1.08 -> 99 | AM10: =项目预算表!$H$73*项目预算表!$I$25/12*1.08 -> 99 | AN10: =SUM(AB10:AM10) -> 831.6 | AO10: =N10+AA10+AN10 -> 1354.1
A11: 4. 业务支撑团队（财务、法务、合规等） | B11: =项目预算表!$E$74/12*项目预算表!$I$26 -> 3.3333333 | C11: =项目预算表!$E$74/12*项目预算表!$I$26 -> 3.3333333 | D11: =项目预算表!$E$74/12*项目预算表!$I$26 -> 3.3333333 | E11: =项目预算表!$E$74/12*项目预算表!$I$26 -> 3.3333333 | F11: =项目预算表!$E$74/12*项目预算表!$I$26 -> 3.3333333 | G11: =项目预算表!$E$74/12*项目预算表!$I$26 -> 3.3333333 | H11: =项目预算表!$E$74/12*项目预算表!$I$26 -> 3.3333333 | I11: =项目预算表!$E$74/12*项目预算表!$I$26 -> 3.3333333 | J11: =项目预算表!$E$74/12*项目预算表!$I$26 -> 3.3333333 | K11: =项目预算表!$F$74/12*项目预算表!$I$26 -> 6.6666667 | L11: =项目预算表!$F$74/12*项目预算表!$I$26 -> 6.6666667 | M11: =项目预算表!$F$74/12*项目预算表!$I$26 -> 6.6666667 | N11: =SUM(B11:M11) -> 50 | O11: =项目预算表!$F$74/12*项目预算表!$I$26 -> 6.6666667 | P11: =项目预算表!$F$74/12*项目预算表!$I$26 -> 6.6666667 | Q11: =项目预算表!$F$74/12*项目预算表!$I$26 -> 6.6666667 | R11: =项目预算表!$F$74/12*项目预算表!$I$26 -> 6.6666667 | S11: =项目预算表!$F$74/12*项目预算表!$I$26 -> 6.6666667 | T11: =项目预算表!$F$74/12*项目预算表!$I$26 -> 6.6666667 | U11: =项目预算表!$F$74/12*项目预算表!$I$26 -> 6.6666667 | V11: =项目预算表!$F$74/12*项目预算表!$I$26 -> 6.6666667 | W11: =项目预算表!$F$74/12*项目预算表!$I$26 -> 6.6666667 | X11: =项目预算表!$G$74/12*项目预算表!$I$26 -> 10 | Y11: =项目预算表!$G$74/12*项目预算表!$I$26 -> 10 | Z11: =项目预算表!$G$74/12*项目预算表!$I$26 -> 10 | AA11: =SUM(O11:Z11) -> 90 | AB11: =项目预算表!$G$74/12*项目预算表!$I$26*1.08 -> 10.8 | AC11: =项目预算表!$G$74/12*项目预算表!$I$26*1.08 -> 10.8 | AD11: =项目预算表!$G$74/12*项目预算表!$I$26*1.08 -> 10.8 | AE11: =项目预算表!$G$74/12*项目预算表!$I$26*1.08 -> 10.8 | AF11: =项目预算表!$G$74/12*项目预算表!$I$26*1.08 -> 10.8 | AG11: =项目预算表!$G$74/12*项目预算表!$I$26*1.08 -> 10.8 | AH11: =项目预算表!$G$74/12*项目预算表!$I$26*1.08 -> 10.8 | AI11: =项目预算表!$G$74/12*项目预算表!$I$26*1.08 -> 10.8 | AJ11: =项目预算表!$G$74/12*项目预算表!$I$26*1.08 -> 10.8 | AK11: =项目预算表!$H$74/12*项目预算表!$I$26*1.08 -> 14.4 | AL11: =项目预算表!$H$74/12*项目预算表!$I$26*1.08 -> 14.4 | AM11: =项目预算表!$H$74/12*项目预算表!$I$26*1.08 -> 14.4 | AN11: =SUM(AB11:AM11) -> 140.4 | AO11: =N11+AA11+AN11 -> 280.4
A12: 二、技术成本流出 | B12: =SUM(B13:B16) -> 4.5597484 | C12: =SUM(C13:C16) -> 4.5597484 | D12: =SUM(D13:D16) -> 4.5597484 | E12: =SUM(E13:E16) -> 4.5597484 | F12: =SUM(F13:F16) -> 4.5597484 | G12: =SUM(G13:G16) -> 4.5597484 | H12: =SUM(H13:H16) -> 4.5597484 | I12: =SUM(I13:I16) -> 4.5597484 | ... M12: =SUM(M13:M16) -> 4.5597484 | N12: =SUM(B12:M12) -> 54.716981 | O12: =SUM(O13:O16) -> 17.767296 | P12: =SUM(P13:P16) -> 17.767296 | Q12: =SUM(Q13:Q16) -> 17.767296 | R12: =SUM(R13:R16) -> 17.767296 | S12: =SUM(S13:S16) -> 17.767296 | T12: =SUM(T13:T16) -> 17.767296 | U12: =SUM(U13:U16) -> 17.767296 | V12: =SUM(V13:V16) -> 17.767296 | ... Z12: =SUM(Z13:Z16) -> 17.767296 | AA12: =SUM(O12:Z12) -> 213.20755 | AB12: =SUM(AB13:AB16) -> 45.597484 | AC12: =SUM(AC13:AC16) -> 45.597484 | AD12: =SUM(AD13:AD16) -> 45.597484 | AE12: =SUM(AE13:AE16) -> 45.597484 | AF12: =SUM(AF13:AF16) -> 45.597484 | AG12: =SUM(AG13:AG16) -> 45.597484 | AH12: =SUM(AH13:AH16) -> 45.597484 | AI12: =SUM(AI13:AI16) -> 45.597484 | ... AM12: =SUM(AM13:AM16) -> 45.597484 | AN12: =SUM(AB12:AM12) -> 547.16981 | AO12: =N12+AA12+AN12 -> 815.09434
A13: 1. 云服务器、数据库、缓存、日志服务、负载均衡、数据存储等 | B13: =年度运营成本测算明细!$D$11/3 -> 2.3584906 | C13: =年度运营成本测算明细!$D$11/3 -> 2.3584906 | D13: =年度运营成本测算明细!$D$11/3 -> 2.3584906 | E13: =年度运营成本测算明细!$E$11/9 -> 2.3584906 | F13: =年度运营成本测算明细!$E$11/9 -> 2.3584906 | G13: =年度运营成本测算明细!$E$11/9 -> 2.3584906 | H13: =年度运营成本测算明细!$E$11/9 -> 2.3584906 | I13: =年度运营成本测算明细!$E$11/9 -> 2.3584906 | J13: =年度运营成本测算明细!$E$11/9 -> 2.3584906 | K13: =年度运营成本测算明细!$E$11/9 -> 2.3584906 | L13: =年度运营成本测算明细!$E$11/9 -> 2.3584906 | M13: =年度运营成本测算明细!$E$11/9 -> 2.3584906 | N13: =SUM(B13:M13) -> 28.301887 | O13: =年度运营成本测算明细!$F$11/12 -> 11.792453 | P13: =年度运营成本测算明细!$F$11/12 -> 11.792453 | Q13: =年度运营成本测算明细!$F$11/12 -> 11.792453 | R13: =年度运营成本测算明细!$F$11/12 -> 11.792453 | S13: =年度运营成本测算明细!$F$11/12 -> 11.792453 | T13: =年度运营成本测算明细!$F$11/12 -> 11.792453 | U13: =年度运营成本测算明细!$F$11/12 -> 11.792453 | V13: =年度运营成本测算明细!$F$11/12 -> 11.792453 | ... Z13: =年度运营成本测算明细!$F$11/12 -> 11.792453 | AA13: =SUM(O13:Z13) -> 141.50943 | AB13: =年度运营成本测算明细!$G$11/12 -> 23.584906 | AC13: =年度运营成本测算明细!$G$11/12 -> 23.584906 | AD13: =年度运营成本测算明细!$G$11/12 -> 23.584906 | AE13: =年度运营成本测算明细!$G$11/12 -> 23.584906 | AF13: =年度运营成本测算明细!$G$11/12 -> 23.584906 | AG13: =年度运营成本测算明细!$G$11/12 -> 23.584906 | AH13: =年度运营成本测算明细!$G$11/12 -> 23.584906 | AI13: =年度运营成本测算明细!$G$11/12 -> 23.584906 | ... AM13: =年度运营成本测算明细!$G$11/12 -> 23.584906 | AN13: =SUM(AB13:AM13) -> 283.01887 | AO13: =N13+AA13+AN13 -> 452.83019
A14: 2. 数据传输 | B14: =年度运营成本测算明细!$D$12/3 -> 2.2012579 | C14: =年度运营成本测算明细!$D$12/3 -> 2.2012579 | D14: =年度运营成本测算明细!$D$12/3 -> 2.2012579 | E14: =年度运营成本测算明细!$E$12/9 -> 2.2012579 | F14: =年度运营成本测算明细!$E$12/9 -> 2.2012579 | G14: =年度运营成本测算明细!$E$12/9 -> 2.2012579 | H14: =年度运营成本测算明细!$E$12/9 -> 2.2012579 | I14: =年度运营成本测算明细!$E$12/9 -> 2.2012579 | J14: =年度运营成本测算明细!$E$12/9 -> 2.2012579 | K14: =年度运营成本测算明细!$E$12/9 -> 2.2012579 | L14: =年度运营成本测算明细!$E$12/9 -> 2.2012579 | M14: =年度运营成本测算明细!$E$12/9 -> 2.2012579 | N14: =SUM(B14:M14) -> 26.415094 | O14: =年度运营成本测算明细!$F$12/12 -> 5.9748428 | P14: =年度运营成本测算明细!$F$12/12 -> 5.9748428 | Q14: =年度运营成本测算明细!$F$12/12 -> 5.9748428 | R14: =年度运营成本测算明细!$F$12/12 -> 5.9748428 | S14: =年度运营成本测算明细!$F$12/12 -> 5.9748428 | T14: =年度运营成本测算明细!$F$12/12 -> 5.9748428 | U14: =年度运营成本测算明细!$F$12/12 -> 5.9748428 | V14: =年度运营成本测算明细!$F$12/12 -> 5.9748428 | ... Z14: =年度运营成本测算明细!$F$12/12 -> 5.9748428 | AA14: =SUM(O14:Z14) -> 71.698113 | AB14: =年度运营成本测算明细!$G$12/12 -> 22.012579 | AC14: =年度运营成本测算明细!$G$12/12 -> 22.012579 | AD14: =年度运营成本测算明细!$G$12/12 -> 22.012579 | AE14: =年度运营成本测算明细!$G$12/12 -> 22.012579 | AF14: =年度运营成本测算明细!$G$12/12 -> 22.012579 | AG14: =年度运营成本测算明细!$G$12/12 -> 22.012579 | AH14: =年度运营成本测算明细!$G$12/12 -> 22.012579 | AI14: =年度运营成本测算明细!$G$12/12 -> 22.012579 | ... AM14: =年度运营成本测算明细!$G$12/12 -> 22.012579 | AN14: =SUM(AB14:AM14) -> 264.15094 | AO14: =N14+AA14+AN14 -> 362.26415
B15: =年度运营成本测算明细!$D$13/12 -> 0 | C15: =年度运营成本测算明细!$D$13/12 -> 0 | D15: =年度运营成本测算明细!$D$13/12 -> 0 | E15: =年度运营成本测算明细!$D$13/12 -> 0 | F15: =年度运营成本测算明细!$D$13/12 -> 0 | G15: =年度运营成本测算明细!$D$13/12 -> 0 | H15: =年度运营成本测算明细!$D$13/12 -> 0 | I15: =年度运营成本测算明细!$D$13/12 -> 0 | ... M15: =年度运营成本测算明细!$D$13/12 -> 0 | N15: =SUM(B15:M15) -> 0 | O15: =年度运营成本测算明细!$F$13/12 -> 0 | P15: =年度运营成本测算明细!$F$13/12 -> 0 | Q15: =年度运营成本测算明细!$F$13/12 -> 0 | R15: =年度运营成本测算明细!$F$13/12 -> 0 | S15: =年度运营成本测算明细!$F$13/12 -> 0 | T15: =年度运营成本测算明细!$F$13/12 -> 0 | U15: =年度运营成本测算明细!$F$13/12 -> 0 | V15: =年度运营成本测算明细!$F$13/12 -> 0 | ... Z15: =年度运营成本测算明细!$F$13/12 -> 0 | AA15: =SUM(O15:Z15) -> 0 | AB15: =年度运营成本测算明细!$G$13/12 -> 0 | AC15: =年度运营成本测算明细!$G$13/12 -> 0 | AD15: =年度运营成本测算明细!$G$13/12 -> 0 | AE15: =年度运营成本测算明细!$G$13/12 -> 0 | AF15: =年度运营成本测算明细!$G$13/12 -> 0 | AG15: =年度运营成本测算明细!$G$13/12 -> 0 | AH15: =年度运营成本测算明细!$G$13/12 -> 0 | AI15: =年度运营成本测算明细!$G$13/12 -> 0 | ... AM15: =年度运营成本测算明细!$G$13/12 -> 0 | AN15: =SUM(AB15:AM15) -> 0 | AO15: =N15+AA15+AN15 -> 0
B16: =年度运营成本测算明细!$D$14/12 -> 0 | C16: =年度运营成本测算明细!$D$14/12 -> 0 | D16: =年度运营成本测算明细!$D$14/12 -> 0 | E16: =年度运营成本测算明细!$D$14/12 -> 0 | F16: =年度运营成本测算明细!$D$14/12 -> 0 | G16: =年度运营成本测算明细!$D$14/12 -> 0 | H16: =年度运营成本测算明细!$D$14/12 -> 0 | I16: =年度运营成本测算明细!$D$14/12 -> 0 | ... M16: =年度运营成本测算明细!$D$14/12 -> 0 | N16: =SUM(B16:M16) -> 0 | O16: =年度运营成本测算明细!$F$14/12 -> 0 | P16: =年度运营成本测算明细!$F$14/12 -> 0 | Q16: =年度运营成本测算明细!$F$14/12 -> 0 | R16: =年度运营成本测算明细!$F$14/12 -> 0 | S16: =年度运营成本测算明细!$F$14/12 -> 0 | T16: =年度运营成本测算明细!$F$14/12 -> 0 | U16: =年度运营成本测算明细!$F$14/12 -> 0 | V16: =年度运营成本测算明细!$F$14/12 -> 0 | ... Z16: =年度运营成本测算明细!$F$14/12 -> 0 | AA16: =SUM(O16:Z16) -> 0 | AB16: =年度运营成本测算明细!$G$14/12 -> 0 | AC16: =年度运营成本测算明细!$G$14/12 -> 0 | AD16: =年度运营成本测算明细!$G$14/12 -> 0 | AE16: =年度运营成本测算明细!$G$14/12 -> 0 | AF16: =年度运营成本测算明细!$G$14/12 -> 0 | AG16: =年度运营成本测算明细!$G$14/12 -> 0 | AH16: =年度运营成本测算明细!$G$14/12 -> 0 | AI16: =年度运营成本测算明细!$G$14/12 -> 0 | ... AM16: =年度运营成本测算明细!$G$14/12 -> 0 | AN16: =SUM(AB16:AM16) -> 0 | AO16: =N16+AA16+AN16 -> 0
A17: 三、广告位成本流出 | B17: =SUM(B18) -> 7.8616352 | C17: =SUM(C18) -> 7.8616352 | D17: =SUM(D18) -> 7.8616352 | E17: =SUM(E18) -> 7.8616352 | F17: =SUM(F18) -> 7.8616352 | G17: =SUM(G18) -> 7.8616352 | H17: =SUM(H18) -> 7.8616352 | I17: =SUM(I18) -> 7.8616352 | ... M17: =SUM(M18) -> 7.8616352 | N17: =SUM(B17:M17) -> 94.339623 | O17: =SUM(O18) -> 0 | P17: =SUM(P18) -> 0 | Q17: =SUM(Q18) -> 0 | R17: =SUM(R18) -> 0 | S17: =SUM(S18) -> 0 | T17: =SUM(T18) -> 0 | U17: =SUM(U18) -> 0 | V17: =SUM(V18) -> 0 | ... Z17: =SUM(Z18) -> 0 | AA17: =SUM(O17:Z17) -> 0 | AB17: =SUM(AB18) -> 0 | AC17: =SUM(AC18) -> 0 | AD17: =SUM(AD18) -> 0 | AE17: =SUM(AE18) -> 0 | AF17: =SUM(AF18) -> 0 | AG17: =SUM(AG18) -> 0 | AH17: =SUM(AH18) -> 0 | AI17: =SUM(AI18) -> 0 | ... AM17: =SUM(AM18) -> 0 | AN17: =SUM(AB17:AM17) -> 0 | AO17: =N17+AA17+AN17 -> 94.339623
A18: IPTV/OTT业务广告位采购成本 | B18: =年度运营成本测算明细!$D$17/12 -> 7.8616352 | C18: =年度运营成本测算明细!$D$17/12 -> 7.8616352 | D18: =年度运营成本测算明细!$D$17/12 -> 7.8616352 | E18: =年度运营成本测算明细!$D$17/12 -> 7.8616352 | F18: =年度运营成本测算明细!$D$17/12 -> 7.8616352 | G18: =年度运营成本测算明细!$D$17/12 -> 7.8616352 | H18: =年度运营成本测算明细!$D$17/12 -> 7.8616352 | I18: =年度运营成本测算明细!$D$17/12 -> 7.8616352 | ... M18: =年度运营成本测算明细!$D$17/12 -> 7.8616352 | N18: =SUM(B18:M18) -> 94.339623 | AA18: =SUM(O18:Z18) -> 0 | AN18: =SUM(AB18:AM18) -> 0 | AO18: =N18+AA18+AN18 -> 94.339623
A19: 四、商务合作与其他运营成本流出 | B19: =SUM(B20:B21) -> 0 | C19: =SUM(C20:C21) -> 0 | D19: =SUM(D20:D21) -> 0 | E19: =SUM(E20:E21) -> 1.0188679 | F19: =SUM(F20:F21) -> 2.0377358 | G19: =SUM(G20:G21) -> 4.0754717 | H19: =SUM(H20:H21) -> 5.4339623 | I19: =SUM(I20:I21) -> 6.7924528 | ... M19: =SUM(M20:M21) -> 10.867925 | N19: =SUM(B19:M19) -> 56.716981 | O19: =SUM(O20:O21) -> 19.613208 | P19: =SUM(P20:P21) -> 20.207547 | Q19: =SUM(Q20:Q21) -> 20.801887 | R19: =SUM(R20:R21) -> 21.396226 | S19: =SUM(S20:S21) -> 21.990566 | T19: =SUM(T20:T21) -> 22.584906 | U19: =SUM(U20:U21) -> 23.179245 | V19: =SUM(V20:V21) -> 23.773585 | ... Z19: =SUM(Z20:Z21) -> 26.150943 | AA19: =SUM(O19:Z19) -> 274.58491 | AB19: =SUM(AB20:AB21) -> 38.037736 | AC19: =SUM(AC20:AC21) -> 49.132075 | AD19: =SUM(AD20:AD21) -> 60.226415 | AE19: =SUM(AE20:AE21) -> 71.320755 | AF19: =SUM(AF20:AF21) -> 87.169811 | AG19: =SUM(AG20:AG21) -> 103.01887 | AH19: =SUM(AH20:AH21) -> 118.86792 | AI19: =SUM(AI20:AI21) -> 134.71698 | ... AM19: =SUM(AM20:AM21) -> 239.47925 | AN19: =SUM(AB19:AM19) -> 1409.1396 | AO19: =N19+AA19+AN19 -> 1740.4415
A20: 1. 渠道合作与分成 | E20: =E36*E37*E39*E41*30/1000/1.06 -> 1.0188679 | F20: =F36*F37*F39*F41*30/1000/1.06 -> 2.0377358 | G20: =G36*G37*G39*G41*30/1000/1.06 -> 4.0754717 | H20: =H36*H37*H39*H41*30/1000/1.06 -> 5.4339623 | I20: =I36*I37*I39*I41*30/1000/1.06 -> 6.7924528 | J20: =J36*J37*J39*J41*30/1000/1.06 -> 7.8113208 | K20: =K36*K37*K39*K41*30/1000/1.06 -> 8.8301887 | L20: =L36*L37*L39*L41*30/1000/1.06 -> 9.8490566 | M20: =M36*M37*M39*M41*30/1000/1.06 -> 10.867925 | N20: =SUM(B20:M20) -> 56.716981 | O20: =O36*O37*O39*O41*30/1000/1.06 -> 16.811321 | P20: =P36*P37*P39*P41*30/1000/1.06 -> 17.320755 | Q20: =Q36*Q37*Q39*Q41*30/1000/1.06 -> 17.830189 | R20: =R36*R37*R39*R41*30/1000/1.06 -> 18.339623 | S20: =S36*S37*S39*S41*30/1000/1.06 -> 18.849057 | T20: =T36*T37*T39*T41*30/1000/1.06 -> 19.358491 | U20: =U36*U37*U39*U41*30/1000/1.06 -> 19.867925 | V20: =V36*V37*V39*V41*30/1000/1.06 -> 20.377358 | ... Z20: =Z36*Z37*Z39*Z41*30/1000/1.06 -> 22.415094 | AA20: =SUM(O20:Z20) -> 235.35849 | AB20: =AB36*AB37*AB39*AB41*30/1000/1.06 -> 32.603774 | AC20: =AC36*AC37*AC39*AC41*30/1000/1.06 -> 42.113208 | AD20: =AD36*AD37*AD39*AD41*30/1000/1.06 -> 51.622642 | AE20: =AE36*AE37*AE39*AE41*30/1000/1.06 -> 61.132075 | AF20: =AF36*AF37*AF39*AF41*30/1000/1.06 -> 74.716981 | AG20: =AG36*AG37*AG39*AG41*30/1000/1.06 -> 88.301887 | AH20: =AH36*AH37*AH39*AH41*30/1000/1.06 -> 101.88679 | AI20: =AI36*AI37*AI39*AI41*30/1000/1.06 -> 115.4717 | ... AM20: =AM36*AM37*AM39*AM41*30/1000/1.06 -> 205.26792 | AN20: =SUM(AB20:AM20) -> 1207.834 | AO20: =N20+AA20+AN20 -> 1499.9094
A21: 2. 市场推广与商务拓展 | E21: =E36*E37*E39*E40*30/1000/1.06 -> 0 | F21: =F36*F37*F39*F40*30/1000/1.06 -> 0 | G21: =G36*G37*G39*G40*30/1000/1.06 -> 0 | H21: =H36*H37*H39*H40*30/1000/1.06 -> 0 | I21: =I36*I37*I39*I40*30/1000/1.06 -> 0 | J21: =J36*J37*J39*J40*30/1000/1.06 -> 0 | K21: =K36*K37*K39*K40*30/1000/1.06 -> 0 | L21: =L36*L37*L39*L40*30/1000/1.06 -> 0 | M21: =M36*M37*M39*M40*30/1000/1.06 -> 0 | N21: =SUM(B21:M21) -> 0 | O21: =O36*O37*O39*O40*30/1000/1.06 -> 2.8018868 | P21: =P36*P37*P39*P40*30/1000/1.06 -> 2.8867925 | Q21: =Q36*Q37*Q39*Q40*30/1000/1.06 -> 2.9716981 | R21: =R36*R37*R39*R40*30/1000/1.06 -> 3.0566038 | S21: =S36*S37*S39*S40*30/1000/1.06 -> 3.1415094 | T21: =T36*T37*T39*T40*30/1000/1.06 -> 3.2264151 | U21: =U36*U37*U39*U40*30/1000/1.06 -> 3.3113208 | V21: =V36*V37*V39*V40*30/1000/1.06 -> 3.3962264 | ... Z21: =Z36*Z37*Z39*Z40*30/1000/1.06 -> 3.7358491 | AA21: =SUM(O21:Z21) -> 39.226415 | AB21: =AB36*AB37*AB39*AB40*30/1000/1.06 -> 5.4339623 | AC21: =AC36*AC37*AC39*AC40*30/1000/1.06 -> 7.0188679 | AD21: =AD36*AD37*AD39*AD40*30/1000/1.06 -> 8.6037736 | AE21: =AE36*AE37*AE39*AE40*30/1000/1.06 -> 10.188679 | AF21: =AF36*AF37*AF39*AF40*30/1000/1.06 -> 12.45283 | AG21: =AG36*AG37*AG39*AG40*30/1000/1.06 -> 14.716981 | AH21: =AH36*AH37*AH39*AH40*30/1000/1.06 -> 16.981132 | AI21: =AI36*AI37*AI39*AI40*30/1000/1.06 -> 19.245283 | ... AM21: =AM36*AM37*AM39*AM40*30/1000/1.06 -> 34.211321 | AN21: =SUM(AB21:AM21) -> 201.30566 | AO21: =N21+AA21+AN21 -> 240.53208
A22: 五、办公运营成本流出 | B22: =SUM(B23:B26) -> 1.8792049 | C22: =SUM(C23:C26) -> 1.8792049 | D22: =SUM(D23:D26) -> 3.6480728 | E22: =SUM(E23:E26) -> 1.8792049 | F22: =SUM(F23:F26) -> 1.8792049 | G22: =SUM(G23:G26) -> 1.8792049 | H22: =SUM(H23:H26) -> 2.2090979 | I22: =SUM(I23:I26) -> 2.2090979 | ... M22: =SUM(M23:M26) -> 2.8340979 | N22: =SUM(B22:M22) -> 30.532175 | O22: =SUM(O23:O26) -> 3.5613532 | P22: =SUM(P23:P26) -> 3.5613532 | Q22: =SUM(Q23:Q26) -> 3.5613532 | R22: =SUM(R23:R26) -> 3.5613532 | S22: =SUM(S23:S26) -> 3.5613532 | T22: =SUM(T23:T26) -> 3.5613532 | U22: =SUM(U23:U26) -> 3.5613532 | V22: =SUM(V23:V26) -> 3.5613532 | ... Z22: =SUM(Z23:Z26) -> 4.8113532 | AA22: =SUM(O22:Z22) -> 51.792842 | AB22: =SUM(AB23:AB26) -> 50.595988 | AC22: =SUM(AC23:AC26) -> 8.1431575 | AD22: =SUM(AD23:AD26) -> 8.1431575 | AE22: =SUM(AE23:AE26) -> 8.1431575 | AF22: =SUM(AF23:AF26) -> 8.1431575 | AG22: =SUM(AG23:AG26) -> 78.897874 | AH22: =SUM(AH23:AH26) -> 8.1431575 | AI22: =SUM(AI23:AI26) -> 8.1431575 | ... AM22: =SUM(AM23:AM26) -> 37.945044 | AN22: =SUM(AB22:AM22) -> 250.73204 | AO22: =N22+AA22+AN22 -> 333.05706
A23: 中介机构费 | B23: =年度运营成本测算明细!$D$24/12 -> 0 | N23: =SUM(B23:M23) -> 0 | O23: =年度运营成本测算明细!F24*30% -> 0 | T23: =年度运营成本测算明细!F24*50% -> 0 | Z23: =年度运营成本测算明细!F24*20% -> 0 | AA23: =SUM(O23:Z23) -> 0 | AB23: =年度运营成本测算明细!G24*30% -> 42.45283 | AG23: =年度运营成本测算明细!G24*50% -> 70.754717 | AM23: =年度运营成本测算明细!G24*20% -> 28.301887 | AN23: =SUM(AB23:AM23) -> 141.50943 | AO23: =N23+AA23+AN23 -> 141.50943
A24: 场地费（含水电） | B24: =年度运营成本测算明细!$D$25/6 -> 0.62920489 | C24: =年度运营成本测算明细!$D$25/6 -> 0.62920489 | D24: =年度运营成本测算明细!$D$25/6 -> 0.62920489 | E24: =年度运营成本测算明细!$D$25/6 -> 0.62920489 | F24: =年度运营成本测算明细!$D$25/6 -> 0.62920489 | G24: =年度运营成本测算明细!$D$25/6 -> 0.62920489 | H24: =年度运营成本测算明细!$E$25/6 -> 0.95909786 | I24: =年度运营成本测算明细!$E$25/6 -> 0.95909786 | J24: =年度运营成本测算明细!$E$25/6 -> 0.95909786 | K24: =年度运营成本测算明细!$E$25/6 -> 0.95909786 | L24: =年度运营成本测算明细!$E$25/6 -> 0.95909786 | M24: =年度运营成本测算明细!$E$25/6 -> 0.95909786 | N24: =SUM(B24:M24) -> 9.5298165 | O24: =年度运营成本测算明细!$F$25/12 -> 1.6863532 | P24: =年度运营成本测算明细!$F$25/12 -> 1.6863532 | Q24: =年度运营成本测算明细!$F$25/12 -> 1.6863532 | R24: =年度运营成本测算明细!$F$25/12 -> 1.6863532 | S24: =年度运营成本测算明细!$F$25/12 -> 1.6863532 | T24: =年度运营成本测算明细!$F$25/12 -> 1.6863532 | U24: =年度运营成本测算明细!$F$25/12 -> 1.6863532 | V24: =年度运营成本测算明细!$F$25/12 -> 1.6863532 | ... Z24: =年度运营成本测算明细!$F$25/12 -> 1.6863532 | AA24: =SUM(O24:Z24) -> 20.236239 | AB24: =年度运营成本测算明细!$G$25/12 -> 5.0181575 | AC24: =年度运营成本测算明细!$G$25/12 -> 5.0181575 | AD24: =年度运营成本测算明细!$G$25/12 -> 5.0181575 | AE24: =年度运营成本测算明细!$G$25/12 -> 5.0181575 | AF24: =年度运营成本测算明细!$G$25/12 -> 5.0181575 | AG24: =年度运营成本测算明细!$G$25/12 -> 5.0181575 | AH24: =年度运营成本测算明细!$G$25/12 -> 5.0181575 | AI24: =年度运营成本测算明细!$G$25/12 -> 5.0181575 | ... AM24: =年度运营成本测算明细!$G$25/12 -> 5.0181575 | AN24: =SUM(AB24:AM24) -> 60.21789 | AO24: =N24+AA24+AN24 -> 89.983945
A25: 招聘费 | D25: =年度运营成本测算明细!D26 -> 1.7688679 | J25: =年度运营成本测算明细!E26 -> 2.3584906 | N25: =SUM(B25:M25) -> 4.1273585 | X25: =年度运营成本测算明细!F26 -> 5.3066038 | AA25: =SUM(O25:Z25) -> 5.3066038 | AK25: =年度运营成本测算明细!G26 -> 7.004717 | AN25: =SUM(AB25:AM25) -> 7.004717 | AO25: =N25+AA25+AN25 -> 16.438679
A26: 其他管理费用 | B26: =项目预算表!$E$75*1.5/12 -> 1.25 | C26: =项目预算表!$E$75*1.5/12 -> 1.25 | D26: =项目预算表!$E$75*1.5/12 -> 1.25 | E26: =项目预算表!$E$75*1.5/12 -> 1.25 | F26: =项目预算表!$E$75*1.5/12 -> 1.25 | G26: =项目预算表!$E$75*1.5/12 -> 1.25 | H26: =项目预算表!$E$75*1.5/12 -> 1.25 | I26: =项目预算表!$E$75*1.5/12 -> 1.25 | J26: =项目预算表!$E$75*1.5/12 -> 1.25 | K26: =项目预算表!$F$75*1.5/12 -> 1.875 | L26: =项目预算表!$F$75*1.5/12 -> 1.875 | M26: =项目预算表!$F$75*1.5/12 -> 1.875 | N26: =SUM(B26:M26) -> 16.875 | O26: =项目预算表!$F$75*1.5/12 -> 1.875 | P26: =项目预算表!$F$75*1.5/12 -> 1.875 | Q26: =项目预算表!$F$75*1.5/12 -> 1.875 | R26: =项目预算表!$F$75*1.5/12 -> 1.875 | S26: =项目预算表!$F$75*1.5/12 -> 1.875 | T26: =项目预算表!$F$75*1.5/12 -> 1.875 | U26: =项目预算表!$F$75*1.5/12 -> 1.875 | V26: =项目预算表!$F$75*1.5/12 -> 1.875 | W26: =项目预算表!$F$75*1.5/12 -> 1.875 | X26: =项目预算表!$G$75*1.5/12 -> 3.125 | Y26: =项目预算表!$G$75*1.5/12 -> 3.125 | Z26: =项目预算表!$G$75*1.5/12 -> 3.125 | AA26: =SUM(O26:Z26) -> 26.25 | AB26: =项目预算表!$G$75*1.5/12 -> 3.125 | AC26: =项目预算表!$G$75*1.5/12 -> 3.125 | AD26: =项目预算表!$G$75*1.5/12 -> 3.125 | AE26: =项目预算表!$G$75*1.5/12 -> 3.125 | AF26: =项目预算表!$G$75*1.5/12 -> 3.125 | AG26: =项目预算表!$G$75*1.5/12 -> 3.125 | AH26: =项目预算表!$G$75*1.5/12 -> 3.125 | AI26: =项目预算表!$G$75*1.5/12 -> 3.125 | AJ26: =项目预算表!$G$75*1.5/12 -> 3.125 | AK26: =项目预算表!$H$75*1.5/12 -> 4.625 | AL26: =项目预算表!$H$75*1.5/12 -> 4.625 | AM26: =项目预算表!$H$75*1.5/12 -> 4.625 | AN26: =SUM(AB26:AM26) -> 42 | AO26: =N26+AA26+AN26 -> 85.125
A27: 六、平台分账现金流出 | B27: 0 | C27: =C36*C37*(1-C39)*30/1000 -> 0 | D27: =D36*D37*(1-D39)*30/1000 -> 0 | E27: =E36*E37*(1-E39)*30/1000/1.06 -> 13.584906 | F27: =F36*F37*(1-F39)*30/1000/1.06 -> 27.169811 | G27: =G36*G37*(1-G39)*30/1000/1.06 -> 54.339623 | H27: =H36*H37*(1-H39)*30/1000/1.06 -> 72.45283 | I27: =I36*I37*(1-I39)*30/1000/1.06 -> 90.566038 | J27: =J36*J37*(1-J39)*30/1000/1.06 -> 104.15094 | K27: =K36*K37*(1-K39)*30/1000/1.06 -> 117.73585 | L27: =L36*L37*(1-L39)*30/1000/1.06 -> 131.32075 | M27: =M36*M37*(1-M39)*30/1000/1.06 -> 144.90566 | N27: =SUM(B27:M27) -> 756.22642 | O27: =O36*O37*(1-O39)*30/1000/1.06 -> 224.15094 | P27: =P36*P37*(1-P39)*30/1000/1.06 -> 230.9434 | Q27: =Q36*Q37*(1-Q39)*30/1000/1.06 -> 237.73585 | R27: =R36*R37*(1-R39)*30/1000/1.06 -> 244.5283 | S27: =S36*S37*(1-S39)*30/1000/1.06 -> 251.32075 | T27: =T36*T37*(1-T39)*30/1000/1.06 -> 258.11321 | U27: =U36*U37*(1-U39)*30/1000/1.06 -> 264.90566 | V27: =V36*V37*(1-V39)*30/1000/1.06 -> 271.69811 | ... Z27: =Z36*Z37*(1-Z39)*30/1000/1.06 -> 298.86792 | AA27: =SUM(O27:Z27) -> 3138.1132 | AB27: =AB36*AB37*(1-AB39)*30/1000/1.06 -> 434.71698 | AC27: =AC36*AC37*(1-AC39)*30/1000/1.06 -> 561.50943 | AD27: =AD36*AD37*(1-AD39)*30/1000/1.06 -> 688.30189 | AE27: =AE36*AE37*(1-AE39)*30/1000/1.06 -> 815.09434 | AF27: =AF36*AF37*(1-AF39)*30/1000/1.06 -> 996.22642 | AG27: =AG36*AG37*(1-AG39)*30/1000/1.06 -> 1177.3585 | AH27: =AH36*AH37*(1-AH39)*30/1000/1.06 -> 1358.4906 | AI27: =AI36*AI37*(1-AI39)*30/1000/1.06 -> 1539.6226 | ... AM27: =AM36*AM37*(1-AM39)*30/1000/1.06 -> 2736.9057 | AN27: =SUM(AB27:AM27) -> 16104.453 | AO27: =N27+AA27+AN27 -> 19998.792 | AP27: =AO27*1.06 -> 21198.72
A28: 七、其他税费 | B28: =B29+B30 -> 0 | C28: =C29+C30 -> 0.0042901766 | D28: =D29+D30 -> 0.0042901766 | E28: =E29+E30 -> 0.0048208369 | F28: =F29+F30 -> 0.013765648 | G28: =G29+G30 -> 0.02324112 | H28: =H29+H30 -> 0.042192063 | I28: =I29+I30 -> 0.054924994 | ... AM28: =AM29+AM30 -> 25.81375 | AN28: =SUM(AB28:AM28) -> 135.22142 | AO28: =N28+AA28+AN28 -> 151.15154
A29: 其中：增值税 | C29: =IF(SUM($B$4:C4)-SUM($B$12:C12,$B$17:C17,$B$19:C19,$B$22:C22,$B$27:C27)>0,(SUM($B$4:C4)-SUM($B$12:C12,$B$17:C17,$B$19:C19,$B$22:C22,$B$27:C27))*6%,0) -> 0 | D29: =IF(SUM($B$4:D4)-SUM($B$12:D12,$B$17:D17,$B$19:C19,$B$22:D22,$B$27:D27)>0,(SUM($B$4:D4)-SUM($B$12:D12,$B$17:D17,$B$19:C19,$B$22:D22,$B$27:D27))*6%,0)-SUM($B$29:C29) -> 0 | E29: =IF(SUM($B$4:E4)-SUM($B$12:E12,$B$17:E17,$B$19:D19,$B$22:E22,$B$27:E27)>0,(SUM($B$4:E4)-SUM($B$12:E12,$B$17:E17,$B$19:D19,$B$22:E22,$B$27:E27))*6%,0)-SUM($B$29:D29) -> 0 | F29: =IF(SUM($B$4:F4)-SUM($B$12:F12,$B$17:F17,$B$19:E19,$B$22:F22,$B$27:F27)>0,(SUM($B$4:F4)-SUM($B$12:F12,$B$17:F17,$B$19:E19,$B$22:F22,$B$27:F27))*6%,0)-SUM($B$29:E29) -> 0 | G29: =IF(SUM($B$4:G4)-SUM($B$12:G12,$B$17:G17,$B$19:F19,$B$22:G22,$B$27:G27)>0,(SUM($B$4:G4)-SUM($B$12:G12,$B$17:G17,$B$19:F19,$B$22:G22,$B$27:G27))*6%,0)-SUM($B$29:F29) -> 0 | H29: =IF(SUM($B$4:H4)-SUM($B$12:H12,$B$17:H17,$B$19:G19,$B$22:H22,$B$27:H27)>0,(SUM($B$4:H4)-SUM($B$12:H12,$B$17:H17,$B$19:G19,$B$22:H22,$B$27:H27))*6%,0)-SUM($B$29:G29) -> 0 | I29: =IF(SUM($B$4:I4)-SUM($B$12:I12,$B$17:I17,$B$19:H19,$B$22:I22,$B$27:I27)>0,(SUM($B$4:I4)-SUM($B$12:I12,$B$17:I17,$B$19:H19,$B$22:I22,$B$27:I27))*6%,0)-SUM($B$29:H29) -> 0 | J29: =IF(SUM($B$4:J4)-SUM($B$12:J12,$B$17:J17,$B$19:I19,$B$22:J22,$B$27:J27)>0,(SUM($B$4:J4)-SUM($B$12:J12,$B$17:J17,$B$19:I19,$B$22:J22,$B$27:J27))*6%,0)-SUM($B$29:I29) -> 0 | K29: =IF(SUM($B$4:K4)-SUM($B$12:K12,$B$17:K17,$B$19:J19,$B$22:K22,$B$27:K27)>0,(SUM($B$4:K4)-SUM($B$12:K12,$B$17:K17,$B$19:J19,$B$22:K22,$B$27:K27))*6%,0)-SUM($B$29:J29) -> 0 | ... M29: =IF(SUM($B$4:M4)-SUM($B$12:M12,$B$17:M17,$B$19:L19,$B$22:M22,$B$27:M27)>0,(SUM($B$4:M4)-SUM($B$12:M12,$B$17:M17,$B$19:L19,$B$22:M22,$B$27:M27))*6%,0)-SUM($B$29:L29) -> 0 | N29: =IF(SUM($N$4:N4)-SUM($N$12:N12,$N$17:N17,$N$19:N19,$N$22:N22,$N$27:N27)>0,(SUM($N$4:N4)-SUM($N$12:N12,$N$17:N17,$N$19:N19,$N$22:N22,$N$27:N27))*6%,0) -> 0 | O29: =IF(SUM($N$4:O4)-SUM($N$12:O12,$N$17:O17,$N$19:O19,$N$22:O22,$N$27:O27)>0,(SUM($N$4:O4)-SUM($N$12:O12,$N$17:O17,$N$19:O19,$N$22:O22,$N$27:O27))*6%,0) -> 0 | P29: =IF(SUM($N$4:P4)-SUM($N$12:P12,$N$17:P17,$N$19:P19,$N$22:P22,$N$27:P27)>0,MAX((SUM($N$4:P4)-SUM($N$12:P12,$N$17:P17,$N$19:P19,$N$22:P22,$N$27:P27)*6%-SUM($N$29:O29)),0),0) -> 0 | Q29: =IF(SUM($N$4:Q4)-SUM($N$12:Q12,$N$17:Q17,$N$19:Q19,$N$22:Q22,$N$27:Q27)>0,MAX(((SUM($N$4:Q4)-SUM($N$12:Q12,$N$17:Q17,$N$19:Q19,$N$22:Q22,$N$27:Q27))*6%-SUM($N$29:P29)),0),0) -> 0.080988186 | R29: =IF(SUM($N$4:R4)-SUM($N$12:R12,$N$17:R17,$N$19:R19,$N$22:R22,$N$27:R27)>0,MAX(((SUM($N$4:R4)-SUM($N$12:R12,$N$17:R17,$N$19:R19,$N$22:R22,$N$27:R27))*6%-SUM($N$29:Q29)),0),0) -> 1.104432 | S29: =IF(SUM($N$4:S4)-SUM($N$12:S12,$N$17:S17,$N$19:S19,$N$22:S22,$N$27:S27)>0,MAX(((SUM($N$4:S4)-SUM($N$12:S12,$N$17:S17,$N$19:S19,$N$22:S22,$N$27:S27))*6%-SUM($N$29:R29)),0),0) -> 1.1706584 | T29: =IF(SUM($N$4:T4)-SUM($N$12:T12,$N$17:T17,$N$19:T19,$N$22:T22,$N$27:T27)>0,MAX(((SUM($N$4:T4)-SUM($N$12:T12,$N$17:T17,$N$19:T19,$N$22:T22,$N$27:T27))*6%-SUM($N$29:S29)),0),0) -> 1.2368848 | U29: =IF(SUM($N$4:U4)-SUM($N$12:U12,$N$17:U17,$N$19:U19,$N$22:U22,$N$27:U27)>0,MAX(((SUM($N$4:U4)-SUM($N$12:U12,$N$17:U17,$N$19:U19,$N$22:U22,$N$27:U27))*6%-SUM($N$29:T29)),0),0) -> 1.3031113 | V29: =IF(SUM($N$4:V4)-SUM($N$12:V12,$N$17:V17,$N$19:V19,$N$22:V22,$N$27:V27)>0,MAX(((SUM($N$4:V4)-SUM($N$12:V12,$N$17:V17,$N$19:V19,$N$22:V22,$N$27:V27))*6%-SUM($N$29:U29)),0),0) -> 1.3693377 | W29: =IF(SUM($N$4:W4)-SUM($N$12:W12,$N$17:W17,$N$19:W19,$N$22:W22,$N$27:W27)>0,MAX(((SUM($N$4:W4)-SUM($N$12:W12,$N$17:W17,$N$19:W19,$N$22:W22,$N$27:W27))*6%-SUM($N$29:V29)),0),0) -> 1.4355641 | X29: =IF(SUM($N$4:X4)-SUM($N$12:X12,$N$17:X17,$N$19:X19,$N$22:X22,$N$27:X27)>0,MAX(((SUM($N$4:X4)-SUM($N$12:X12,$N$17:X17,$N$19:X19,$N$22:X22,$N$27:X27))*6%-SUM($N$29:W29)),0),0) -> 1.1083943 | ... Z29: =IF(SUM($N$4:Z4)-SUM($N$12:Z12,$N$17:Z17,$N$19:Z19,$N$22:Z22,$N$27:Z27)>0,MAX(((SUM($N$4:Z4)-SUM($N$12:Z12,$N$17:Z17,$N$19:Z19,$N$22:Z22,$N$27:Z27))*6%-SUM($N$29:Y29)),0),0) -> 1.5592433 | AA29: =SUM(O29:Z29) -> 11.861631 | AB29: =IF(SUM($AA$4:AB4)-SUM($AA$12:AB12,$AA$17:AB17,$AA$19:AB19,$AA$22:AB22,$AA$27:AB27)>0,(SUM($AA$4:AB4)-SUM($AA$12:AB12,$AA$17:AB17,$AA$19:AB19,$AA$22:AB22,$AA$27:AB27))*6%,0) -> 13.163463 | AC29: =IF(SUM($AA$4:AC4)-SUM($AA$12:AC12,$AA$17:AC17,$AA$19:AC19,$AA$22:AC22,$AA$27:AC27)>0,MAX(((SUM($AA$4:AC4)-SUM($AA$12:AC12,$AA$17:AC17,$AA$19:AC19,$AA$22:AC22,$AA$27:AC27))*6%-SUM($AA$29:AB29)),0),0) -> 0 | AD29: =IF(SUM($AA$4:AD4)-SUM($AA$12:AD12,$AA$17:AD17,$AA$19:AD19,$AA$22:AD22,$AA$27:AD27)>0,MAX(((SUM($AA$4:AD4)-SUM($AA$12:AD12,$AA$17:AD17,$AA$19:AD19,$AA$22:AD22,$AA$27:AD27))*6%-SUM($AA$29:AC29)),0),0) -> 0 | AE29: =IF(SUM($AA$4:AE4)-SUM($AA$12:AE12,$AA$17:AE17,$AA$19:AE19,$AA$22:AE22,$AA$27:AE27)>0,MAX(((SUM($AA$4:AE4)-SUM($AA$12:AE12,$AA$17:AE17,$AA$19:AE19,$AA$22:AE22,$AA$27:AE27))*6%-SUM($AA$29:AD29)),0),0) -> 0 | AF29: =IF(SUM($AA$4:AF4)-SUM($AA$12:AF12,$AA$17:AF17,$AA$19:AF19,$AA$22:AF22,$AA$27:AF27)>0,MAX(((SUM($AA$4:AF4)-SUM($AA$12:AF12,$AA$17:AF17,$AA$19:AF19,$AA$22:AF22,$AA$27:AF27))*6%-SUM($AA$29:AE29)),0),0) -> 5.0866527 | AG29: =IF(SUM($AA$4:AG4)-SUM($AA$12:AG12,$AA$17:AG17,$AA$19:AG19,$AA$22:AG22,$AA$27:AG27)>0,MAX(((SUM($AA$4:AG4)-SUM($AA$12:AG12,$AA$17:AG17,$AA$19:AG19,$AA$22:AG22,$AA$27:AG27))*6%-SUM($AA$29:AF29)),0),0) -> 4.0095238 | AH29: =IF(SUM($AA$4:AH4)-SUM($AA$12:AH12,$AA$17:AH17,$AA$19:AH19,$AA$22:AH22,$AA$27:AH27)>0,MAX(((SUM($AA$4:AH4)-SUM($AA$12:AH12,$AA$17:AH17,$AA$19:AH19,$AA$22:AH22,$AA$27:AH27))*6%-SUM($AA$29:AG29)),0),0) -> 10.020845 | AI29: =IF(SUM($AA$4:AI4)-SUM($AA$12:AI12,$AA$17:AI17,$AA$19:AI19,$AA$22:AI22,$AA$27:AI27)>0,MAX(((SUM($AA$4:AI4)-SUM($AA$12:AI12,$AA$17:AI17,$AA$19:AI19,$AA$22:AI22,$AA$27:AI27))*6%-SUM($AA$29:AH29)),0),0) -> 11.786882 | AJ29: =IF(SUM($AA$4:AJ4)-SUM($AA$12:AJ12,$AA$17:AJ17,$AA$19:AJ19,$AA$22:AJ22,$AA$27:AJ27)>0,MAX(((SUM($AA$4:AJ4)-SUM($AA$12:AJ12,$AA$17:AJ17,$AA$19:AJ19,$AA$22:AJ22,$AA$27:AJ27))*6%-SUM($AA$29:AI29)),0),0) -> 13.55292 | ... AM29: =IF(SUM($AA$4:AM4)-SUM($AA$12:AM12,$AA$17:AM17,$AA$19:AM19,$AA$22:AM22,$AA$27:AM27)>0,MAX(((SUM($AA$4:AM4)-SUM($AA$12:AM12,$AA$17:AM17,$AA$19:AM19,$AA$22:AM22,$AA$27:AM27))*6%-SUM($AA$29:AL29)),0),0) -> 21.672278 | AN29: =SUM(AB29:AM29) -> 111.97925 | AO29: =N29+AA29+AN29 -> 123.84088
A30: 附加税及其他 | C30: =C29*12%+SUM(B4,B12,B17,B19,B22,B27)*0.03% -> 0.0042901766 | D30: =D29*12%+SUM(C4,C12,C17,C19,C22,C27)*0.03% -> 0.0042901766 | E30: =E29*12%+SUM(D4,D12,D17,D19,D22,D27)*0.03% -> 0.0048208369 | F30: =F29*12%+SUM(E4,E12,E17,E19,E22,E27)*0.03% -> 0.013765648 | G30: =G29*12%+SUM(F4,F12,F17,F19,F22,F27)*0.03% -> 0.02324112 | H30: =H29*12%+SUM(G4,G12,G17,G19,G22,G27)*0.03% -> 0.042192063 | I30: =I29*12%+SUM(H4,H12,H17,H19,H22,H27)*0.03% -> 0.054924994 | J30: =J29*12%+SUM(I4,I12,I17,I19,I22,I27)*0.03% -> 0.067558956 | ... M30: =M29*12%+SUM(L4,L12,L17,L19,L22,L27)*0.03% -> 0.096172871 | N30: =SUM(B30:M30) -> 0.47569622 | O30: =O29*12%+SUM(M4,M12,M17,M19,M22,M27)*0.03% -> 0.10564834 | P30: =P29*12%+SUM(O4,O12,O17,O19,O22,O27)*0.03% -> 0.16358444 | Q30: =Q29*12%+SUM(P4,P12,P17,P19,P22,P27)*0.03% -> 0.17806623 | R30: =R29*12%+SUM(Q4,Q12,Q17,Q19,Q22,Q27)*0.03% -> 0.3056427 | S30: =S29*12%+SUM(R4,R12,R17,R19,R22,R27)*0.03% -> 0.31835308 | T30: =T29*12%+SUM(S4,S12,S17,S19,S22,S27)*0.03% -> 0.33106346 | U30: =U29*12%+SUM(T4,T12,T17,T19,T22,T27)*0.03% -> 0.34377383 | V30: =V29*12%+SUM(U4,U12,U17,U19,U22,U27)*0.03% -> 0.35648421 | W30: =W29*12%+SUM(V4,V12,V17,V19,V22,V27)*0.03% -> 0.36919459 | ... Z30: =Z29*12%+SUM(Y4,Y12,Y17,Y19,Y22,Y27)*0.03% -> 0.39870072 | AA30: =SUM(O30:Z30) -> 3.5927913 | AB30: =AB29*12%+SUM(Z4,Z12,Z17,Z19,Z22,Z27)*0.03% -> 1.7959702 | AC30: =AC29*12%+SUM(AB4,AB12,AB17,AB19,AB22,AB27)*0.03% -> 0.33370332 | AD30: =AD29*12%+SUM(AC4,AC12,AC17,AC19,AC22,AC27)*0.03% -> 0.40988068 | AE30: =AE29*12%+SUM(AD4,AD12,AD17,AD19,AD22,AD27)*0.03% -> 0.49879389 | AF30: =AF29*12%+SUM(AE4,AE12,AE17,AE19,AE22,AE27)*0.03% -> 1.1981054 | AG30: =AG29*12%+SUM(AF4,AF12,AF17,AF19,AF22,AF27)*0.03% -> 1.1958688 | AH30: =AH29*12%+SUM(AG4,AG12,AG17,AG19,AG22,AG27)*0.03% -> 2.0654726 | AI30: =AI29*12%+SUM(AH4,AH12,AH17,AH19,AH22,AH27)*0.03% -> 2.3831896 | AJ30: =AJ29*12%+SUM(AI4,AI12,AI17,AI19,AI22,AI27)*0.03% -> 2.722133 | ... AM30: =AM29*12%+SUM(AL4,AL12,AL17,AL19,AL22,AL27)*0.03% -> 4.141472 | AN30: =SUM(AB30:AM30) -> 23.242165 | AO30: =N30+AA30+AN30 -> 27.310653
A31: 净现金流 | B31: =B3-B6-B28 -> 941.11608 | C31: =C3-C6-C28 -> -58.888212 | D31: =D3-D6-D28 -> -60.65708 | E31: =E3-E6-E28 -> -56.511384 | F31: =F3-F6-F28 -> -54.142971 | G31: =G3-G6-G28 -> -49.397729 | H31: =H3-H6-H28 -> -46.576762 | I31: =I3-I6-I28 -> -43.419683 | ... AO31: =AO3-AO6-AO28 -> 2226.314
A32: 累计现金流 | C32: =B31+C31 -> 882.22787 | D32: =C32+D31 -> 821.57079 | E32: =D32+E31 -> 765.0594 | F32: =E32+F31 -> 710.91643 | G32: =F32+G31 -> 661.5187 | H32: =G32+H31 -> 614.94194 | I32: =H32+I31 -> 571.52226 | J32: =I32+J31 -> 528.10881 | K32: =J32+K31 -> 467.12936 | ... M32: =L32+M31 -> 352.27515 | O32: =M32+O31 -> 1801.0154 | P32: =O32+P31 -> 1750.8014 | Q32: =P32+Q31 -> 1701.5958 | R32: =Q32+R31 -> 1652.3429 | S32: =R32+S31 -> 1604.1149 | T32: =S32+T31 -> 1556.9117 | U32: =T32+U31 -> 1510.7333 | V32: =U32+V31 -> 1465.5798 | W32: =V32+W31 -> 1421.4511 | ... Z32: =Y32+Z31 -> 1153.0137 | AB32: =Z32+AB31 -> 1992.8023 | AC32: =AB32+AC31 -> 1910.2733 | AD32: =AC32+AD31 -> 1848.2718 | AE32: =AD32+AE31 -> 1806.7852 | AF32: =AE32+AF31 -> 1788.9466 | AG32: =AF32+AG31 -> 1730.8666 | AH32: =AG32+AH31 -> 1766.0944 | AI32: =AH32+AI31 -> 1828.6723 | AJ32: =AI32+AJ31 -> 1918.5793 | ... AM32: =AL32+AM31 -> 2226.314
A33: 后续三个月固定成本 | C33: =SUM(D7:F7,D12:F12,D17:F17,D22:F22,D28:F28) -> 178.44351 | D33: =SUM(E7:G7,E12:G12,E17:G17,E22:G22,E28:G28) -> 176.69359 | E33: =SUM(F7:H7,F12:H12,F17:H17,F22:H22,F28:H28) -> 177.06086 | F33: =SUM(G7:I7,G12:I12,G17:I17,G22:I22,G28:I28) -> 177.43191 | G33: =SUM(H7:J7,H12:J12,H17:J17,H22:J22,H28:J28) -> 180.16461 | H33: =SUM(I7:K7,I12:K12,I17:K17,I22:K22,I28:K28) -> 202.49183 | I33: =SUM(J7:L7,J12:L12,J17:L17,J22:L22,J28:L28) -> 224.81527 | J33: =SUM(K7:M7,K12:M12,K17:M17,K22:M22,K28:M28) -> 244.77706 | K33: =SUM(L7:O7,L12:O12,L17:O17,L22:O22,L28:O28)-$N$7-$N$12-$N$17-$N$22-$N$28 -> 250.87813 | L33: =SUM(M7:P7,M12:P12,M17:P17,M22:P22,M28:P28)-$N$7-$N$12-$N$17-$N$22-$N$28 -> 257.02818 | M33: =SUM(O7:Q7,O12:Q12,O17:Q17,O22:Q22,O28:Q28) -> 263.26423 | O33: =SUM(P7:R7,P12:R12,P17:R17,P22:R22,P28:R28) -> 264.56866 | P33: =SUM(Q7:S7,Q12:S12,Q17:S17,Q22:S22,Q28:S28) -> 265.89409 | Q33: =SUM(R7:T7,R12:T12,R17:T17,R22:T22,R28:T28) -> 267.20298 | R33: =SUM(S7:U7,S12:U12,S17:U17,S22:U22,S28:U28) -> 267.43979 | S33: =SUM(T7:V7,T12:V12,T17:V17,T22:V22,T28:V28) -> 267.6766 | T33: =SUM(U7:W7,U12:W12,U17:W17,U22:W22,U28:W28) -> 267.91341 | U33: =SUM(V7:X7,V12:X12,V17:X17,V22:X22,V28:X28) -> 318.84956 | V33: =SUM(W7:Y7,W12:Y12,W17:Y17,W22:Y22,W28:Y28) -> 364.83767 | W33: =SUM(X7:Z7,X12:Z12,X17:Z17,X22:Z22,X28:Z28) -> 410.82419 | X33: =SUM(Y7:AB7,Y12:AB12,Y17:AB17,Y22:AB22,Y28:AB28)-SUM($AA$7,$AA$12,$AA$17,$AA$22) -> 516.96983 | Y33: =SUM(Z7:AC7,Z12:AC12,Z17:AC17,Z22:AC22,Z28:AC28)-SUM($AA$7,$AA$12,$AA$17,$AA$22) -> 555.4516 | Z33: =SUM(AB7:AD7,AB12:AD12,AB17:AD17,AB22:AD22,AB28:AD28) -> 578.47777 | AB33: =SUM(AC7:AE7,AC12:AE12,AC17:AE17,AC22:AE22,AC28:AE28) -> 521.5643 | AC33: =SUM(AD7:AF7,AD12:AF12,AD17:AF17,AD22:AF22,AD28:AF28) -> 527.51536 | AD33: =SUM(AE7:AG7,AE12:AG12,AE17:AG17,AE22:AG22,AE28:AG28) -> 603.06559 | AE33: =SUM(AF7:AH7,AF12:AH12,AF17:AH17,AF22:AH22,AF28:AH28) -> 614.65311 | AF33: =SUM(AG7:AI7,AG12:AI12,AG17:AI17,AG22:AI22,AG28:AI28) -> 622.53842 | AG33: =SUM(AH7:AJ7,AH12:AJ12,AH17:AJ17,AH22:AJ22,AH28:AJ28) -> 562.85337 | AH33: =SUM(AI7:AK7,AI12:AK12,AI17:AK17,AI22:AK22,AI28:AK28) -> 635.13028 | AI33: =SUM(AJ7:AL7,AJ12:AL12,AJ17:AL17,AJ22:AL22,AJ28:AL28) -> 701.88596 | AJ33: =SUM(AK7:AM7,AK12:AM12,AK17:AM17,AK22:AM22,AK28:AM28) -> 799.27654 | AK33: =$AJ$33 -> 799.27654 | AL33: =$AJ$33 -> 799.27654 | AM33: =$AJ$33 -> 799.27654
A34: 是否存在资金需求 | C34: =IF(C32>C33,"","是") | D34: =IF(D32>D33,"","是") | E34: =IF(E32>E33,"","是") | F34: =IF(F32>F33,"","是") | G34: =IF(G32>G33,"","是") | H34: =IF(H32>H33,"","是") | I34: =IF(I32>I33,"","是") | J34: =IF(J32>J33,"","是") | ... M34: =IF(M32>M33,"","是") | O34: =IF(O32>O33,"","是") | P34: =IF(P32>P33,"","是") | Q34: =IF(Q32>Q33,"","是") | R34: =IF(R32>R33,"","是") | S34: =IF(S32>S33,"","是") | T34: =IF(T32>T33,"","是") | U34: =IF(U32>U33,"","是") | V34: =IF(V32>V33,"","是") | ... Z34: =IF(Z32>Z33,"","是") | AB34: =IF(AB32>AB33,"","是") | AC34: =IF(AC32>AC33,"","是") | AD34: =IF(AD32>AD33,"","是") | AE34: =IF(AE32>AE33,"","是") | AF34: =IF(AF32>AF33,"","是") | AG34: =IF(AG32>AG33,"","是") | AH34: =IF(AH32>AH33,"","是") | AI34: =IF(AI32>AI33,"","是") | ... AM34: =IF(AM32>AM33,"","是")
AM35: =AM31/(AM4*0.2) -> 0.23039287
A36: 日均广告请求次数（万次） | E36: 30 | F36: 60 | G36: 120 | H36: 160 | I36: 200 | J36: 230 | K36: 260 | L36: 290 | M36: 320 | O36: 330 | P36: 340 | Q36: 350 | R36: 360 | S36: 370 | T36: 380 | U36: 390 | V36: 400 | W36: 410 | X36: 420 | Y36: 430 | Z36: 440 | AB36: 480 | AC36: 620 | AD36: 760 | AE36: 900 | AF36: 1100 | AG36: 1300 | AH36: 1500 | AI36: 1700 | AJ36: 1900 | AK36: 2100 | AL36: 2400 | AM36: 3022
A37: CPM单价（元） | B37: =项目预算表!$D$20 -> 20 | C37: =项目预算表!$D$20 -> 20 | D37: =项目预算表!$D$20 -> 20 | E37: =项目预算表!$D$20 -> 20 | F37: =项目预算表!$D$20 -> 20 | G37: =项目预算表!$D$20 -> 20 | H37: =项目预算表!$E$20 -> 20 | I37: =项目预算表!$E$20 -> 20 | J37: =项目预算表!$E$20 -> 20 | K37: =项目预算表!$E$20 -> 20 | L37: =项目预算表!$E$20 -> 20 | M37: =项目预算表!$E$20 -> 20 | O37: =项目预算表!$F$20 -> 30 | P37: =项目预算表!$F$20 -> 30 | Q37: =项目预算表!$F$20 -> 30 | R37: =项目预算表!$F$20 -> 30 | S37: =项目预算表!$F$20 -> 30 | T37: =项目预算表!$F$20 -> 30 | U37: =项目预算表!$F$20 -> 30 | V37: =项目预算表!$F$20 -> 30 | ... Z37: =项目预算表!$F$20 -> 30 | AB37: =项目预算表!$G$20 -> 40 | AC37: =项目预算表!$G$20 -> 40 | AD37: =项目预算表!$G$20 -> 40 | AE37: =项目预算表!$G$20 -> 40 | AF37: =项目预算表!$G$20 -> 40 | AG37: =项目预算表!$G$20 -> 40 | AH37: =项目预算表!$G$20 -> 40 | AI37: =项目预算表!$G$20 -> 40 | ... AM37: =项目预算表!$G$20 -> 40
A38: 广告填充率 | B38: =项目预算表!$D$19 -> 1 | C38: =项目预算表!$D$19 -> 1 | D38: =项目预算表!$D$19 -> 1 | E38: =项目预算表!$D$19 -> 1 | F38: =项目预算表!$D$19 -> 1 | G38: =项目预算表!$D$19 -> 1 | H38: =项目预算表!$E$19 -> 1 | I38: =项目预算表!$E$19 -> 1 | J38: =项目预算表!$E$19 -> 1 | K38: =项目预算表!$E$19 -> 1 | L38: =项目预算表!$E$19 -> 1 | M38: =项目预算表!$E$19 -> 1 | O38: =项目预算表!$F$19 -> 1 | P38: =项目预算表!$F$19 -> 1 | Q38: =项目预算表!$F$19 -> 1 | R38: =项目预算表!$F$19 -> 1 | S38: =项目预算表!$F$19 -> 1 | T38: =项目预算表!$F$19 -> 1 | U38: =项目预算表!$F$19 -> 1 | V38: =项目预算表!$F$19 -> 1 | ... Z38: =项目预算表!$F$19 -> 1 | AB38: =项目预算表!$G$19 -> 1 | AC38: =项目预算表!$G$19 -> 1 | AD38: =项目预算表!$G$19 -> 1 | AE38: =项目预算表!$G$19 -> 1 | AF38: =项目预算表!$G$19 -> 1 | AG38: =项目预算表!$G$19 -> 1 | AH38: =项目预算表!$G$19 -> 1 | AI38: =项目预算表!$G$19 -> 1 | ... AM38: =项目预算表!$G$19 -> 1
A39: 平台交易佣金比例 | B39: =项目预算表!$D$21 -> 0.2 | C39: =项目预算表!$D$21 -> 0.2 | D39: =项目预算表!$D$21 -> 0.2 | E39: =项目预算表!$D$21 -> 0.2 | F39: =项目预算表!$D$21 -> 0.2 | G39: =项目预算表!$D$21 -> 0.2 | H39: =项目预算表!$E$21 -> 0.2 | I39: =项目预算表!$E$21 -> 0.2 | J39: =项目预算表!$E$21 -> 0.2 | K39: =项目预算表!$E$21 -> 0.2 | L39: =项目预算表!$E$21 -> 0.2 | M39: =项目预算表!$E$21 -> 0.2 | O39: =项目预算表!$F$21 -> 0.2 | P39: =项目预算表!$F$21 -> 0.2 | Q39: =项目预算表!$F$21 -> 0.2 | R39: =项目预算表!$F$21 -> 0.2 | S39: =项目预算表!$F$21 -> 0.2 | T39: =项目预算表!$F$21 -> 0.2 | U39: =项目预算表!$F$21 -> 0.2 | V39: =项目预算表!$F$21 -> 0.2 | ... Z39: =项目预算表!$F$21 -> 0.2 | AB39: =项目预算表!$G$21 -> 0.2 | AC39: =项目预算表!$G$21 -> 0.2 | AD39: =项目预算表!$G$21 -> 0.2 | AE39: =项目预算表!$G$21 -> 0.2 | AF39: =项目预算表!$G$21 -> 0.2 | AG39: =项目预算表!$G$21 -> 0.2 | AH39: =项目预算表!$G$21 -> 0.2 | AI39: =项目预算表!$G$21 -> 0.2 | ... AM39: =项目预算表!$G$21 -> 0.2
A40: 市场推广费占收入比例 | B40: =项目预算表!$E$23 -> 0 | C40: =项目预算表!$E$23 -> 0 | D40: =项目预算表!$E$23 -> 0 | E40: =项目预算表!$E$23 -> 0 | F40: =项目预算表!$E$23 -> 0 | G40: =项目预算表!$E$23 -> 0 | H40: =项目预算表!$E$23 -> 0 | I40: =项目预算表!$E$23 -> 0 | ... M40: =项目预算表!$E$23 -> 0 | O40: =项目预算表!$F$23 -> 0.05 | P40: =项目预算表!$F$23 -> 0.05 | Q40: =项目预算表!$F$23 -> 0.05 | R40: =项目预算表!$F$23 -> 0.05 | S40: =项目预算表!$F$23 -> 0.05 | T40: =项目预算表!$F$23 -> 0.05 | U40: =项目预算表!$F$23 -> 0.05 | V40: =项目预算表!$F$23 -> 0.05 | ... Z40: =项目预算表!$F$23 -> 0.05 | AB40: =项目预算表!$G$23 -> 0.05 | AC40: =项目预算表!$G$23 -> 0.05 | AD40: =项目预算表!$G$23 -> 0.05 | AE40: =项目预算表!$G$23 -> 0.05 | AF40: =项目预算表!$G$23 -> 0.05 | AG40: =项目预算表!$G$23 -> 0.05 | AH40: =项目预算表!$G$23 -> 0.05 | AI40: =项目预算表!$G$23 -> 0.05 | ... AM40: =项目预算表!$G$23 -> 0.05
...

Sheet 年度运营成本测算明细
A1: 百视通CTV程序化广告能力建设项目年度运营成本预算表（3年预测）
A2: 成本类别 | B2: 三年合计(万元) | C2: 第1年(万元) | F2: 第2年(万元) | G2: 第3年(万元) | H2: 测算说明
C3: 合计 | D3: POC前段 | E3: POC后段
A4: 一、人力成本
A5: 1. 管理团队（项目负责人、技术负责人、财务负责人） | B5: =SUM(C5,F5:G5) -> 466.95 | C5: =SUM(D5:E5) -> 123.75 | D5: =项目预算表!E71*项目预算表!$I$25/12*3 -> 27.5 | E5: =项目预算表!E71*项目预算表!$I$25/12*6+项目预算表!F71*项目预算表!$I$25/12*3 -> 96.25 | F5: =项目预算表!F71*项目预算表!$I$25/12*9+项目预算表!G71*项目预算表!$I$25/12*3 -> 165 | G5: =项目预算表!G71*项目预算表!$I$25*(1+8%)/12*9+项目预算表!H71*项目预算表!$I$25/12*3*(1+8%) -> 178.2 | H5: 55万元/人年；第一年2人，第二年3人，第三年5人，人员前置3个月到岗
A6: 2. 技术团队（DSP/SSP开发、运维等） | B6: =SUM(C6,F6:G6) -> 1037.85 | C6: =SUM(D6:E6) -> 275 | D6: =项目预算表!E72*项目预算表!$I$25/12*3 -> 68.75 | E6: =项目预算表!E72*项目预算表!$I$25/12*6+项目预算表!F72*项目预算表!$I$25/12*3 -> 206.25 | F6: =项目预算表!F72*项目预算表!$I$25/12*9+项目预算表!G72*项目预算表!$I$25/12*3 -> 302.5 | G6: =项目预算表!G72*项目预算表!$I$25*(1+8%)/12*9+项目预算表!H72*项目预算表!$I$25/12*3*(1+8%) -> 460.35 | H6: 55万元/人年，第一年5人，第二年5人，第三年10人，人员前置3个月到岗
A7: 3. 商务与运营团队 | B7: =SUM(C7,F7:G7) -> 1354.1 | C7: =SUM(D7:E7) -> 151.25 | D7: =项目预算表!E73*项目预算表!$I$25/12*3 -> 27.5 | E7: =项目预算表!E73*项目预算表!$I$25/12*6+项目预算表!F73*项目预算表!$I$25/12*3 -> 123.75 | F7: =项目预算表!F73*项目预算表!$I$25/12*9+项目预算表!G73*项目预算表!$I$25/12*3 -> 371.25 | G7: =项目预算表!G73*项目预算表!$I$25*(1+8%)/12*9+项目预算表!H73*项目预算表!$I$25/12*3*(1+8%) -> 831.6 | H7: 55万元/人年；第一年2人，第二年5人，第三年12人，人员前置3个月到岗
A8: 4. 业务支撑团队（财务、法务、合规等） | B8: =SUM(C8,F8:G8) -> 280.4 | C8: =SUM(D8:E8) -> 50 | D8: =项目预算表!E74*项目预算表!$I$26/12*3 -> 10 | E8: =项目预算表!E74*项目预算表!$I$26/12*6+项目预算表!F74*项目预算表!$I$26/12*3 -> 40 | F8: =项目预算表!F74*项目预算表!$I$26/12*9+项目预算表!G74*项目预算表!$I$26/12*3 -> 90 | G8: =项目预算表!G74*项目预算表!$I$26*(1+8%)/12*9+项目预算表!H74*项目预算表!$I$26/12*3*(1+8%) -> 140.4 | H8: 40万元/人年；第一年1人，第二年2人，第三年3人，人员前置3个月到岗
A9: 人力成本小计 | B9: =SUM(C9,F9:G9) -> 3139.3 | C9: =SUM(C5:C8) -> 600 | D9: =SUM(D5:D8) -> 133.75 | E9: =SUM(E5:E8) -> 466.25 | F9: =SUM(F5:F8) -> 928.75 | G9: =SUM(G5:G8) -> 1610.55
A10: 二、技术成本
A11: 1. 云服务器、数据库、缓存、日志服务、负载均衡、数据存储等 | B11: =SUM(C11,F11:G11) -> 452.83019 | C11: =SUM(D11:E11) -> 28.301887 | D11: =30/12*3/1.06 -> 7.0754717 | E11: =30/12*9/1.06 -> 21.226415 | F11: =150/1.06 -> 141.50943 | G11: =300/1.06 -> 283.01887 | H11: 程序化广告平台DSP、SSP等系统服务端部署、运营
A12: 2. 数据传输 | B12: =SUM(C12,F12:G12) -> 363.84906 | C12: 28 | D12: =28/12*3/1.06 -> 6.6037736 | E12: =28/12*9/1.06 -> 19.811321 | F12: =76/1.06 -> 71.698113 | G12: =280/1.06 -> 264.15094 | H12: 终端广告请求数预估：第一年280万次/天，第二年760万次/天，第三年2800万次/天；平均每次请求（1张图片+1段视频）数据传输量7MB（其中视频6MB，图片1MB），流量单价0.04元/GB
A15: 技术成本小计 | B15: =SUM(C15,F15:G15) -> 815.09434 | C15: =SUM(D15:E15) -> 54.716981 | D15: =SUM(D11:D14) -> 13.679245 | E15: =SUM(E11:E14) -> 41.037736 | F15: =SUM(F11:F14) -> 213.20755 | G15: =SUM(G11:G14) -> 547.16981
A16: 三、广告位成本
A17: IPTV/OTT业务广告位采购成本 | B17: =SUM(C17,F17:G17) -> 94.339623 | C17: =SUM(D17:E17) -> 94.339623 | D17: =100/1.06 -> 94.339623 | F17: 0 | H17: 湖北移动、安徽移动用户贴片广告位库存数量，每天250-300个CPM，CPM单价10元折算；或者向第三方采购
A18: 广告位成本小计 | B18: =B17 -> 94.339623 | C18: =C17 -> 94.339623 | D18: =D17 -> 94.339623 | E18: =E17 -> 0 | F18: =F17 -> 0 | G18: =G17 -> 0
A19: 四、商务合作与其他运营成本 | B19: =SUM(C19,F19:G19) -> 94.339623 | C19: =SUM(D19:E19) -> 94.339623 | D19: =SUM(D17:D17) -> 94.339623 | F19: =SUM(F17:F17) -> 0 | G19: =SUM(G17:G17) -> 0
A20: 1. 渠道合作与分成 | B20: =SUM(C20,F20:G20) -> 1499.9094 | C20: =SUM(D20:E20) -> 56.716981 | D20: =项目预算表!D32*项目预算表!D22 -> 0 | E20: =项目预算表!E32*项目预算表!E22 -> 56.716981 | F20: =项目预算表!F32*项目预算表!F22 -> 235.35849 | G20: =项目预算表!G32*项目预算表!G22 -> 1207.834 | H20: 按全年净收入30%向Moloco分账
A21: 2. 市场推广与商务拓展 | B21: =SUM(C21,F21:G21) -> 240.53208 | C21: =SUM(D21:E21) -> 0 | D21: =项目预算表!D32*项目预算表!D23 -> 0 | E21: =项目预算表!E32*项目预算表!E23 -> 0 | F21: =项目预算表!F32*项目预算表!F23 -> 39.226415 | G21: =项目预算表!G32*项目预算表!G23 -> 201.30566 | H21: 第二年开始按全年净收入5%测算
A22: 商务合作与其他运营成本小计 | B22: =SUM(C22,F22:G22) -> 1740.4415 | C22: =SUM(D22:E22) -> 56.716981 | D22: =SUM(D20:D21) -> 0 | E22: =SUM(E20:E21) -> 56.716981 | F22: =SUM(F20:F21) -> 274.58491 | G22: =SUM(G20:G21) -> 1409.1396
A23: 五、办公运营成本 | C23: =SUM(D23:E23) -> 0 | D23: 0
A24: 中介机构费 | B24: =SUM(C24,F24:G24) -> 141.50943 | C24: =SUM(D24:E24) -> 0 | D24: 0 | E24: 0 | F24: 0 | G24: =150/1.06 -> 141.50943 | H24: 合资公司日常评估费、审计费
A25: 场地费（含水电） | B25: =SUM(C25,F25:G25) -> 89.983945 | C25: =SUM(D25:E25) -> 9.5298165 | D25: =((3.35*50*180+15*50*6)/10000+1.3/2)/1.09 -> 3.7752294 | E25: =((3.35*50*90+15*50*3)/10000+1.3/4+(3.35*100*90+15*100*3)/10000+3/4)/1.09 -> 5.7545872 | F25: =((3.35*100*270+15*100*9)/10000+(3.35*250*90+15*250*3)/10000+3)/1.09 -> 20.236239 | G25: =((3.35*250*270+15*250*9)/10000+(3.35*1000*90+15*1000*3)/10000+5)/1.09 -> 60.21789 | H25: 按智媒城租赁合同，日租金3.35元/天/平方米，物业费15元/月/平方米测算；7人租用50平，15人租用100平，30人租赁250平，100人租赁1000平，前置三个月租用
A26: 招聘费 | B26: =SUM(C26,F26:G26) -> 16.438679 | C26: =SUM(D26:E26) -> 4.1273585 | D26: =3*50/12*50%*30%/1.06 -> 1.7688679 | E26: =50/12*4*30%*50%/1.06 -> 2.3584906 | F26: =50/12*9*30%*50%/1.06 -> 5.3066038 | G26: =50/12*11*30%*50%*1.08/1.06 -> 7.004717 | H26: 30%技术与商务需通过猎头外聘，按月薪50%支付猎头费，招聘费前置3个月
A27: 其他管理费用 | B27: =SUM(C27,F27:G27) -> 85.125 | C27: =SUM(D27:E27) -> 16.875 | D27: =项目预算表!E75*1.5/12*3 -> 3.75 | E27: =项目预算表!E75*1.5/12*6+项目预算表!F75*1.5/12*3 -> 13.125 | F27: =项目预算表!F75*1.5/12*9+项目预算表!G75*1.5/12*3 -> 26.25 | G27: =项目预算表!G75*1.5/12*9+项目预算表!H75*1.5/12*3 -> 42 | H27: 参考百视通25年人均管理费1万*1.5
A28: 办公运营成本小计 | B28: =SUM(C28,F28:G28) -> 333.05706 | C28: =SUM(D28:E28) -> 30.532175 | D28: =SUM(D24:D27) -> 9.2940973 | E28: =SUM(E24:E27) -> 21.238078 | F28: =SUM(F24:F27) -> 51.792842 | G28: =SUM(G24:G27) -> 250.73204
A29: 六、其他税费 | B29: =SUM(C29,F29:G29) -> 27.310653 | C29: =项目预算表!C47 -> 0.47569622 | D29: =项目预算表!D47 -> 0.0085803531 | E29: =项目预算表!E47 -> 0.46711586 | F29: =项目预算表!F47 -> 3.5927913 | G29: =项目预算表!G47 -> 23.242165
A30: 年度运营总成本合计 | B30: =SUM(C30,F30:G30) -> 6149.5432 | C30: =SUM(C9,C15,C18,C22,C28,C29) -> 836.78146 | D30: =SUM(D9,D15,D18,D22,D28,D29) -> 251.07155 | E30: =SUM(E9,E15,E18,E22,E28,E29) -> 585.70991 | F30: =SUM(F9,F15,F18,F22,F28,F29) -> 1471.9281 | G30: =SUM(G9,G15,G18,G22,G28,G29) -> 3840.8336
A32: 全年流水（盈亏平衡点） | C32: =SUM(C9,C15,C18,C28)/(项目预算表!C21-项目预算表!C21*项目预算表!C22-项目预算表!C21*项目预算表!C23) -> 5996.8368 | D32: =SUM(D9,D15,D18,D28)/(项目预算表!D21-项目预算表!D21*项目预算表!D22-项目预算表!D21*项目预算表!D23) -> 1793.3069 | E32: =SUM(E9,E15,E18,E28)/(项目预算表!E21-项目预算表!E21*项目预算表!E22-项目预算表!E21*项目预算表!E23) -> 3775.1844 | F32: =(SUM(F9,F15,F18,F28))/(项目预算表!F21-项目预算表!F21*项目预算表!F22-项目预算表!F21*项目预算表!F23) -> 9182.6953 | G32: =(SUM(G9,G15,G18,G28))/(项目预算表!G21-项目预算表!G21*项目预算表!G22-项目预算表!G21*项目预算表!G23) -> 18526.553
