Workbook

Sheet 单用户成本与收益
A1: 用户数 | B1: 100000 | C1: CDN单价 | D1: 码率 | E1: 收看分钟数 | F1: 单用户CDN成本 | G1: 月成本（30*分钟数） | H1: cpm价格（元） | I1: 广告次数（开机1次，后续15分钟一次） | J1: 单用户广告收入 | L1: 利润 | M1: 利润率 | O1: 盈亏平衡点 | Q1: 月成本 | R1: 月收入
A2: =B2*$B$1 -> 30000 | B2: 0.3 | C2: 0.04 | D2: 2.3 | E2: 60 | F2: =C2*D2*E2*60/1000/8 -> 0.0414 | G2: =F2*30 -> 1.242 | H2: 10 | I2: 6 | J2: =H2*I2/1000 -> 0.06 | L2: =J2-F2 -> 0.0186 | M2: =L2/J2 -> 0.31 | O2: =F2/I2*1000 -> 6.9 | Q2: =A2*G2 -> 37260 | R2: =J2*30*A2 -> 54000
A3: =B3*$B$1 -> 10000 | B3: 0.1 | C3: 0.04 | D3: 2.3 | E3: 30 | F3: =C3*D3*E3*60/1000/8 -> 0.0207 | G3: =F3*30 -> 0.621 | H3: 10 | I3: 3 | J3: =H3*I3/1000 -> 0.03 | L3: =J3-F3 -> 0.0093 | M3: =L3/J3 -> 0.31 | O3: =F3/I3*1000 -> 6.9 | Q3: =F3*A3 -> 207 | R3: =J3*30*A3 -> 9000
A4: =B4*$B$1 -> 10000 | B4: 0.1 | C4: 0.04 | D4: 2.3 | E4: 15 | F4: =C4*D4*E4*60/1000/8 -> 0.01035 | G4: =F4*30 -> 0.3105 | H4: 10 | I4: 2 | J4: =H4*I4/1000 -> 0.02 | L4: =J4-F4 -> 0.00965 | M4: =L4/J4 -> 0.4825 | O4: =F4/I4*1000 -> 5.175 | Q4: =F4*A4 -> 103.5 | R4: =J4*30*A4 -> 6000
A5: =B5*$B$1 -> 20000 | B5: 0.2 | C5: 0.04 | D5: 2.3 | E5: 5 | F5: =C5*D5*E5*60/1000/8 -> 0.00345 | G5: =F5*30 -> 0.1035 | H5: 10 | I5: 1 | J5: =H5*I5/1000 -> 0.01 | L5: =J5-F5 -> 0.00655 | M5: =L5/J5 -> 0.655 | O5: =F5/I5*1000 -> 3.45 | Q5: =F5*A5 -> 69 | R5: =J5*30*A5 -> 6000
A6: =B6*$B$1 -> 30000 | B6: 0.3 | C6: 0.04 | D6: 2.3 | E6: 1 | F6: =C6*D6*E6*60/1000/8 -> 0.00069 | G6: =F6*30 -> 0.0207 | H6: 10 | I6: 1 | J6: =H6*I6/1000 -> 0.01 | L6: =J6-F6 -> 0.00931 | M6: =L6/J6 -> 0.931 | O6: =F6/I6*1000 -> 0.69 | Q6: =F6*A6 -> 20.7 | R6: =J6*30*A6 -> 9000
Q7: =SUM(Q2:Q6) -> 37660.2 | R7: =SUM(R2:R6) -> 84000
A9: =B9*$B$1 -> 30000 | B9: 0.3 | C9: 0.04 | D9: 2.3 | E9: 60 | F9: =C9*D9*E9*60/1000/8 -> 0.0414 | G9: =F9*30 -> 1.242 | H9: 5 | I9: 5 | J9: =H9*I9/1000 -> 0.025 | L9: =J9-F9 -> -0.0164 | M9: =L9/J9 -> -0.656 | O9: =F9/I9*1000 -> 8.28 | Q9: =A9*G9 -> 37260 | R9: =J9*30*A9 -> 22500
A10: =B10*$B$1 -> 10000 | B10: 0.1 | C10: 0.04 | D10: 2.3 | E10: 30 | F10: =C10*D10*E10*60/1000/8 -> 0.0207 | G10: =F10*30 -> 0.621 | H10: 5 | I10: 3 | J10: =H10*I10/1000 -> 0.015 | L10: =J10-F10 -> -0.0057 | M10: =L10/J10 -> -0.38 | O10: =F10/I10*1000 -> 6.9 | Q10: =F10*A10 -> 207 | R10: =J10*30*A10 -> 4500
A11: =B11*$B$1 -> 10000 | B11: 0.1 | C11: 0.04 | D11: 2.3 | E11: 15 | F11: =C11*D11*E11*60/1000/8 -> 0.01035 | G11: =F11*30 -> 0.3105 | H11: 5 | I11: 2 | J11: =H11*I11/1000 -> 0.01 | L11: =J11-F11 -> -0.00035 | M11: =L11/J11 -> -0.035 | O11: =F11/I11*1000 -> 5.175 | Q11: =F11*A11 -> 103.5 | R11: =J11*30*A11 -> 3000
A12: =B12*$B$1 -> 20000 | B12: 0.2 | C12: 0.04 | D12: 2.3 | E12: 5 | F12: =C12*D12*E12*60/1000/8 -> 0.00345 | G12: =F12*30 -> 0.1035 | H12: 5 | I12: 1 | J12: =H12*I12/1000 -> 0.005 | L12: =J12-F12 -> 0.00155 | M12: =L12/J12 -> 0.31 | O12: =F12/I12*1000 -> 3.45 | Q12: =F12*A12 -> 69 | R12: =J12*30*A12 -> 3000
A13: =B13*$B$1 -> 30000 | B13: 0.3 | C13: 0.04 | D13: 2.3 | E13: 1 | F13: =C13*D13*E13*60/1000/8 -> 0.00069 | G13: =F13*30 -> 0.0207 | H13: 5 | I13: 1 | J13: =H13*I13/1000 -> 0.005 | L13: =J13-F13 -> 0.00431 | M13: =L13/J13 -> 0.862 | O13: =F13/I13*1000 -> 0.69 | Q13: =F13*A13 -> 20.7 | R13: =J13*30*A13 -> 4500
C14: 0.04 | D14: 2.3 | F14: =C14*D14*E14*60/1000/8 -> 0 | G14: =F14*30 -> 0 | H14: 5 | J14: =H14*I14/1000 -> 0 | Q14: =SUM(Q9:Q13) -> 37660.2 | R14: =SUM(R9:R13) -> 37500
C15: 0.04 | D15: 4 | E15: 60 | F15: =C15*D15*E15*60/1000/8 -> 0.072 | G15: =F15*30 -> 2.16 | J15: =H15*I15/1000 -> 0
C17: 提升收益办法：降低CDN单价、提高CPM价格、动态调整广告次数

Sheet 收视用户分布模型
B1: 用户数 | C1: 收视分钟数 | D1: 用户分布占比 | E1: 码率（M） | F1: CDN单价（元） | G1: 成本(元/天) | H1: 广告次数 | I1: CPM价格（元） | J1: 广告收入（元） | K1: CPM价格（元） | L1: 广告收入（元） | M1: 盈亏平衡点CPM
B2: 34 | C2: 60 | D2: =ROUND(B2/$B$7,4) -> 0.2237 | E2: 2.3 | F2: 0.04 | G2: =B2*C2*E2*F2*60/1000/8 -> 1.4076 | H2: =1+INT(C2/15) -> 5 | I2: 5 | J2: =I2*H2*B2/1000 -> 0.85 | K2: 10 | L2: =B2*H2*K2/1000 -> 1.7 | M2: =G2/H2/B2*1000 -> 8.28
B3: 7 | C3: 30 | D3: =ROUND(B3/$B$7,4) -> 0.0461 | E3: 2.3 | F3: 0.04 | G3: =B3*C3*E3*F3*60/1000/8 -> 0.1449 | H3: =1+INT(C3/15) -> 3 | I3: 5 | J3: =I3*H3*B3/1000 -> 0.105 | K3: 10 | L3: =B3*H3*K3/1000 -> 0.21 | M3: =G3/H3/B3*1000 -> 6.9
B4: 4 | C4: 15 | D4: =ROUND(B4/$B$7,4) -> 0.0263 | E4: 2.3 | F4: 0.04 | G4: =B4*C4*E4*F4*60/1000/8 -> 0.0414 | H4: =1+INT(C4/15) -> 2 | I4: 5 | J4: =I4*H4*B4/1000 -> 0.04 | K4: 10 | L4: =B4*H4*K4/1000 -> 0.08 | M4: =G4/H4/B4*1000 -> 5.175
B5: 7 | C5: 5 | D5: =ROUND(B5/$B$7,4) -> 0.0461 | E5: 2.3 | F5: 0.04 | G5: =B5*C5*E5*F5*60/1000/8 -> 0.02415 | H5: =1+INT(C5/15) -> 1 | I5: 5 | J5: =I5*H5*B5/1000 -> 0.035 | K5: 10 | L5: =B5*H5*K5/1000 -> 0.07 | M5: =G5/H5/B5*1000 -> 3.45
B6: 100 | C6: 1 | D6: =ROUND(B6/$B$7,4) -> 0.6579 | E6: 2.3 | F6: 0.04 | G6: =B6*C6*E6*F6*60/1000/8 -> 0.069 | H6: =1+INT(C6/15) -> 1 | I6: 5 | J6: =I6*H6*B6/1000 -> 0.5 | K6: 10 | L6: =B6*H6*K6/1000 -> 1 | M6: =G6/H6/B6*1000 -> 0.69
A7: 长虹合计 | B7: =SUM(B2:B6) -> 152 | G7: =SUM(G2:G6) -> 1.68705 | J7: =SUM(J2:J6) -> 1.53 | L7: =SUM(L2:L6) -> 3.06
B9: 149 | C9: 60 | D9: =ROUND(B9/B$14,4) -> 0.1789 | E9: 2.3 | F9: 0.04 | G9: =B9*C9*E9*F9*60/1000/8 -> 6.1686 | H9: =1+INT(C9/15) -> 5 | I9: 5 | J9: =I9*H9*B9/1000 -> 3.725 | K9: 10 | L9: =B9*H9*K9/1000 -> 7.45
B10: 25 | C10: 30 | D10: =ROUND(B10/B$14,4) -> 0.03 | E10: 2.3 | F10: 0.04 | G10: =B10*C10*E10*F10*60/1000/8 -> 0.5175 | H10: =1+INT(C10/15) -> 3 | I10: 5 | J10: =I10*H10*B10/1000 -> 0.375 | K10: 10 | L10: =B10*H10*K10/1000 -> 0.75
B11: 42 | C11: 15 | D11: =ROUND(B11/B$14,4) -> 0.0504 | E11: 2.3 | F11: 0.04 | G11: =B11*C11*E11*F11*60/1000/8 -> 0.4347 | H11: =1+INT(C11/15) -> 2 | I11: 5 | J11: =I11*H11*B11/1000 -> 0.42 | K11: 10 | L11: =B11*H11*K11/1000 -> 0.84
B12: 39 | C12: 5 | D12: =ROUND(B12/B$14,4) -> 0.0468 | E12: 2.3 | F12: 0.04 | G12: =B12*C12*E12*F12*60/1000/8 -> 0.13455 | H12: =1+INT(C12/15) -> 1 | I12: 5 | J12: =I12*H12*B12/1000 -> 0.195 | K12: 10 | L12: =B12*H12*K12/1000 -> 0.39
B13: 578 | C13: 1 | D13: =ROUND(B13/B$14,4) -> 0.6939 | E13: 2.3 | F13: 0.04 | G13: =B13*C13*E13*F13*60/1000/8 -> 0.39882 | H13: =1+INT(C13/15) -> 1 | I13: 5 | J13: =I13*H13*B13/1000 -> 2.89 | K13: 10 | L13: =B13*H13*K13/1000 -> 5.78
A14: 天津合计 | B14: =SUM(B9:B13) -> 833 | G14: =SUM(G9:G13) -> 7.65417 | J14: =SUM(J9:J13) -> 7.605 | L14: =SUM(L9:L13) -> 15.21
B16: 723 | C16: 60 | D16: =ROUND(B16/$B$21,4) -> 0.2743 | E16: 2.3 | F16: 0.04 | G16: =B16*C16*E16*F16*60/1000/8 -> 29.9322 | H16: =1+INT(C16/15) -> 5 | I16: 5 | J16: =I16*H16*B16/1000 -> 18.075 | K16: 10 | L16: =B16*H16*K16/1000 -> 36.15
B17: 117 | C17: 30 | D17: =ROUND(B17/$B$21,4) -> 0.0444 | E17: 2.3 | F17: 0.04 | G17: =B17*C17*E17*F17*60/1000/8 -> 2.4219 | H17: =1+INT(C17/15) -> 3 | I17: 5 | J17: =I17*H17*B17/1000 -> 1.755 | K17: 10 | L17: =B17*H17*K17/1000 -> 3.51
B18: 186 | C18: 15 | D18: =ROUND(B18/$B$21,4) -> 0.0706 | E18: 2.3 | F18: 0.04 | G18: =B18*C18*E18*F18*60/1000/8 -> 1.9251 | H18: =1+INT(C18/15) -> 2 | I18: 5 | J18: =I18*H18*B18/1000 -> 1.86 | K18: 10 | L18: =B18*H18*K18/1000 -> 3.72
B19: 232 | C19: 5 | D19: =ROUND(B19/$B$21,4) -> 0.088 | E19: 2.3 | F19: 0.04 | G19: =B19*C19*E19*F19*60/1000/8 -> 0.8004 | H19: =1+INT(C19/15) -> 1 | I19: 5 | J19: =I19*H19*B19/1000 -> 1.16 | K19: 10 | L19: =B19*H19*K19/1000 -> 2.32
B20: 1378 | C20: 1 | D20: =ROUND(B20/$B$21,4) -> 0.5228 | E20: 2.3 | F20: 0.04 | G20: =B20*C20*E20*F20*60/1000/8 -> 0.95082 | H20: =1+INT(C20/15) -> 1 | I20: 5 | J20: =I20*H20*B20/1000 -> 6.89 | K20: 10 | L20: =B20*H20*K20/1000 -> 13.78
A21: 湖北合计 | B21: =SUM(B16:B20) -> 2636 | G21: =SUM(G16:G20) -> 36.03042 | J21: =SUM(J16:J20) -> 29.74 | L21: =SUM(L16:L20) -> 59.48
C23: 收视分钟数 | D23: 平均占比
C24: 60 | D24: =AVERAGE(D2,D9,D16) -> 0.22563333
C25: 30 | D25: =AVERAGE(D3,D10,D17) -> 0.040166667
C26: 15 | D26: =AVERAGE(D4,D11,D18) -> 0.0491
C27: 5 | D27: =AVERAGE(D5,D12,D19) -> 0.0603
C28: 1 | D28: =AVERAGE(D6,D13,D20) -> 0.62486667
B31: 长虹 | E31: 天津 | H31: 湖北
A32: 收视分钟数 | B32: 用户数 | C32: 用户分布占比 | E32: 用户数 | F32: 用户分布占比 | H32: 用户数 | I32: 用户分布占比 | J32: 平均占比
A33: 60 | B33: 426 | C33: =B33/$B$41 -> 0.14984172 | E33: 127 | F33: =E33/$E$41 -> 0.15246098 | H33: 643 | I33: =H33/$H$41 -> 0.2439302 | J33: =AVERAGE(C33,F33,I33) -> 0.18207763 | M33: 426 | N33: =M33/$M$41 -> 0.14984172
A34: 30 | B34: 30 | C34: =B34/$B$41 -> 0.010552234 | E34: 47 | F34: =E34/$E$41 -> 0.056422569 | H34: 197 | I34: =H34/$H$41 -> 0.074734446 | J34: =AVERAGE(C34,F34,I34) -> 0.047236416 | M34: 30 | N34: =M34/$M$41 -> 0.010552234
A35: 25 | B35: 38 | C35: =B35/$B$41 -> 0.013366163 | E35: 15 | F35: =E35/$E$41 -> 0.018007203 | H35: 51 | I35: =H35/$H$41 -> 0.019347496 | J35: =AVERAGE(C35,F35,I35) -> 0.016906954 | M35: 38 | N35: =M35/$M$41 -> 0.013366163
A36: 20 | B36: 50 | C36: =B36/$B$41 -> 0.017587056 | E36: 15 | F36: =E36/$E$41 -> 0.018007203 | H36: 67 | I36: =H36/$H$41 -> 0.025417299 | J36: =AVERAGE(C36,F36,I36) -> 0.020337186 | M36: 50 | N36: =M36/$M$41 -> 0.017587056
A37: 15 | B37: 63 | C37: =B37/$B$41 -> 0.02215969 | E37: 12 | F37: =E37/$E$41 -> 0.014405762 | H37: 68 | I37: =H37/$H$41 -> 0.025796662 | J37: =AVERAGE(C37,F37,I37) -> 0.020787371 | M37: 63 | N37: =M37/$M$41 -> 0.02215969
A38: 10 | B38: 71 | C38: =B38/$B$41 -> 0.024973619 | E38: 15 | F38: =E38/$E$41 -> 0.018007203 | H38: 100 | I38: =H38/$H$41 -> 0.037936267 | J38: =AVERAGE(C38,F38,I38) -> 0.026972363 | M38: 71 | N38: =M38/$M$41 -> 0.024973619
A39: 5 | B39: 125 | C39: =B39/$B$41 -> 0.04396764 | E39: 24 | F39: =E39/$E$41 -> 0.028811525 | H39: 132 | I39: =H39/$H$41 -> 0.050075873 | J39: =AVERAGE(C39,F39,I39) -> 0.040951679 | M39: 125 | N39: =M39/$M$41 -> 0.04396764
A40: 1 | B40: 2040 | C40: =B40/$B$41 -> 0.71755188 | E40: 578 | F40: =E40/$E$41 -> 0.69387755 | H40: 1378 | I40: =H40/$H$41 -> 0.52276176 | J40: =AVERAGE(C40,F40,I40) -> 0.6447304 | M40: 2040 | N40: =M40/$M$41 -> 0.71755188
A41: 长虹合计 | B41: =SUM(B33:B40) -> 2843 | C41: =SUM(C33:C40) -> 1 | E41: =SUM(E33:E40) -> 833 | F41: =SUM(F33:F40) -> 1 | H41: =SUM(H33:H40) -> 2636 | I41: =SUM(I33:I40) -> 1 | J41: =AVERAGE(C41,F41,I41) -> 1 | M41: =SUM(M33:M40) -> 2843

Sheet 概要
B2: 根据业务及技术提供的测算假设如下： 1、收视分钟数假定为1min、5min、10min、15min、20min、25min、30min、60min8种情况，广告播放次数：开机1次，30分钟内每15分钟一次，超出30分钟为每10分钟一次； 2、成本假设：码率设为2.3Mb/s或4/Mb/s，CDN单价为0.04元/Gb，按1Gb=1000Mb换算； 3、用户分布假设：假定日用户规模为10万，分3种模式进行测算，模式一按现有用户分布情况测算（1min占比最大），模式二取根据现有用户分布头尾两端（1min取最低，60min取最高）峰值测算，模式三按业务成熟期60min占比最大、1min占比最小测算； 4、CPM单价假设：假设单价为10或5，结合2种不同权重进行测算；另外假设单价为4测算； 5、渠道分成假设：按三七分、五五分进行测算。
B13: 测算主要数据如下：
B14: 码率 | C14: 盈亏平衡点CPM底价 | F14: 10万日活用户CDN成本（万元/年） | I14: 10万日活用户毛利（万元/年）
C15: 模式一 | D15: 模式二 | E15: 模式三 | F15: 模式一 | G15: 模式二 | H15: 模式三 | I15: 模式一 | L15: 模式二 | O15: 模式三
D16: 模式二 | E16: 模式三 | F16: 模式一 | G16: 模式二 | H16: 模式三 | I16: 50%广告CPM单价为10,50%为5 | J16: 30%广告CPM单价为10,70%为5 | K16: 100%广告CPM定价为4 | L16: 50%广告CPM单价为10,50%为5 | M16: 30%广告CPM单价为10,70%为5 | N16: 100%广告CPM定价为4 | O16: 50%广告CPM单价为10,50%为5 | P16: 30%广告CPM单价为10,70%为5 | Q16: 100%广告CPM定价为4
B17: 2.3M | C17: ='2.3码率'!K53 -> 4.9509953 | D17: ='2.3码率'!K89 -> 5.5754217 | E17: ='2.3码率'!K126 -> 6.7889655 | F17: ='2.3码率'!O45*12 -> 37.60776 | G17: ='2.3码率'!O81*12 -> 49.97808 | H17: ='2.3码率'!O118*12 -> 106.3152 | I17: ='2.3码率'!P45*12 -> 19.36224 | J17: ='2.3码率'!P54*12 -> 11.76624 | K17: ='2.3码率'!P63*12 -> -7.22376 | L17: ='2.3码率'!P81*12 -> 17.25192 | M17: ='2.3码率'!P90*12 -> 8.28792 | N17: ='2.3码率'!P99*12 -> -14.12208 | O17: ='2.3码率'!P118*12 -> 11.1348 | P17: ='2.3码率'!P127*12 -> -4.5252 | Q17: ='2.3码率'!P136*12 -> -43.6752
B18: 4M | C18: ='4码率'!K51 -> 8.6104265 | D18: ='4码率'!K80 -> 9.6963855 | E18: ='4码率'!K109 -> 11.806897 | F18: ='4码率'!O43*12 -> 65.4048 | G18: ='4码率'!O72*12 -> 86.9184 | H18: ='4码率'!O101*12 -> 184.896 | I18: ='4码率'!P43*12 -> -8.4348 | J18: ='4码率'!P47*12 -> -16.0308 | K18: ='4码率'!P50*12 -> -35.0208 | L18: ='4码率'!P72*12 -> -19.6884 | M18: ='4码率'!P76*12 -> -28.6524 | N18: ='4码率'!P79*12 -> -51.0624 | O18: ='4码率'!P101*12 -> -67.446 | P18: ='4码率'!P105*12 -> -83.106 | Q18: ='4码率'!P108*12 -> -122.256
B20: 参考电淘，首季度13.2万日活用户，后续33.2万日活用户测算
B21: 码率 | F21: 33万日活用户CDN成本（万元/年） | I21: 33万日活用户毛利（万元/年）
F22: 模式一 | G22: 模式二 | H22: 模式三 | I22: 模式一 | L22: 模式二 | O22: 模式三
F23: 模式一 | G23: 模式二 | H23: 模式三 | I23: 50%广告CPM单价为10,50%为5 | J23: 30%广告CPM单价为10,70%为5 | K23: 100%广告CPM定价为4 | L23: 50%广告CPM单价为10,50%为5 | M23: 30%广告CPM单价为10,70%为5 | N23: 100%广告CPM定价为4 | O23: 50%广告CPM单价为10,50%为5 | P23: 30%广告CPM单价为10,70%为5 | Q23: 100%广告CPM定价为4
B24: 2.3M | F24: ='2.3码率'!O45*1.33*3+'2.3码率'!O45*3.32*9 -> 106.1479 | G24: ='2.3码率'!O81*1.33*3+'2.3码率'!O81*3.32*9 -> 141.06313 | H24: ='2.3码率'!O118*1.33*3+'2.3码率'!O118*3.32*9 -> 300.07465 | I24: ='2.3码率'!N45*1.33*3+'2.3码率'!N45*3.32*9-F24 -> 54.649922 | J24: ='2.3码率'!N54*1.33*3+'2.3码率'!N54*3.32*9-F24 -> 33.210212 | K24: ='2.3码率'!N63*1.33*3+'2.3码率'!N63*3.32*9-F24 -> -20.389063 | L24: ='2.3码率'!N81*1.33*3+'2.3码率'!N81*3.32*9-F24 -> 83.608772 | M24: ='2.3码率'!N90*1.33*3+'2.3码率'!N90*3.32*9-G24 -> 23.392654 | N24: ='2.3码率'!N99*1.33*3+'2.3码率'!N99*3.32*9-G24 -> -39.859571 | O24: ='2.3码率'!N118*1.33*3+'2.3码率'!N118*3.32*9-H24 -> 31.427973 | P24: ='2.3码率'!N127*1.33*3+'2.3码率'!N127*3.32*9-H24 -> -12.772377 | Q24: ='2.3码率'!N136*1.33*3+'2.3码率'!N136*3.32*9-H24 -> -123.27325
B25: 4M | F25: ='4码率'!O43*1.33*3+'4码率'!O43*3.32*9 -> 184.60505 | G25: ='4码率'!O79*1.33*3+'4码率'!O79*3.32*9 -> 245.32718 | H25: ='4码率'!O108*1.33*3+'4码率'!O108*3.32*9 -> 521.86896 | I25: ='4码率'!N43*1.33*3+'4码率'!N43*3.32*9-F25 -> -23.807223 | J25: ='4码率'!N47*1.33*3+'4码率'!N47*3.32*9-F25 -> -45.246933 | K25: ='4码率'!N50*1.33*3+'4码率'!N50*3.32*9-F25 -> -98.846208 | L25: ='4码率'!N72*1.33*3+'4码率'!N72*3.32*9-G25 -> -55.570509 | M25: ='4码率'!N76*1.33*3+'4码率'!N76*3.32*9-G25 -> -80.871399 | N25: ='4码率'!N79*1.33*3+'4码率'!N79*3.32*9-G25 -> -144.12362 | O25: ='4码率'!N101*1.33*3+'4码率'!N101*3.32*9-H25 -> -190.36633 | P25: ='4码率'!N105*1.33*3+'4码率'!N105*3.32*9-H25 -> -234.56669 | Q25: ='4码率'!N108*1.33*3+'4码率'!N108*3.32*9-H25 -> -345.06756
K26: =F24-K24 -> 126.53697
B28: 主要结论： 项目盈亏的关键在用户收视时长分布以及码率 1、模式一情形下CPM 4.95/8.61元时达到盈亏平衡点，模式二下CPM 5.58/9.7元时达到盈亏平衡点，模式三下CPM 6.79/11.81元时达到盈亏平衡点； 2、随着收视时长增加，利润率逐步降低，盈亏平衡点CPM上涨，需提高收视20分钟以上区间的利润率（提示用户做调查问卷或休息一下）； 3、目前长虹业务码率是4M/s，后续码率最低2.3M/s起，需考虑码率设置为最低的可行性； 4、模式一情形下，年收入200万需要日活用户达到35万户/40万户/66万户；模式二情形下，年收入200万需要日活用户达到30万户/34万户/56万户；模式三情形下，年收入200万需要日活用户达到17万户/20万户/32万户； 5、10万日活用户，按现状模式一测算：不考虑广告收入，年投入成本在38-65万；按电淘目前CPM平均为4测算，年亏损在7-35万； 极限情况模式三下：不考虑广告收入，年投入成本在106-185万；按电淘目前CPM平均为4测算，年亏损在44-122万； 6、通过敏感性分析，后期可通过降低CDN成本、提高客户粘性使CPM增加来提高利润率，业务需考虑几种方式的可行性。

Sheet 2.3码率
B2: 根据业务及技术提供的测算假设如下： 1、收视分钟数假定为1min、5min、10min、15min、20min、25min、30min、60min8种情况，广告播放次数：开机1次，30分钟内每15分钟一次，超出30分钟为每10分钟一次； 2、成本假设：码率设为最低2.3Mb/s，CDN单价为0.04元/Gb，按1Gb=1000Mb换算； 3、用户分布假设：假定日活用户规模为10万，分3种模式进行测算，模式一按现有用户分布情况测算（1min占比最大），模式二取根据现有用户分布头尾两端（1min取最低，60min取最高）峰值测算，模式三按业务成熟期60min占比最大、1min占比最小测算； 4、CPM单价假设：假设单价为10或5，结合2种不同权重进行测算；另外假设单价为4测算； 5、渠道分成假设：按三七分、五五分进行测算。
B12: 主要结论： 项目盈亏的关键在用户收视时长分布以及码率 1、模式一情形下CPM 4.95元时达到盈亏平衡点，模式二下CPM 5.58元时达到盈亏平衡点，模式三下CPM 6.79元时达到盈亏平衡点； 2、随着收视时长增加，利润率逐步降低，盈亏平衡点CPM上涨，需提高收视20分钟以上区间的利润率（提示用户做调查问卷或休息一下）； 3、目前业务码率是4M/s，后续码率最低2.3M/s起，需考虑码率设置为最低的可行性； 4、模式一情形下，年收入200万需要日活用户达到35万户/40万户/66万户；不考虑广告收入，纯成本投入每月3.1万，年投入37.2万； 5、通过敏感性分析，后期可通过降低CDN成本、提高客户粘性使CPM增加来提高利润率，业务需考虑几种方式的可行性。
B22: 截止2026年3月31日现状：
B23: 明细 | C23: 合计 | E23: B端 | I23: C端 | K23: 备注
E24: 未来电视 | G24: 凌顶 | I24: 长虹 | K24: 目前行业毛利率在哪个区间，头部平台和中小平台
B25: 合作期间 | E25: 2025/7/1-2026/3/31 | G25: 2025/9/1-2026/3/31 | I25: 2026/2/6-2026/3/31
B26: 总收入（元） | C26: 135364 | E26: =94800+27500 -> 122300 | G26: =12166+898 -> 13064 | I26: 90
B27: 总成本（元） | C27: =SUM(E27:H27) -> 4700 | E27: 2350 | G27: 2350 | I27: 246 | K27: CDN成本能否按渠道拆分
B28: 总利润（元） | C28: =C26-C27 -> 130664 | E28: =E26-E27 -> 119950 | G28: =G26-G27 -> 10714 | I28: =I26-I27 -> -156
B29: 毛利率 | C29: =C28/C26 -> 0.9652788 | E29: =E28/E26 -> 0.98078496 | G29: =G28/G26 -> 0.82011635 | I29: =I28/I26 -> -1.7333333
B30: 码率（M/s） | C30: 2.3 | E30: 2.3 | G30: 2.3 | I30: 4
B31: 广告次数（CPM） | C31: =SUM(E31:H31) -> 31334 | E31: 24802 | G31: 6532 | I31: 20
B32: 广告位 | E32: 图片、前插广告 | G32: 图片、前插视频 | I32: 启动视频、图片 | K32: 图片广告不需要cdn
B33: 累计用户数 | C33: 212973 | E33: 200141 | G33: 200141 | I33: 12832
B34: 激活用户数 | C34: 212973 | E34: 200141 | G34: 200141 | I34: 12832 | K34: 激活的概念：进入FAST频道
B35: 日活用户数 | E35: 100000 | G35: 100000 | I35: 200 | K35: 未来和凌顶是广告覆盖用户，动态经营数据
B36: CDN单价（元/G） | C36: 0.04 | E36: 0.04 | G36: 0.04 | I36: 0.04
B37: CPM单价 | C37: =C26/C31 -> 4.3200357 | E37: =E26/E31 -> 4.9310539 | G37: =G26/G31 -> 2 | I37: =I26/I31 -> 4.5
B39: 模式一: 1、假定码率为最低2.3M/s，CDN单价为0.04元/G； 2、广告播放次数：开机1次，30分钟内每15分钟一次，超出30分钟为每10分钟一次； 3、假定日活用户数为10万户，用户分布按现有用户分布比例进行测算。
B42: 明细 | C42: 用户分布 | M42: 明细 | N42: 10万日活用户（万元/月） | V42: 结论
C43: 收视分钟数（1min） | D43: 收视分钟数（5min） | E43: 收视分钟数（10min） | F43: 收视分钟数（15min） | G43: 收视分钟数（20min） | H43: 收视分钟数（25min） | I43: 收视分钟数（30min） | J43: 收视分钟数（60min） | K43: 合计 | N43: 总收入 | O43: 总成本 | P43: 总利润 | Q43: 净利润 | S43: 毛利率 | T43: 净利率
Q44: 三七分 | R44: 五五分 | T44: 三七分 | U44: 五五分
B45: 业务假设： | M45: 假设一：CPM单价50%为10,50%为5 | N45: {=SUMPRODUCT(C46:J46,C58:J58)*30/10000} -> 4.7475 | O45: {=SUMPRODUCT(C52:J52,C46:J46)*30/10000} -> 3.13398 | P45: =N45-O45 -> 1.61352 | Q45: =P45*0.7 -> 1.129464 | R45: =P45*0.5 -> 0.80676 | S45: =P45/N45 -> 0.3398673 | T45: =K69 -> 0.23790711 | U45: =K72 -> 0.16993365 | V45: 1、目前实际用户分布集中在头尾部，收视1分钟以内占比最高，其次为收视60分钟及以上，收视5分钟-30分钟占比最小； 2、假定日用户数10万户，用户分布按现有用户分布比例测算，当CPM单价50%为10,50%为5时，毛利率为34%；CPM单价30%为10,70%为5时，毛利率为24%；CPM为4.95时达到盈亏平衡点； 3、随着收视时长增加，利润率逐步降低，需提高收视25分钟以上区间的利润率； 4、目前FAST广告CPM没有固定标准，参考国内中小平台收视60分钟，单次广告时长15s平均定价18元测算，毛利率达72%； 5、目前业务码率是4M/s，后续码率最低2.3M/s起，需考虑码率设置为最低的可行性； 6、通过敏感性分析，后期可通过降低CDN成本、提高客户粘性使CPM增加来提高利润率，业务需考虑几种方式的可行性。
B46: 用户数 | C46: =ROUND(C47*$K$46,0) -> 64000 | D46: =ROUND(D47*$K$46,0) -> 4000 | E46: =ROUND(E47*$K$46,0) -> 2000 | F46: =ROUND(F47*$K$46,0) -> 2000 | G46: =ROUND(G47*$K$46,0) -> 2000 | H46: =ROUND(H47*$K$46,0) -> 2000 | I46: =ROUND(I47*$K$46,0) -> 5000 | J46: =ROUND(J47*$K$46,0) -> 19000 | K46: 100000 | M46: 敏感性分析：
B47: 用户分布占比 | C47: 0.64 | D47: 0.04 | E47: 0.02 | F47: 0.02 | G47: 0.02 | H47: 0.02 | I47: 0.05 | J47: 0.19 | K47: =SUM(C47:J47) -> 1 | M47: 变量 | N47: 总收入变动 | O47: 总成本变动 | P47: 总利润变动 | Q47: 净利润变动 | S47: 毛利率变动 | T47: 净利率变动
B48: 成本： | Q48: 三七分 | R48: 五五分 | T48: 三七分 | U48: 五五分
B49: 收视分钟数（min） | C49: 1 | D49: 5 | E49: 10 | F49: 15 | G49: 20 | H49: 25 | I49: 30 | J49: 60 | M49: CDN单价 +/-10% | N49: 0 | O49: ="+/-"&ROUND(O45*10%,1) -> +/-0.3 | P49: ="-/+"&ROUND(O45*10%,1) -> -/+0.3 | Q49: ="-/+"&ROUND(O45*0.1*0.7,1) -> -/+0.2 | R49: ="-/+"&ROUND(O45*0.1*0.5,1) -> -/+0.2 | S49: ="-/+"&ROUND((N45-O45*0.9)/N45-S45,3)*100&"%" -> -/+6.6% | T49: ="-/+"&ROUND((N45-O45*0.9)*0.7/N45-T45,3)*100&"%" -> -/+4.6% | U49: ="-/+"&ROUND((N45-O45*0.9)*0.5/N45-U45,3)*100&"%" -> -/+3.3%
B50: 码率（M/s） | C50: 2.3 | D50: 2.3 | E50: 2.3 | F50: 2.3 | G50: 2.3 | H50: 2.3 | I50: 2.3 | J50: 2.3 | M50: CPM +/-10% | N50: ="+/-"&ROUND(N45*10%,1) -> +/-0.5 | O50: 0 | P50: ="+/-"&ROUND(N45*10%,1) -> +/-0.5 | Q50: ="+/-"&ROUND(N45*10%*0.7,1) -> +/-0.3 | R50: ="+/-"&ROUND(N45*10%*0.5,1) -> +/-0.2 | S50: ="+"&ROUND((N45*1.1-O45)/(N45*1.1)-S45,3)*100&"%/"&ROUND((N45*0.9-O45)/(N45*0.9)-S45,3)*100&"%" -> +6%/-7.3% | T50: ="+"&ROUND((N45*1.1-O45)*0.7/(N45*1.1)-T45,3)*100&"%/"&ROUND((N45*0.9-O45)*0.7/(N45*0.9)-T45,3)*100&"%" -> +4.2%/-5.1% | U50: ="+"&ROUND((N45*1.1-O45)*0.5/(N45*1.1)-U45,3)*100&"%/"&ROUND((N45*0.9-O45)*0.5/(N45*0.9)-U45,3)*100&"%" -> +3%/-3.7%
B51: CDN单价（元/G） | C51: 0.04 | D51: 0.04 | E51: 0.04 | F51: 0.04 | G51: 0.04 | H51: 0.04 | I51: 0.04 | J51: 0.04 | M51: 收入达到200万规模，需要发展日活用户数（万户）： | N51: =200/N45*10/12 -> 35.106196
B52: 单用户成本（元/天） | C52: =C49*C50*C51*60/1000/8 -> 0.00069 | D52: =D49*D50*D51*60/1000/8 -> 0.00345 | E52: =E49*E50*E51*60/1000/8 -> 0.0069 | F52: =F49*F50*F51*60/1000/8 -> 0.01035 | G52: =G49*G50*G51*60/1000/8 -> 0.0138 | H52: =H49*H50*H51*60/1000/8 -> 0.01725 | I52: =I49*I50*I51*60/1000/8 -> 0.0207 | J52: =J49*J50*J51*60/1000/8 -> 0.0414 | K52: =SUM(C52:J52) -> 0.11454 | M52: 明细 | N52: 总收入 | O52: 总成本 | P52: 总利润 | Q52: 净利润 | S52: 毛利率 | T52: 净利率
B53: 盈亏平衡点CPM底价 | C53: =C52/C56*1000 -> 0.69 | D53: =D52/D56*1000 -> 3.45 | E53: =E52/E56*1000 -> 6.9 | F53: =F52/F56*1000 -> 5.175 | G53: =G52/G56*1000 -> 6.9 | H53: =H52/H56*1000 -> 8.625 | I53: =I52/I56*1000 -> 6.9 | J53: =J52/J56*1000 -> 6.9 | K53: {=SUMPRODUCT(C52:J52,C46:J46)/SUMPRODUCT(C56:J56,C46:J46)*1000} -> 4.9509953 | Q53: 三七分 | R53: 五五分 | T53: 三七分 | U53: 五五分
B54: 备注：若不考虑广告收入，纯成本投入每月3.1万，年投入37.2万。 | M54: 假设二：CPM单价30%为10,70%为5 | N54: {=SUMPRODUCT(C46:J46,C61:J61)*30/10000} -> 4.1145 | O54: {=SUMPRODUCT(C52:J52,C46:J46)*30/10000} -> 3.13398 | P54: =N54-O54 -> 0.98052 | Q54: =P54*0.7 -> 0.686364 | R54: =P54*0.5 -> 0.49026 | S54: =P54/N54 -> 0.23830842 | T54: =K70 -> 0.1668159 | U54: =K73 -> 0.11915421
B55: 收入： | M55: 敏感性分析：
B56: 广告次数 | C56: =MIN(1+INT(C49/5),8) -> 1 | D56: =1+INT(D49/15) -> 1 | E56: =1+INT(E49/15) -> 1 | F56: =1+INT(F49/15) -> 2 | G56: =1+INT(G49/15) -> 2 | H56: =1+INT(H49/15) -> 2 | I56: =1+INT(I49/15) -> 3 | J56: =1+INT(30/15)+INT((J49-30)/10) -> 6 | M56: 变量 | N56: 总收入变动 | O56: 总成本变动 | P56: 总利润变动 | Q56: 净利润变动 | S56: 毛利率变动 | T56: 净利率变动
B57: 假设一：CPM单价50%为10,50%为5 | C57: =10*0.5+5*0.5 -> 7.5 | D57: =10*0.5+5*0.5 -> 7.5 | E57: =10*0.5+5*0.5 -> 7.5 | F57: =10*0.5+5*0.5 -> 7.5 | G57: =10*0.5+5*0.5 -> 7.5 | H57: =10*0.5+5*0.5 -> 7.5 | I57: =10*0.5+5*0.5 -> 7.5 | J57: =10*0.5+5*0.5 -> 7.5 | Q57: 三七分 | R57: 五五分 | T57: 三七分 | U57: 五五分
B58: 单用户收入（元/天） | C58: =C57*C56/1000 -> 0.0075 | D58: =D57*D56/1000 -> 0.0075 | E58: =E57*E56/1000 -> 0.0075 | F58: =F57*F56/1000 -> 0.015 | G58: =G57*G56/1000 -> 0.015 | H58: =H57*H56/1000 -> 0.015 | I58: =I57*I56/1000 -> 0.0225 | J58: =J57*J56/1000 -> 0.045 | K58: =SUM(C58:J58) -> 0.135 | M58: CDN单价 +/-10% | N58: 0 | O58: ="+/-"&ROUND(O54*10%,1) -> +/-0.3 | P58: ="-/+"&ROUND(O54*10%,1) -> -/+0.3 | Q58: ="-/+"&ROUND(O54*0.1*0.7,1) -> -/+0.2 | R58: ="-/+"&ROUND(O54*0.1*0.5,1) -> -/+0.2 | S58: ="-/+"&ROUND((N54-O54*0.9)/N54-S54,3)*100&"%" -> -/+7.6% | T58: ="-/+"&ROUND((N54-O54*0.9)*0.7/N54-T54,3)*100&"%" -> -/+5.3% | U58: ="-/+"&ROUND((N54-O54*0.9)*0.5/N54-U54,3)*100&"%" -> -/+3.8%
B59: 毛利率 | C59: =(C58-C52)/C58 -> 0.908 | D59: =(D58-D52)/D58 -> 0.54 | E59: =(E58-E52)/E58 -> 0.08 | F59: =(F58-F52)/F58 -> 0.31 | G59: =(G58-G52)/G58 -> 0.08 | H59: =(H58-H52)/H58 -> -0.15 | I59: =(I58-I52)/I58 -> 0.08 | J59: =(J58-J52)/J58 -> 0.08 | K59: {=(SUMPRODUCT(C46:J46,C58:J58)-SUMPRODUCT(C52:J52,C46:J46))/SUMPRODUCT(C46:J46,C58:J58)} -> 0.3398673 | M59: CPM +/-10% | N59: ="+/-"&ROUND(N54*10%,1) -> +/-0.4 | O59: 0 | P59: ="+/-"&ROUND(N54*10%,1) -> +/-0.4 | Q59: ="+/-"&ROUND(N54*10%*0.7,1) -> +/-0.3 | R59: ="+/-"&ROUND(N54*10%*0.5,1) -> +/-0.2 | S59: ="+"&ROUND((N54*1.1-O54)/(N54*1.1)-S54,3)*100&"%/"&ROUND((N54*0.9-O54)/(N54*0.9)-S54,3)*100&"%" -> +6.9%/-8.5% | T59: ="+"&ROUND((N54*1.1-O54)*0.7/(N54*1.1)-T54,3)*100&"%/"&ROUND((N54*0.9-O54)*0.7/(N54*0.9)-T54,3)*100&"%" -> +4.8%/-5.9% | U59: ="+"&ROUND((N54*1.1-O54)*0.5/(N54*1.1)-U54,3)*100&"%/"&ROUND((N54*0.9-O54)*0.5/(N54*0.9)-U54,3)*100&"%" -> +3.5%/-4.2%
B60: 假设二：CPM单价30%为10,70%为5 | C60: =10*0.3+5*0.7 -> 6.5 | D60: =10*0.3+5*0.7 -> 6.5 | E60: =10*0.3+5*0.7 -> 6.5 | F60: =10*0.3+5*0.7 -> 6.5 | G60: =10*0.3+5*0.7 -> 6.5 | H60: =10*0.3+5*0.7 -> 6.5 | I60: =10*0.3+5*0.7 -> 6.5 | J60: =10*0.3+5*0.7 -> 6.5 | M60: 收入达到200万规模，需要发展日活用户数（万户）： | N60: =200/N54*10/12 -> 40.50715
B61: 单用户收入（元/天） | C61: =C60*C56/1000 -> 0.0065 | D61: =D60*D56/1000 -> 0.0065 | E61: =E60*E56/1000 -> 0.0065 | F61: =F60*F56/1000 -> 0.013 | G61: =G60*G56/1000 -> 0.013 | H61: =H60*H56/1000 -> 0.013 | I61: =I60*I56/1000 -> 0.0195 | J61: =J60*J56/1000 -> 0.039 | K61: =SUM(C61:J61) -> 0.117 | M61: 明细 | N61: 总收入 | O61: 总成本 | P61: 总利润 | Q61: 净利润 | S61: 毛利率 | T61: 净利率
B62: 毛利率 | C62: =(C61-C52)/C61 -> 0.89384615 | D62: =(D61-D52)/D61 -> 0.46923077 | E62: =(E61-E52)/E61 -> -0.061538462 | F62: =(F61-F52)/F61 -> 0.20384615 | G62: =(G61-G52)/G61 -> -0.061538462 | H62: =(H61-H52)/H61 -> -0.32692308 | I62: =(I61-I52)/I61 -> -0.061538462 | J62: =(J61-J52)/J61 -> -0.061538462 | K62: {=(SUMPRODUCT(C46:J46,C61:J61)-SUMPRODUCT(C52:J52,C46:J46))/SUMPRODUCT(C46:J46,C61:J61)} -> 0.23830842 | Q62: 三七分 | R62: 五五分 | T62: 三七分 | U62: 五五分
...

Sheet 4码率
B2: 根据业务及技术提供的测算假设如下： 1、收视分钟数假定为1min、5min、10min、15min、20min、25min、30min、60min8种情况，广告播放次数：开机1次，30分钟内每15分钟一次，超出30分钟为每10分钟一次； 2、成本假设：码率设为4Mb/s，CDN单价为0.04元/Gb，按1Gb=1000Mb换算； 3、用户分布假设：假定日用户规模为10万，分3种模式进行测算，模式一按现有用户分布情况测算（1min占比最大），模式二取根据现有用户分布头尾两端（1min取最低，60min取最高）峰值测算，模式三按业务成熟期60min占比最大、1min占比最小测算； 4、CPM单价假设：假设单价为10或5，结合2种不同权重进行测算；另外假设单价为4测算； 5、渠道分成假设：按三七分、五五分进行测算。
B12: 主要结论： 项目盈亏的关键在用户收视时长分布 1、模式一情形下CPM 8.61元时达到盈亏平衡点，模式二下CPM 9.7元时达到盈亏平衡点，模式三下CPM 11.81元时达到盈亏平衡点； 2、随着收视时长增加，利润率逐步降低，盈亏平衡点CPM上涨，业务需加强运营管理，考虑10分钟之后码率降为2.3M/s； 3、模式一情形下，年收入200万需要月用户达到35万户/40万户/66万户；不考虑广告收入，纯成本投入每月5.5万，年投入66万； 4、通过敏感性分析，后期可通过降低CDN成本、降低码率、提高客户粘性使CPM增加来提高利润率，业务需考虑几种方式的可行性。
B20: 截止2026年3月31日现状：
B21: 明细 | C21: 合计 | E21: B端 | I21: C端 | K21: 备注
E22: 未来电视 | G22: 凌顶 | I22: 长虹 | K22: 目前行业毛利率在哪个区间，头部平台和中小平台
B23: 合作期间 | E23: 2025/7/1-2026/3/31 | G23: 2025/9/1-2026/3/31 | I23: 2026/2/6-2026/3/31
B24: 总收入（元） | C24: 135364 | E24: =94800+27500 -> 122300 | G24: =12166+898 -> 13064 | I24: 90
B25: 总成本（元） | C25: =SUM(E25:H25) -> 4700 | E25: 2350 | G25: 2350 | I25: 246 | K25: CDN成本能否按渠道拆分
B26: 总利润（元） | C26: =C24-C25 -> 130664 | E26: =E24-E25 -> 119950 | G26: =G24-G25 -> 10714 | I26: =I24-I25 -> -156
B27: 毛利率 | C27: =C26/C24 -> 0.9652788 | E27: =E26/E24 -> 0.98078496 | G27: =G26/G24 -> 0.82011635 | I27: =I26/I24 -> -1.7333333
B28: 码率（M/s） | C28: 2.3 | E28: 2.3 | G28: 2.3 | I28: 4
B29: 广告次数（CPM） | C29: =SUM(E29:H29) -> 31334 | E29: 24802 | G29: 6532 | I29: 20
B30: 广告位 | E30: 图片、前插广告 | G30: 图片、前插视频 | I30: 启动视频、图片 | K30: 图片广告不需要cdn
B31: 累计用户数 | C31: 212973 | E31: 200141 | G31: 200141 | I31: 12832
B32: 激活用户数 | C32: 212973 | E32: 200141 | G32: 200141 | I32: 12832 | K32: 激活的概念：进入FAST频道
B33: 日活用户数 | E33: 100000 | G33: 100000 | I33: 200 | K33: 未来和凌顶是广告覆盖用户，动态经营数据
B34: CDN单价（元/G） | C34: 0.04 | E34: 0.04 | G34: 0.04 | I34: 0.04
B35: CPM单价 | C35: =C24/C29 -> 4.3200357 | E35: =E24/E29 -> 4.9310539 | G35: =G24/G29 -> 2 | I35: =I24/I29 -> 4.5
B37: 模式一: 1、假定码率为4M/s，CDN单价为0.04元/G； 2、广告播放次数：开机1次，30分钟内每15分钟一次，超出30分钟为每10分钟一次； 3、假定日活用户数为10万户，用户分布按现有用户分布比例进行测算。
B40: 明细 | C40: 用户分布 | M40: 明细 | N40: 10万日活用户（万元/月） | T40: 结论
C41: 收视分钟数（1min） | D41: 收视分钟数（5min） | E41: 收视分钟数（10min） | F41: 收视分钟数（15min） | G41: 收视分钟数（20min） | H41: 收视分钟数（25min） | I41: 收视分钟数（30min） | J41: 收视分钟数（60min） | K41: 合计 | N41: 总收入 | O41: 总成本 | P41: 总利润 | Q41: 净利润 | S41: 毛利率
Q42: 三七分 | R42: 五五分
B43: 业务假设： | M43: 假设一：CPM单价50%为10,50%为5 | N43: {=SUMPRODUCT(C44:J44,C56:J56)*30/10000} -> 4.7475 | O43: {=SUMPRODUCT(C50:J50,C44:J44)*30/10000} -> 5.4504 | P43: =N43-O43 -> -0.7029 | S43: =P43/N43 -> -0.14805687 | T43: 1、目前实际用户分布集中在头尾部，收视1分钟以内占比最高，其次为收视60分钟及以上，收视5分钟-30分钟占比最小； 2、假定日用户数10万户，用户分布按现有用户分布比例测算，当CPM单价50%为10,50%为5时，毛利率为-15%；CPM单价30%为10,70%为5时，毛利率为-32%；CPM为8.61时达到盈亏平衡点； 3、随着收视时长增加，利润率逐步降低，收视10分钟以上区间亏损，需提高收视10分钟以上区间的利润率； 4、目前FAST广告CPM没有固定标准，参考国内中小平台收视60分钟，单次广告时长15s平均定价18元测算，毛利率达52%； 5、通过敏感性分析，后期可通过降低CDN成本、降低码率、提高客户粘性使CPM增加来提高利润率，业务需考虑几种方式的可行性。
B44: 用户数 | C44: =ROUND(C45*$K$44,0) -> 64000 | D44: =ROUND(D45*$K$44,0) -> 4000 | E44: =ROUND(E45*$K$44,0) -> 2000 | F44: =ROUND(F45*$K$44,0) -> 2000 | G44: =ROUND(G45*$K$44,0) -> 2000 | H44: =ROUND(H45*$K$44,0) -> 2000 | I44: =ROUND(I45*$K$44,0) -> 5000 | J44: =ROUND(J45*$K$44,0) -> 19000 | K44: 100000 | M44: 收入达到200万规模，需要发展日活用户数（万户）： | N44: =200/N43*10/12 -> 35.106196
B45: 用户分布占比 | C45: 0.64 | D45: 0.04 | E45: 0.02 | F45: 0.02 | G45: 0.02 | H45: 0.02 | I45: 0.05 | J45: 0.19 | K45: =SUM(C45:J45) -> 1
B46: 成本：
B47: 收视分钟数（min） | C47: 1 | D47: 5 | E47: 10 | F47: 15 | G47: 20 | H47: 25 | I47: 30 | J47: 60 | M47: 假设二：CPM单价30%为10,70%为5 | N47: {=SUMPRODUCT(C44:J44,C59:J59)*30/10000} -> 4.1145 | O47: {=SUMPRODUCT(C50:J50,C44:J44)*30/10000} -> 5.4504 | P47: =N47-O47 -> -1.3359 | S47: =P47/N47 -> -0.32468101
B48: 码率（M/s） | C48: 4 | D48: 4 | E48: 4 | F48: 4 | G48: 4 | H48: 4 | I48: 4 | J48: 4 | M48: 收入达到200万规模，需要发展日活用户数（万户）： | N48: =200/N47*10/12 -> 40.50715
B49: CDN单价（元/G） | C49: 0.04 | D49: 0.04 | E49: 0.04 | F49: 0.04 | G49: 0.04 | H49: 0.04 | I49: 0.04 | J49: 0.04
B50: 单用户成本（元/天） | C50: =C47*C48*C49*60/1000/8 -> 0.0012 | D50: =D47*D48*D49*60/1000/8 -> 0.006 | E50: =E47*E48*E49*60/1000/8 -> 0.012 | F50: =F47*F48*F49*60/1000/8 -> 0.018 | G50: =G47*G48*G49*60/1000/8 -> 0.024 | H50: =H47*H48*H49*60/1000/8 -> 0.03 | I50: =I47*I48*I49*60/1000/8 -> 0.036 | J50: =J47*J48*J49*60/1000/8 -> 0.072 | K50: =SUM(C50:J50) -> 0.1992 | M50: 假设三：CPM单价100%为4 | N50: {=SUMPRODUCT(C44:J44,C62:J62)*30/10000} -> 2.532 | O50: {=SUMPRODUCT(C50:J50,C44:J44)*30/10000} -> 5.4504 | P50: =N50-O50 -> -2.9184 | S50: =P50/N50 -> -1.1526066
B51: 盈亏平衡点CPM底价 | C51: =C50/C54*1000 -> 1.2 | D51: =D50/D54*1000 -> 6 | E51: =E50/E54*1000 -> 12 | F51: =F50/F54*1000 -> 9 | G51: =G50/G54*1000 -> 12 | H51: =H50/H54*1000 -> 15 | I51: =I50/I54*1000 -> 12 | J51: =J50/J54*1000 -> 12 | K51: {=SUMPRODUCT(C50:J50,C44:J44)/SUMPRODUCT(C54:J54,C44:J44)*1000} -> 8.6104265 | M51: 收入达到200万规模，需要发展日活用户数（万户）： | N51: =200/N50*10/12 -> 65.824118
B52: 备注：若不考虑广告收入，纯成本投入每月5.5万，年投入66万。
B53: 收入： | M53: 按行业中小平台收视60分钟，单次15s广告平均定价：CPM定为18 | N53: {=SUMPRODUCT(C44:J44,C56:J56)*30/C55*18/10000} -> 11.394 | O53: =O43 -> 5.4504 | P53: =N53-O53 -> 5.9436 | Q53: =P53*0.7 -> 4.16052 | R53: =P53*0.5 -> 2.9718 | S53: =P53/N53 -> 0.52164297
B54: 广告次数 | C54: =MIN(1+INT(C47/5),8) -> 1 | D54: =1+INT(D47/15) -> 1 | E54: =1+INT(E47/15) -> 1 | F54: =1+INT(F47/15) -> 2 | G54: =1+INT(G47/15) -> 2 | H54: =1+INT(H47/15) -> 2 | I54: =1+INT(I47/15) -> 3 | J54: =1+INT(30/15)+INT((J47-30)/10) -> 6 | M54: 收入达到200万规模，需要发展日活用户数（万户）： | N54: =200/N53/12*10 -> 14.627582
B55: 假设一：CPM单价50%为10,50%为5 | C55: =10*0.5+5*0.5 -> 7.5 | D55: =10*0.5+5*0.5 -> 7.5 | E55: =10*0.5+5*0.5 -> 7.5 | F55: =10*0.5+5*0.5 -> 7.5 | G55: =10*0.5+5*0.5 -> 7.5 | H55: =10*0.5+5*0.5 -> 7.5 | I55: =10*0.5+5*0.5 -> 7.5 | J55: =10*0.5+5*0.5 -> 7.5
B56: 单用户收入（元/天） | C56: =C55*C54/1000 -> 0.0075 | D56: =D55*D54/1000 -> 0.0075 | E56: =E55*E54/1000 -> 0.0075 | F56: =F55*F54/1000 -> 0.015 | G56: =G55*G54/1000 -> 0.015 | H56: =H55*H54/1000 -> 0.015 | I56: =I55*I54/1000 -> 0.0225 | J56: =J55*J54/1000 -> 0.045 | K56: =SUM(C56:J56) -> 0.135
B57: 毛利率 | C57: =(C56-C50)/C56 -> 0.84 | D57: =(D56-D50)/D56 -> 0.2 | E57: =(E56-E50)/E56 -> -0.6 | F57: =(F56-F50)/F56 -> -0.2 | G57: =(G56-G50)/G56 -> -0.6 | H57: =(H56-H50)/H56 -> -1 | I57: =(I56-I50)/I56 -> -0.6 | J57: =(J56-J50)/J56 -> -0.6 | K57: {=(SUMPRODUCT(C44:J44,C56:J56)-SUMPRODUCT(C50:J50,C44:J44))/SUMPRODUCT(C44:J44,C56:J56)} -> -0.14805687
B58: 假设二：CPM单价30%为10,70%为5 | C58: =10*0.3+5*0.7 -> 6.5 | D58: =10*0.3+5*0.7 -> 6.5 | E58: =10*0.3+5*0.7 -> 6.5 | F58: =10*0.3+5*0.7 -> 6.5 | G58: =10*0.3+5*0.7 -> 6.5 | H58: =10*0.3+5*0.7 -> 6.5 | I58: =10*0.3+5*0.7 -> 6.5 | J58: =10*0.3+5*0.7 -> 6.5
B59: 单用户收入（元/天） | C59: =C58*C54/1000 -> 0.0065 | D59: =D58*D54/1000 -> 0.0065 | E59: =E58*E54/1000 -> 0.0065 | F59: =F58*F54/1000 -> 0.013 | G59: =G58*G54/1000 -> 0.013 | H59: =H58*H54/1000 -> 0.013 | I59: =I58*I54/1000 -> 0.0195 | J59: =J58*J54/1000 -> 0.039 | K59: =SUM(C59:J59) -> 0.117
B60: 毛利率 | C60: =(C59-C50)/C59 -> 0.81538462 | D60: =(D59-D50)/D59 -> 0.076923077 | E60: =(E59-E50)/E59 -> -0.84615385 | F60: =(F59-F50)/F59 -> -0.38461538 | G60: =(G59-G50)/G59 -> -0.84615385 | H60: =(H59-H50)/H59 -> -1.3076923 | I60: =(I59-I50)/I59 -> -0.84615385 | J60: =(J59-J50)/J59 -> -0.84615385 | K60: {=(SUMPRODUCT(C44:J44,C59:J59)-SUMPRODUCT(C50:J50,C44:J44))/SUMPRODUCT(C44:J44,C59:J59)} -> -0.32468101
...

Sheet 行业情况
B1: 以下为AI搜索：
B3: 国内头部平台 | I3: 国内中小平台
B4: 广告时长 | C4: 行业CPM均价（按收视及广告时长） | I4: 广告时长 | J4: 行业CPM均价（按收视及广告时长）
C5: 收视分钟数（1min） | D5: 收视分钟数（5min） | E5: 收视分钟数（15min） | F5: 收视分钟数（30min） | G5: 收视分钟数（60min） | J5: 收视分钟数（1min） | K5: 收视分钟数（5min） | L5: 收视分钟数（15min） | M5: 收视分钟数（30min） | N5: 收视分钟数（60min）
B6: 15s | C6: 8-12元 | D6: 12-18元 | E6: 18-25元 | F6: 25-35元 | G6: 40-60元 | I6: 15s | J6: 4-8元 | K6: 6-12元 | L6: 10-16元 | M6: 16-22元 | N6: 18-25元
B7: 30s | C7: 7-10元 | D7: 10-16元 | E7: 16-22元 | F7: 22-32元 | G7: 36-55元 | I7: 30s | J7: 3-7元 | K7: 5-10元 | L7: 8-14元 | M7: 14-20元 | N7: 16-22元
B8: 1min | C8: 5-8元 | D8: 8-12元 | E8: 14-18元 | F8: 20-28元 | G8: 32-48元 | I8: 1min | J8: 2-5元 | K8: 4-8元 | L8: 7-12元 | M8: 12-18元 | N8: 14-20元
B9: 5min | C9: 3-6元 | D9: 6-10元 | E9: 10-14元 | F9: 16-22元 | G9: 28-40元 | I9: 5min | J9: 1-3元 | K9: 3-6元 | L9: 5-9元 | M9: 10-16元 | N9: 12-18元
B11: 行业广告平均播放次数
B12: 广告时长 | C12: 行业广告播放次数
C13: 收视分钟数（1min） | D13: 收视分钟数（5min） | E13: 收视分钟数（15min） | F13: 收视分钟数（30min） | G13: 收视分钟数（60min）
B14: 15s | C14: 1次 | D14: 1次 | E14: 2次 | F14: 4次 | G14: 8次
B15: 30s | C15: 1次 | D15: 1次 | E15: 2次 | F15: 3次 | G15: 5次
