Workbook
Name 出租人: [1]基础数据!$C$4:$C$5

Sheet 总表
B2: 根据业务提供的测算假设如下： 1、项目周期：2026年8月1日-2027年12月31日 2、收入结算：包盘保底收入300万元/年，其中云游戏收入240万/年，超高清收入60万/年。从项目上线之日起按月折算，云游戏20万/月，超高清5万/月，账期3个月； 3、云游戏服务器（50路并发）租赁46.86万/年，3.905万/月，月度后付； 4、云游戏技术服务费7.2万/年，0.6万/月，月度后付； 5、4台IDC机柜租赁费24万/年，2万/月，半年预付； 6、100M专线费3.6万/年，0.3万/月，半年预付； 7、游戏CP分成分按5000保底订购用户和包盘收入2种情况测算，季度后付； 8、测算不包含MG买断游戏版权成本及超高清集采版权成本； 9、以上数据均含税。
B8: 主要结论及提示： 1、项目整体盈利：两种场景测算均实现盈利，项目具备财务可行性； 2、现金流：2026年存在垫资情况，建议商务谈判时尽量延后付款节奏； 3、模式优化可提升利润：若能与运营商协商获取鉴权订购数据，采用按实际用户数进行游戏CP分成的模式，利润空间更大，建议作为首选谈判目标； 4、上线时点：根据会议沟通，项目结束期为固定时点2027年12月，建议尽早上线以争取更多利润。
B12: 利润情况（游戏CP分成按包盘收入测算） | L12: 单位：万元 | N12: 利润情况（游戏CP分成按5000用户保底订购量测算） | X12: 单位：万元
B13: 明细项目（不含税） | F13: 2026年（8月起） | I13: 2027年 | L13: 合计 | N13: 明细项目（不含税） | R13: 2026年（8月起） | U13: 2027年 | X13: 合计
F14: 本年小计 | G14: 云游戏 | H14: 超高清 | I14: 本年小计 | J14: 云游戏 | K14: 超高清 | R14: 本年小计 | S14: 云游戏 | T14: 超高清 | U14: 本年小计 | V14: 云游戏 | W14: 超高清
B15: 收入 | F15: =G15+H15 -> 117.92453 | G15: =G16 -> 94.339623 | H15: =H16 -> 23.584906 | I15: =J15+K15 -> 283.01887 | J15: =J16 -> 226.41509 | K15: =K16 -> 56.603774 | L15: =F15+I15 -> 400.9434 | N15: 收入 | R15: =S15+T15 -> 117.92453 | S15: =S16 -> 94.339623 | T15: =T16 -> 23.584906 | U15: =V15+W15 -> 283.01887 | V15: =V16 -> 226.41509 | W15: =W16 -> 56.603774 | X15: =R15+U15 -> 400.9434
B16: 包盘保底收入 | F16: =G16+H16 -> 117.92453 | G16: =20*5/1.06 -> 94.339623 | H16: =5*5/1.06 -> 23.584906 | I16: =J16+K16 -> 283.01887 | J16: =240/1.06 -> 226.41509 | K16: =60/1.06 -> 56.603774 | L16: =F16+I16 -> 400.9434 | N16: 包盘保底收入 | R16: =S16+T16 -> 117.92453 | S16: =20*5/1.06 -> 94.339623 | T16: =5*5/1.06 -> 23.584906 | U16: =V16+W16 -> 283.01887 | V16: =240/1.06 -> 226.41509 | W16: =60/1.06 -> 56.603774 | X16: =R16+U16 -> 400.9434
B17: 成本 | F17: =G17+H17 -> 53.98517 | G17: =SUM(G18:G22) -> 53.98517 | H17: =SUM(H18:H22) -> 0 | I17: =J17+K17 -> 120.15612 | J17: =SUM(J18:J22) -> 120.15612 | K17: =SUM(K18:K22) -> 0 | L17: =F17+I17 -> 174.14129 | N17: 成本 | R17: =S17+T17 -> 43.919133 | S17: =SUM(S18:S22) -> 43.919133 | T17: =SUM(T18:T22) -> 0 | U17: =V17+W17 -> 99.608949 | V17: =SUM(V18:V22) -> 99.608949 | W17: =SUM(W18:W22) -> 0 | X17: =R17+U17 -> 143.52808
B18: 服务器租赁（利息费用+折旧） | F18: =G18+H18 -> 16.195533 | G18: =SUM(云游戏分月测算明细!B5:F5) -> 16.195533 | I18: =J18+K18 -> 38.124876 | J18: =SUM(云游戏分月测算明细!G5:R5) -> 38.124876 | L18: =F18+I18 -> 54.320409 | N18: 服务器租赁（利息费用+折旧） | R18: =S18+T18 -> 16.195533 | S18: =SUM(云游戏分月测算明细!B17:F17) -> 16.195533 | U18: =V18+W18 -> 38.124876 | V18: =SUM(云游戏分月测算明细!G17:R17) -> 38.124876 | X18: =R18+U18 -> 54.320409
B19: 云游戏技术服务费 | F19: =G19+H19 -> 2.8301887 | G19: =SUM(云游戏分月测算明细!B6:F6) -> 2.8301887 | I19: =J19+K19 -> 6.7924528 | J19: =SUM(云游戏分月测算明细!G6:R6) -> 6.7924528 | L19: =F19+I19 -> 9.6226415 | N19: 云游戏技术服务费 | R19: =S19+T19 -> 2.8301887 | S19: =SUM(云游戏分月测算明细!B18:F18) -> 2.8301887 | U19: =V19+W19 -> 6.7924528 | V19: =SUM(云游戏分月测算明细!G18:R18) -> 6.7924528 | X19: =R19+U19 -> 9.6226415
B20: IDC机柜租赁费 | F20: =G20+H20 -> 9.4339623 | G20: =SUM(云游戏分月测算明细!B7:F7) -> 9.4339623 | I20: =J20+K20 -> 22.641509 | J20: =SUM(云游戏分月测算明细!G7:R7) -> 22.641509 | L20: =F20+I20 -> 32.075472 | N20: IDC机柜租赁费 | R20: =S20+T20 -> 9.4339623 | S20: =SUM(云游戏分月测算明细!B19:F19) -> 9.4339623 | U20: =V20+W20 -> 22.641509 | V20: =SUM(云游戏分月测算明细!G19:R19) -> 22.641509 | X20: =R20+U20 -> 32.075472
B21: 100M专线费 | F21: =G21+H21 -> 1.3761468 | G21: =SUM(云游戏分月测算明细!B8:F8) -> 1.3761468 | I21: =J21+K21 -> 3.3027523 | J21: =SUM(云游戏分月测算明细!G8:R8) -> 3.3027523 | L21: =F21+I21 -> 4.6788991 | N21: 100M专线费 | R21: =S21+T21 -> 1.3761468 | S21: =SUM(云游戏分月测算明细!B20:F20) -> 1.3761468 | U21: =V21+W21 -> 3.3027523 | V21: =SUM(云游戏分月测算明细!G20:R20) -> 3.3027523 | X21: =R21+U21 -> 4.6788991
B22: 游戏CP分成 | F22: =G22+H22 -> 24.14934 | G22: =SUM(云游戏分月测算明细!B9:F9) -> 24.14934 | I22: =J22+K22 -> 49.294528 | J22: =SUM(云游戏分月测算明细!G9:R9) -> 49.294528 | L22: =F22+I22 -> 73.443868 | N22: 游戏CP分成 | R22: =S22+T22 -> 14.083302 | S22: =SUM(云游戏分月测算明细!B21:F21) -> 14.083302 | U22: =V22+W22 -> 28.747358 | V22: =SUM(云游戏分月测算明细!G21:R21) -> 28.747358 | X22: =R22+U22 -> 42.83066
B23: 毛利 | F23: =G23+H23 -> 63.939358 | G23: =G15-G17 -> 40.354452 | H23: =H15-H17 -> 23.584906 | I23: =J23+K23 -> 162.86275 | J23: =J15-J17 -> 106.25898 | K23: =K15-K17 -> 56.603774 | L23: =F23+I23 -> 226.80211 | N23: 毛利 | R23: =S23+T23 -> 74.005396 | S23: =S15-S17 -> 50.42049 | T23: =T15-T17 -> 23.584906 | U23: =V23+W23 -> 183.40992 | V23: =V15-V17 -> 126.80615 | W23: =W15-W17 -> 56.603774 | X23: =R23+U23 -> 257.41531
B24: 毛利率 | F24: =F23/F15 -> 0.54220576 | G24: =G23/G15 -> 0.42775719 | H24: =H23/H15 -> 1 | I24: =I23/I15 -> 0.57544838 | J24: =J23/J15 -> 0.46931048 | K24: =K23/K15 -> 1 | L24: =L23/L15 -> 0.56567114 | N24: 毛利率 | R24: =R23/R15 -> 0.62756576 | S24: =S23/S15 -> 0.53445719 | T24: =T23/T15 -> 1 | U24: =U23/U15 -> 0.64804838 | V24: =V23/V15 -> 0.56006048 | W24: =W23/W15 -> 1 | X24: =X23/X15 -> 0.64202408
B26: 现金流情况（游戏CP分成按包盘收入测算） | L26: 单位：万元 | N26: 现金流情况（游戏CP分成按5000用户保底订购量测算） | X26: 单位：万元
B27: 明细项目（含税） | F27: 2026年（8月起） | H27: 2027年 | J27: 2028年 | L27: 合计 | N27: 明细项目（含税） | R27: 2026年（8月起） | T27: 2027年 | V27: 2028年 | X27: 合计
B29: 收款 | F29: =F30+F31 -> 50 | H29: =H30+H31 -> 300 | J29: =J30+J31 -> 75 | L29: =F29+H29+J29 -> 425 | N29: 收款 | R29: =R30+R31 -> 50 | T29: =T30+T31 -> 300 | V29: =V30+V31 -> 75 | X29: =R29+T29+V29 -> 425
B30: 云游戏收入 | F30: =SUM(云游戏分月测算明细!B28:F28) -> 40 | H30: =SUM(云游戏分月测算明细!G28:R28) -> 240 | J30: =SUM(云游戏分月测算明细!S28:U28) -> 60 | L30: =F30+H30+J30 -> 340 | N30: 云游戏收入 | R30: =SUM(云游戏分月测算明细!B41:F41) -> 40 | T30: =SUM(云游戏分月测算明细!G41:R41) -> 240 | V30: =SUM(云游戏分月测算明细!S41:U41) -> 60 | X30: =R30+T30+V30 -> 340
B31: 超高清收入 | F31: =SUM(云游戏分月测算明细!B29:F29) -> 10 | H31: =SUM(云游戏分月测算明细!G29:R29) -> 60 | J31: =SUM(云游戏分月测算明细!S29:U29) -> 15 | L31: =F31+H31+J31 -> 85 | N31: 超高清收入 | R31: =SUM(云游戏分月测算明细!B42:F42) -> 10 | T31: =SUM(云游戏分月测算明细!G42:R42) -> 60 | V31: =SUM(云游戏分月测算明细!S42:U42) -> 15 | X31: =R31+T31+V31 -> 85
B32: 付款 | F32: =SUM(F33:G37) -> 55.85525 | G32: =SUM(G33:G37) -> 0 | H32: =SUM(H33:I37) -> 120.1122 | I32: =SUM(I33:I37) -> 0 | J32: =SUM(J33:K37) -> 17.56805 | K32: =SUM(K33:K37) -> 0 | L32: =F32+H32+J32 -> 193.5355 | N32: 付款 | R32: =SUM(R33:S37) -> 50.63025 | S32: =SUM(S33:S37) -> 0 | T32: =SUM(T33:U37) -> 98.3322 | U32: =SUM(U33:U37) -> 0 | V32: =SUM(V33:W37) -> 12.12305 | W32: =SUM(W33:W37) -> 0 | X32: =R32+T32+V32 -> 161.0855
B33: 服务器租赁 | F33: =SUM(云游戏分月测算明细!B31:F31) -> 15.62 | H33: =SUM(云游戏分月测算明细!G31:R31) -> 46.86 | J33: =SUM(云游戏分月测算明细!S31:U31) -> 3.905 | L33: =F33+H33+J33 -> 66.385 | N33: 服务器租赁 | R33: =SUM(云游戏分月测算明细!B44:F44) -> 15.62 | T33: =SUM(云游戏分月测算明细!G44:R44) -> 46.86 | V33: =SUM(云游戏分月测算明细!S44:U44) -> 3.905 | X33: =R33+T33+V33 -> 66.385
B34: 云游戏技术服务费 | F34: =SUM(云游戏分月测算明细!B32:F32) -> 2.4 | H34: =SUM(云游戏分月测算明细!G32:R32) -> 7.2 | J34: =SUM(云游戏分月测算明细!S32:U32) -> 0.6 | L34: =F34+H34+J34 -> 10.2 | N34: 云游戏技术服务费 | R34: =SUM(云游戏分月测算明细!B45:F45) -> 2.4 | T34: =SUM(云游戏分月测算明细!G45:R45) -> 7.2 | V34: =SUM(云游戏分月测算明细!S45:U45) -> 0.6 | X34: =R34+T34+V34 -> 10.2
B35: IDC机柜租赁费 | F35: =SUM(云游戏分月测算明细!B33:F33) -> 22 | H35: =SUM(云游戏分月测算明细!G33:R33) -> 12 | J35: =SUM(云游戏分月测算明细!S33:U33) -> 0 | L35: =F35+H35+J35 -> 34 | N35: IDC机柜租赁费 | R35: =SUM(云游戏分月测算明细!B46:F46) -> 22 | T35: =SUM(云游戏分月测算明细!G46:R46) -> 12 | V35: =SUM(云游戏分月测算明细!S46:U46) -> 0 | X35: =R35+T35+V35 -> 34
B36: 100M专线费 | F36: =SUM(云游戏分月测算明细!B34:F34) -> 3.3 | H36: =SUM(云游戏分月测算明细!G34:R34) -> 1.8 | J36: =SUM(云游戏分月测算明细!S34:U34) -> 0 | L36: =F36+H36+J36 -> 5.1 | N36: 100M专线费 | R36: =SUM(云游戏分月测算明细!B47:F47) -> 3.3 | T36: =SUM(云游戏分月测算明细!G47:R47) -> 1.8 | V36: =SUM(云游戏分月测算明细!S47:U47) -> 0 | X36: =R36+T36+V36 -> 5.1
B37: 游戏CP分成 | F37: =SUM(云游戏分月测算明细!B35:F35) -> 12.53525 | H37: =SUM(云游戏分月测算明细!G35:R35) -> 52.2522 | J37: =SUM(云游戏分月测算明细!S35:U35) -> 13.06305 | L37: =F37+H37+J37 -> 77.8505 | N37: 游戏CP分成 | R37: =SUM(云游戏分月测算明细!B48:F48) -> 7.31025 | T37: =SUM(云游戏分月测算明细!G48:R48) -> 30.4722 | V37: =SUM(云游戏分月测算明细!S48:U48) -> 7.61805 | X37: =R37+T37+V37 -> 45.4005
B38: 净现金流 | F38: =F29-F32 -> -5.85525 | H38: =H29-H32 -> 179.8878 | I38: =I29-I32 -> 0 | J38: =J29-J32 -> 57.43195 | K38: =K29-K32 -> 0 | L38: =F38+H38+J38 -> 231.4645 | N38: 净现金流 | R38: =R29-R32 -> -0.63025 | T38: =T29-T32 -> 201.6678 | U38: =U29-U32 -> 0 | V38: =V29-V32 -> 62.87695 | W38: =W29-W32 -> 0 | X38: =R38+T38+V38 -> 263.9145

Sheet 云游戏分月测算明细
A1: 云游戏分月利润情况（游戏CP分成按包盘收入测算） | S1: 单位：万元
A2: 明细项目（不含税） | B2: 46235 | C2: 46267 | D2: 46299 | E2: 46331 | F2: 46363 | G2: 46395 | H2: 46427 | I2: 46459 | J2: 46491 | K2: 46523 | L2: 46555 | M2: 46587 | N2: 46619 | O2: 46651 | P2: 46683 | Q2: 46715 | R2: 46747 | S2: 合计
A3: 收入 | B3: =20/1.06 -> 18.867925 | C3: =20/1.06 -> 18.867925 | D3: =20/1.06 -> 18.867925 | E3: =20/1.06 -> 18.867925 | F3: =20/1.06 -> 18.867925 | G3: =20/1.06 -> 18.867925 | H3: =20/1.06 -> 18.867925 | I3: =20/1.06 -> 18.867925 | ... R3: =20/1.06 -> 18.867925 | S3: =SUM(B3:R3) -> 320.75472
A4: 成本 | B4: =SUM(B5:B9) -> 11.894442 | C4: =SUM(C5:C9) -> 11.887246 | D4: =SUM(D5:D9) -> 10.075059 | E4: =SUM(E5:E9) -> 10.067833 | F4: =SUM(F5:F9) -> 10.06059 | G4: =SUM(G5:G9) -> 10.053332 | H4: =SUM(H5:H9) -> 10.046059 | I4: =SUM(I5:I9) -> 10.038769 | ... R4: =SUM(R5:R9) -> 9.9721189 | S4: =SUM(B4:R4) -> 174.14129
A5: 服务器租赁（利息费用+折旧） | B5: 3.253529 | C5: 3.246333 | D5: 3.239122 | E5: 3.231896 | F5: 3.224653 | G5: 3.217395 | H5: 3.210122 | I5: 3.202832 | J5: 3.195527 | K5: 3.188206 | L5: 3.18087 | M5: 3.173517 | N5: 3.166149 | O5: 3.158764 | P5: 3.151364 | Q5: 3.143948 | R5: 3.136182 | S5: =SUM(B5:R5) -> 54.320409
A6: 云游戏技术服务费 | B6: =7.2/12/1.06 -> 0.56603774 | C6: =7.2/12/1.06 -> 0.56603774 | D6: =7.2/12/1.06 -> 0.56603774 | E6: =7.2/12/1.06 -> 0.56603774 | F6: =7.2/12/1.06 -> 0.56603774 | G6: =7.2/12/1.06 -> 0.56603774 | H6: =7.2/12/1.06 -> 0.56603774 | I6: =7.2/12/1.06 -> 0.56603774 | ... R6: =7.2/12/1.06 -> 0.56603774 | S6: =SUM(B6:R6) -> 9.6226415
A7: IDC机柜租赁费 | B7: =2/1.06 -> 1.8867925 | C7: =2/1.06 -> 1.8867925 | D7: =2/1.06 -> 1.8867925 | E7: =2/1.06 -> 1.8867925 | F7: =2/1.06 -> 1.8867925 | G7: =2/1.06 -> 1.8867925 | H7: =2/1.06 -> 1.8867925 | I7: =2/1.06 -> 1.8867925 | ... R7: =2/1.06 -> 1.8867925 | S7: =SUM(B7:R7) -> 32.075472
A8: 100M专线费 | B8: =0.3/1.09 -> 0.27522936 | C8: =0.3/1.09 -> 0.27522936 | D8: =0.3/1.09 -> 0.27522936 | E8: =0.3/1.09 -> 0.27522936 | F8: =0.3/1.09 -> 0.27522936 | G8: =0.3/1.09 -> 0.27522936 | H8: =0.3/1.09 -> 0.27522936 | I8: =0.3/1.09 -> 0.27522936 | ... R8: =0.3/1.09 -> 0.27522936 | S8: =SUM(B8:R8) -> 4.6788991
A9: 游戏CP分成 | B9: =云游戏CP分成明细!C8/1.06 -> 5.9128538 | C9: =云游戏CP分成明细!D8/1.06 -> 5.9128538 | D9: =云游戏CP分成明细!E8/1.06 -> 4.1078774 | E9: =云游戏CP分成明细!F8/1.06 -> 4.1078774 | F9: =云游戏CP分成明细!G8/1.06 -> 4.1078774 | G9: =云游戏CP分成明细!H8/1.06 -> 4.1078774 | H9: =云游戏CP分成明细!I8/1.06 -> 4.1078774 | I9: =云游戏CP分成明细!J8/1.06 -> 4.1078774 | ... R9: =云游戏CP分成明细!S8/1.06 -> 4.1078774 | S9: =SUM(B9:R9) -> 73.443868
A10: 毛利 | B10: =B3-B4 -> 6.9734822 | C10: =C3-C4 -> 6.9806782 | D10: =D3-D4 -> 8.7928656 | E10: =E3-E4 -> 8.8000916 | F10: =F3-F4 -> 8.8073346 | G10: =G3-G4 -> 8.8145926 | H10: =H3-H4 -> 8.8218656 | I10: =I3-I4 -> 8.8291556 | ... R10: =R3-R4 -> 8.8958056 | S10: =SUM(B10:R10) -> 146.61343
A11: 毛利率 | B11: =B10/B3 -> 0.36959456 | C11: =C10/C3 -> 0.36997595 | D11: =D10/D3 -> 0.46602188 | E11: =E10/E3 -> 0.46640486 | F11: =F10/F3 -> 0.46678874 | G11: =G10/G3 -> 0.46717341 | H11: =H10/H3 -> 0.46755888 | I11: =I10/I3 -> 0.46794525 | ... S11: =S10/S3 -> 0.45708892
A13: 云游戏分月利润情况（游戏CP分成按5000用户保底订购量测算） | S13: 单位：万元
A14: 明细项目（不含税） | B14: 46235 | C14: 46267 | D14: 46299 | E14: 46331 | F14: 46363 | G14: 46395 | H14: 46427 | I14: 46459 | J14: 46491 | K14: 46523 | L14: 46555 | M14: 46587 | N14: 46619 | O14: 46651 | P14: 46683 | Q14: 46715 | R14: 46747 | S14: 合计
A15: 收入 | B15: =20/1.06 -> 18.867925 | C15: =20/1.06 -> 18.867925 | D15: =20/1.06 -> 18.867925 | E15: =20/1.06 -> 18.867925 | F15: =20/1.06 -> 18.867925 | G15: =20/1.06 -> 18.867925 | H15: =20/1.06 -> 18.867925 | I15: =20/1.06 -> 18.867925 | ... R15: =20/1.06 -> 18.867925 | S15: =SUM(B15:R15) -> 320.75472
A16: 成本 | B16: =SUM(B17:B21) -> 9.4298197 | C16: =SUM(C17:C21) -> 9.4226237 | D16: =SUM(D17:D21) -> 8.3627948 | E16: =SUM(E17:E21) -> 8.3555688 | F16: =SUM(F17:F21) -> 8.3483258 | G16: =SUM(G17:G21) -> 8.3410678 | H16: =SUM(H17:H21) -> 8.3337948 | I16: =SUM(I17:I21) -> 8.3265048 | ... R16: =SUM(R17:R21) -> 8.2598548 | S16: =SUM(B16:R16) -> 143.52808
A17: 服务器租赁（利息费用+折旧） | B17: 3.253529 | C17: 3.246333 | D17: 3.239122 | E17: 3.231896 | F17: 3.224653 | G17: 3.217395 | H17: 3.210122 | I17: 3.202832 | J17: 3.195527 | K17: 3.188206 | L17: 3.18087 | M17: 3.173517 | N17: 3.166149 | O17: 3.158764 | P17: 3.151364 | Q17: 3.143948 | R17: 3.136182 | S17: =SUM(B17:R17) -> 54.320409
A18: 云游戏技术服务费 | B18: =7.2/12/1.06 -> 0.56603774 | C18: =7.2/12/1.06 -> 0.56603774 | D18: =7.2/12/1.06 -> 0.56603774 | E18: =7.2/12/1.06 -> 0.56603774 | F18: =7.2/12/1.06 -> 0.56603774 | G18: =7.2/12/1.06 -> 0.56603774 | H18: =7.2/12/1.06 -> 0.56603774 | I18: =7.2/12/1.06 -> 0.56603774 | ... R18: =7.2/12/1.06 -> 0.56603774 | S18: =SUM(B18:R18) -> 9.6226415
A19: IDC机柜租赁费 | B19: =2/1.06 -> 1.8867925 | C19: =2/1.06 -> 1.8867925 | D19: =2/1.06 -> 1.8867925 | E19: =2/1.06 -> 1.8867925 | F19: =2/1.06 -> 1.8867925 | G19: =2/1.06 -> 1.8867925 | H19: =2/1.06 -> 1.8867925 | I19: =2/1.06 -> 1.8867925 | ... R19: =2/1.06 -> 1.8867925 | S19: =SUM(B19:R19) -> 32.075472
A20: 100M专线费 | B20: =0.3/1.09 -> 0.27522936 | C20: =0.3/1.09 -> 0.27522936 | D20: =0.3/1.09 -> 0.27522936 | E20: =0.3/1.09 -> 0.27522936 | F20: =0.3/1.09 -> 0.27522936 | G20: =0.3/1.09 -> 0.27522936 | H20: =0.3/1.09 -> 0.27522936 | I20: =0.3/1.09 -> 0.27522936 | ... R20: =0.3/1.09 -> 0.27522936 | S20: =SUM(B20:R20) -> 4.6788991
A21: 游戏CP分成 | B21: =云游戏CP分成明细!C30/1.06 -> 3.4482311 | C21: =云游戏CP分成明细!D30/1.06 -> 3.4482311 | D21: =云游戏CP分成明细!E30/1.06 -> 2.3956132 | E21: =云游戏CP分成明细!F30/1.06 -> 2.3956132 | F21: =云游戏CP分成明细!G30/1.06 -> 2.3956132 | G21: =云游戏CP分成明细!H30/1.06 -> 2.3956132 | H21: =云游戏CP分成明细!I30/1.06 -> 2.3956132 | I21: =云游戏CP分成明细!J30/1.06 -> 2.3956132 | ... R21: =云游戏CP分成明细!S30/1.06 -> 2.3956132 | S21: =SUM(B21:R21) -> 42.83066
A22: 毛利 | B22: =B15-B16 -> 9.4381048 | C22: =C15-C16 -> 9.4453008 | D22: =D15-D16 -> 10.50513 | E22: =E15-E16 -> 10.512356 | F22: =F15-F16 -> 10.519599 | G22: =G15-G16 -> 10.526857 | H22: =H15-H16 -> 10.53413 | I22: =I15-I16 -> 10.54142 | ... R22: =R15-R16 -> 10.60807 | S22: =SUM(B22:R22) -> 177.22664
A23: 毛利率 | B23: =B22/B15 -> 0.50021956 | C23: =C22/C15 -> 0.50060095 | D23: =D22/D15 -> 0.55677188 | E23: =E22/E15 -> 0.55715486 | F23: =F22/F15 -> 0.55753874 | G23: =G22/G15 -> 0.55792341 | H23: =H22/H15 -> 0.55830888 | I23: =I22/I15 -> 0.55869525 | ... S23: =S22/S15 -> 0.5525301
A25: 云游戏+超高清分月现金流（游戏CP分成按包盘收入测算） | V25: 单位：万元
A26: 明细项目（含税） | B26: 46235 | C26: 46267 | D26: 46299 | E26: 46331 | F26: 46363 | G26: 46395 | H26: 46427 | I26: 46459 | J26: 46491 | K26: 46523 | L26: 46555 | M26: 46587 | N26: 46619 | O26: 46651 | P26: 46683 | Q26: 46715 | R26: 46747 | S26: 46779 | T26: 46811 | U26: 46843 | V26: 合计
A27: 收款 | E27: =E28+E29 -> 25 | F27: =F28+F29 -> 25 | G27: =G28+G29 -> 25 | H27: =H28+H29 -> 25 | I27: =I28+I29 -> 25 | J27: =J28+J29 -> 25 | K27: =K28+K29 -> 25 | L27: =L28+L29 -> 25 | ... V27: =V28+V29 -> 425
A28: 云游戏 | E28: 20 | F28: 20 | G28: 20 | H28: 20 | I28: 20 | J28: 20 | K28: 20 | L28: 20 | M28: 20 | N28: 20 | O28: 20 | P28: 20 | Q28: 20 | R28: 20 | S28: 20 | T28: 20 | U28: 20 | V28: =SUM(B28:U28) -> 340
A29: 超高清 | E29: 5 | F29: 5 | G29: 5 | H29: 5 | I29: 5 | J29: 5 | K29: 5 | L29: 5 | M29: 5 | N29: 5 | O29: 5 | P29: 5 | Q29: 5 | R29: 5 | S29: 5 | T29: 5 | U29: 5 | V29: =SUM(B29:U29) -> 85
A30: 付款 | B30: =SUM(B31:B35) -> 11.5 | C30: =SUM(C31:C35) -> 4.505 | D30: =SUM(D31:D35) -> 17.04025 | E30: =SUM(E31:E35) -> 4.505 | F30: =SUM(F31:F35) -> 18.305 | G30: =SUM(G31:G35) -> 17.56805 | H30: =SUM(H31:H35) -> 4.505 | I30: =SUM(I31:I35) -> 4.505 | ... U30: =SUM(U31:U35) -> 0 | V30: =SUM(B30:U30) -> 193.5355
A31: 服务器租赁 | C31: 3.905 | D31: 3.905 | E31: 3.905 | F31: 3.905 | G31: 3.905 | H31: 3.905 | I31: 3.905 | J31: 3.905 | K31: 3.905 | L31: 3.905 | M31: 3.905 | N31: 3.905 | O31: 3.905 | P31: 3.905 | Q31: 3.905 | R31: 3.905 | S31: 3.905 | V31: =SUM(B31:U31) -> 66.385
A32: 云游戏技术服务费 | C32: 0.6 | D32: 0.6 | E32: 0.6 | F32: 0.6 | G32: 0.6 | H32: 0.6 | I32: 0.6 | J32: 0.6 | K32: 0.6 | L32: 0.6 | M32: 0.6 | N32: 0.6 | O32: 0.6 | P32: 0.6 | Q32: 0.6 | R32: 0.6 | S32: 0.6 | V32: =SUM(B32:U32) -> 10.2
A33: IDC机柜租赁费 | B33: =24/12*5 -> 10 | F33: 12 | L33: 12 | V33: =SUM(B33:U33) -> 34
A34: 100M专线费 | B34: =3.6/12*5 -> 1.5 | F34: 1.8 | L34: 1.8 | V34: =SUM(B34:U34) -> 5.1
A35: 游戏CP分成 | D35: =云游戏CP分成明细!C8+云游戏CP分成明细!D8 -> 12.53525 | G35: =云游戏CP分成明细!E8+云游戏CP分成明细!F8+云游戏CP分成明细!G8 -> 13.06305 | J35: =云游戏CP分成明细!H8+云游戏CP分成明细!I8+云游戏CP分成明细!J8 -> 13.06305 | M35: =云游戏CP分成明细!K8+云游戏CP分成明细!L8+云游戏CP分成明细!M8 -> 13.06305 | P35: =云游戏CP分成明细!N8+云游戏CP分成明细!O8+云游戏CP分成明细!P8 -> 13.06305 | S35: =云游戏CP分成明细!Q8+云游戏CP分成明细!R8+云游戏CP分成明细!S8 -> 13.06305 | V35: =SUM(B35:U35) -> 77.8505
A36: 净现金流 | B36: =B27-B30 -> -11.5 | C36: =C27-C30 -> -4.505 | D36: =D27-D30 -> -17.04025 | E36: =E27-E30 -> 20.495 | F36: =F27-F30 -> 6.695 | G36: =G27-G30 -> 7.43195 | H36: =H27-H30 -> 20.495 | I36: =I27-I30 -> 20.495 | ... U36: =U27-U30 -> 25 | V36: =SUM(B36:U36) -> 231.4645
A38: 云游戏+超高清分月现金流（游戏CP分成按5000用户保底订购量测算） | V38: 单位：万元
A39: 明细项目（含税） | B39: 46235 | C39: 46267 | D39: 46299 | E39: 46331 | F39: 46363 | G39: 46395 | H39: 46427 | I39: 46459 | J39: 46491 | K39: 46523 | L39: 46555 | M39: 46587 | N39: 46619 | O39: 46651 | P39: 46683 | Q39: 46715 | R39: 46747 | S39: 46779 | T39: 46811 | U39: 46843 | V39: 合计
A40: 收款 | E40: =E41+E42 -> 25 | F40: =F41+F42 -> 25 | G40: =G41+G42 -> 25 | H40: =H41+H42 -> 25 | I40: =I41+I42 -> 25 | J40: =J41+J42 -> 25 | K40: =K41+K42 -> 25 | L40: =L41+L42 -> 25 | ... V40: =V41+V42 -> 425
A41: 云游戏 | E41: 20 | F41: 20 | G41: 20 | H41: 20 | I41: 20 | J41: 20 | K41: 20 | L41: 20 | M41: 20 | N41: 20 | O41: 20 | P41: 20 | Q41: 20 | R41: 20 | S41: 20 | T41: 20 | U41: 20 | V41: =SUM(B41:U41) -> 340
A42: 超高清 | E42: 5 | F42: 5 | G42: 5 | H42: 5 | I42: 5 | J42: 5 | K42: 5 | L42: 5 | M42: 5 | N42: 5 | O42: 5 | P42: 5 | Q42: 5 | R42: 5 | S42: 5 | T42: 5 | U42: 5 | V42: =SUM(B42:U42) -> 85
A43: 付款 | B43: =SUM(B44:B48) -> 11.5 | C43: =SUM(C44:C48) -> 4.505 | D43: =SUM(D44:D48) -> 11.81525 | E43: =SUM(E44:E48) -> 4.505 | F43: =SUM(F44:F48) -> 18.305 | G43: =SUM(G44:G48) -> 12.12305 | H43: =SUM(H44:H48) -> 4.505 | I43: =SUM(I44:I48) -> 4.505 | ... U43: =SUM(U44:U48) -> 0 | V43: =SUM(B43:U43) -> 161.0855
...

Sheet 云游戏CP分成明细
A1: 云游戏CP分账成本
A2: 序号 | B2: 类目名称 | C2: 2026年8月 | D2: 9月 | E2: 10月 | F2: 11月 | G2: 12月 | H2: 2027年1月 | I2: 2月 | J2: 3月 | K2: 4月 | L2: 5月 | M2: 6月 | N2: 7月 | O2: 8月 | P2: 9月 | Q2: 10月 | R2: 11月 | S2: 12月 | T2: 合计
A3: 1 | B3: 收入（万元） | C3: 20 | D3: 20 | E3: 20 | F3: 20 | G3: 20 | H3: 20 | I3: 20 | J3: 20 | K3: 20 | L3: 20 | M3: 20 | N3: 20 | O3: 20 | P3: 20 | Q3: 20 | R3: 20 | S3: 20 | T3: =SUM(C3:S3) -> 340
A4: 2 | B4: 固定成本（万元） | C4: =81.66/12 -> 6.805 | D4: =81.66/12 -> 6.805 | E4: =81.66/12 -> 6.805 | F4: =81.66/12 -> 6.805 | G4: =81.66/12 -> 6.805 | H4: =81.66/12 -> 6.805 | I4: =81.66/12 -> 6.805 | J4: =81.66/12 -> 6.805 | ... S4: =81.66/12 -> 6.805 | T4: =SUM(C4:S4) -> 115.685
A5: 3 | B5: 结算基数（万元） | C5: =C3-C4 -> 13.195 | D5: =D3-D4 -> 13.195 | E5: =E3-E4 -> 13.195 | F5: =F3-F4 -> 13.195 | G5: =G3-G4 -> 13.195 | H5: =H3-H4 -> 13.195 | I5: =I3-I4 -> 13.195 | J5: =J3-J4 -> 13.195 | ... S5: =S3-S4 -> 13.195 | T5: =SUM(C5:S5) -> 224.315
A6: 4 | B6: CP分账比例 | C6: 0.5 | D6: 0.5 | E6: 0.5 | F6: 0.5 | G6: 0.5 | H6: 0.5 | I6: 0.5 | J6: 0.5 | K6: 0.5 | L6: 0.5 | M6: 0.5 | N6: 0.5 | O6: 0.5 | P6: 0.5 | Q6: 0.5 | R6: 0.5 | S6: 0.5
A7: 5 | B7: CP分成时长占比 | C7: 0.95 | D7: 0.95 | E7: 0.66 | F7: 0.66 | G7: 0.66 | H7: 0.66 | I7: 0.66 | J7: 0.66 | K7: 0.66 | L7: 0.66 | M7: 0.66 | N7: 0.66 | O7: 0.66 | P7: 0.66 | Q7: 0.66 | R7: 0.66 | S7: 0.66
A8: 6 | B8: CP分账成本（万元） | C8: =C5*C6*C7 -> 6.267625 | D8: =D5*D6*D7 -> 6.267625 | E8: =E5*E6*E7 -> 4.35435 | F8: =F5*F6*F7 -> 4.35435 | G8: =G5*G6*G7 -> 4.35435 | H8: =H5*H6*H7 -> 4.35435 | I8: =I5*I6*I7 -> 4.35435 | J8: =J5*J6*J7 -> 4.35435 | ... S8: =S5*S6*S7 -> 4.35435 | T8: =SUM(C8:S8) -> 77.8505
A9: 7 | B9: 百视通利润（万元） | C9: =C5-C8 -> 6.927375 | D9: =D5-D8 -> 6.927375 | E9: =E5-E8 -> 8.84065 | F9: =F5-F8 -> 8.84065 | G9: =G5-G8 -> 8.84065 | H9: =H5-H8 -> 8.84065 | I9: =I5-I8 -> 8.84065 | J9: =J5-J8 -> 8.84065 | ... S9: =S5-S8 -> 8.84065 | T9: =SUM(C9:S9) -> 146.4645
A10: ※结算按无用户订购数据情况测算
A12: 说明：
A13: 上线日期预期再2026年8月
A14: 结算基数=总额-高清分账-硬件租金-机柜租金-带宽租金-其他费用
A15: 分账成本=结算基数*CP分账比例*参与分账CP时长比例占比（预估按照参与分账游戏数量比例测算）
A16: 参与分账游戏数量比例 | B16: 至2026年10月，计划上线总数51款，参与分账游戏33款。分成占比66%
A20: 云游戏CP分账成本
A21: 序号 | B21: 类目名称 | C21: 2026年8月 | D21: 9月 | E21: 10月 | F21: 11月 | G21: 12月 | H21: 2027年1月 | I21: 2月 | J21: 3月 | K21: 4月 | L21: 5月 | M21: 6月 | N21: 7月 | O21: 8月 | P21: 9月 | Q21: 10月 | R21: 11月 | S21: 12月 | T21: 合计
A22: 1 | B22: 收入（万元） | C22: 20 | D22: 20 | E22: 20 | F22: 20 | G22: 20 | H22: 20 | I22: 20 | J22: 20 | K22: 20 | L22: 20 | M22: 20 | N22: 20 | O22: 20 | P22: 20 | Q22: 20 | R22: 20 | S22: 20 | T22: =SUM(C22:S22) -> 340
A23: 2 | B23: 固定成本（万元） | C23: =81.66/12 -> 6.805 | D23: =81.66/12 -> 6.805 | E23: =81.66/12 -> 6.805 | F23: =81.66/12 -> 6.805 | G23: =81.66/12 -> 6.805 | H23: =81.66/12 -> 6.805 | I23: =81.66/12 -> 6.805 | J23: =81.66/12 -> 6.805 | ... S23: =81.66/12 -> 6.805 | T23: =SUM(C23:S23) -> 115.685
A24: 3 | B24: 订购用户数 | C24: 5000 | D24: 5000 | E24: 5000 | F24: 5000 | G24: 5000 | H24: 5000 | I24: 5000 | J24: 5000 | K24: 5000 | L24: 5000 | M24: 5000 | N24: 5000 | O24: 5000 | P24: 5000 | Q24: 5000 | R24: 5000 | S24: 5000
A25: 4 | B25: 包月单价（元） | C25: 29 | D25: 29 | E25: 29 | F25: 29 | G25: 29 | H25: 29 | I25: 29 | J25: 29 | K25: 29 | L25: 29 | M25: 29 | N25: 29 | O25: 29 | P25: 29 | Q25: 29 | R25: 29 | S25: 29
A26: 5 | B26: 订购收入（万元） | C26: =C24*C25/10000 -> 14.5 | D26: =D24*D25/10000 -> 14.5 | E26: =E24*E25/10000 -> 14.5 | F26: =F24*F25/10000 -> 14.5 | G26: =G24*G25/10000 -> 14.5 | H26: =H24*H25/10000 -> 14.5 | I26: =I24*I25/10000 -> 14.5 | J26: =J24*J25/10000 -> 14.5 | ... S26: =S24*S25/10000 -> 14.5 | T26: =SUM(C26:S26) -> 246.5
A27: 6 | B27: 结算基数（万元） | C27: =C26-C23 -> 7.695 | D27: =D26-D23 -> 7.695 | E27: =E26-E23 -> 7.695 | F27: =F26-F23 -> 7.695 | G27: =G26-G23 -> 7.695 | H27: =H26-H23 -> 7.695 | I27: =I26-I23 -> 7.695 | J27: =J26-J23 -> 7.695 | ... S27: =S26-S23 -> 7.695 | T27: =SUM(C27:S27) -> 130.815
A28: 7 | B28: CP分账比例 | C28: 0.5 | D28: 0.5 | E28: 0.5 | F28: 0.5 | G28: 0.5 | H28: 0.5 | I28: 0.5 | J28: 0.5 | K28: 0.5 | L28: 0.5 | M28: 0.5 | N28: 0.5 | O28: 0.5 | P28: 0.5 | Q28: 0.5 | R28: 0.5 | S28: 0.5
A29: 8 | B29: CP分成时长占比 | C29: 0.95 | D29: 0.95 | E29: 0.66 | F29: 0.66 | G29: 0.66 | H29: 0.66 | I29: 0.66 | J29: 0.66 | K29: 0.66 | L29: 0.66 | M29: 0.66 | N29: 0.66 | O29: 0.66 | P29: 0.66 | Q29: 0.66 | R29: 0.66 | S29: 0.66
A30: 9 | B30: CP分账成本（万元） | C30: =C27*C28*C29 -> 3.655125 | D30: =D27*D28*D29 -> 3.655125 | E30: =E27*E28*E29 -> 2.53935 | F30: =F27*F28*F29 -> 2.53935 | G30: =G27*G28*G29 -> 2.53935 | H30: =H27*H28*H29 -> 2.53935 | I30: =I27*I28*I29 -> 2.53935 | J30: =J27*J28*J29 -> 2.53935 | ... S30: =S27*S28*S29 -> 2.53935 | T30: =SUM(C30:S30) -> 45.4005
A31: 10 | B31: 百视通利润（万元） | C31: =C22-C23-C30 -> 9.539875 | D31: =D22-D23-D30 -> 9.539875 | E31: =E22-E23-E30 -> 10.65565 | F31: =F22-F23-F30 -> 10.65565 | G31: =G22-G23-G30 -> 10.65565 | H31: =H22-H23-H30 -> 10.65565 | I31: =I22-I23-I30 -> 10.65565 | J31: =J22-J23-J30 -> 10.65565 | ... S31: =S22-S23-S30 -> 10.65565 | T31: =SUM(C31:S31) -> 178.9145
A32: ※结算按5000用户保底订购数据情况测算
A33: 用户订购按包月29元为单价测算

Sheet 使用权资产（服务器）
C1: 日期 | D1: 租赁负债 | AB1: 使用权资产折旧 | AC1: 利息费用+折旧（万元）
A2: 本期资产负债表日 | B2: 下期资产负债表日 | D2: 期初余额(1) | E2: 期初余额(2) | F2: 期初余额(3) | G2: 期初余额(4) | H2: 期初余额(5) | I2: 期初余额 | J2: 租赁付款额(1) | K2: 利息费用(1) | L2: 租赁付款额(2) | M2: 利息费用(2) | N2: 租赁付款额(3) | O2: 利息费用(3) | P2: 租赁付款额(4) | Q2: 利息费用(4) | R2: 租赁付款额(5) | S2: 利息费用(5) | T2: 租赁付款额 | U2: 利息费用 | V2: 期末余额(1) | W2: 期末余额(2) | X2: 期末余额(3) | Y2: 期末余额(4) | Z2: 期末余额(5) | AA2: 期末余额
A3: =IF(([2]原始数据录入!$L$17-[2]租赁后续计量表!C3)>=0,1,0) -> 0 | B3: =IF(([2]原始数据录入!$L$18-[2]租赁后续计量表!C3)>=0,2,0) -> 0 | C3: =[2]租赁初始计量表!D40 -> 46235 | V3: 576208.63 | W3: 0 | X3: 0 | Y3: 0 | Z3: 0 | AA3: 576208.63
A4: =IF(([2]原始数据录入!$L$17-[2]租赁后续计量表!C4)>=0,1,0) -> 0 | B4: =IF(([2]原始数据录入!$L$18-[2]租赁后续计量表!C4)>=0,2,0) -> 0 | C4: =[2]租赁初始计量表!D41 -> 46265 | D4: =ROUND(V3,2) -> 576208.63 | E4: =ROUND(W3,2) -> 0 | F4: =ROUND(X3,2) -> 0 | G4: =ROUND(Y3,2) -> 0 | H4: =ROUND(Z3,2) -> 0 | I4: 576208.63 | J4: 34557.52 | K4: 1244.61 | L4: 0 | M4: 0 | N4: 0 | O4: 0 | P4: 0 | Q4: 0 | R4: 0 | S4: 0 | T4: 34557.52 | U4: 1244.61 | V4: 542895.72 | W4: 0 | X4: 0 | Y4: 0 | Z4: 0 | AA4: 542895.72 | AB4: 31290.68 | AC4: =(U4+AB4)/10000 -> 3.253529 | AD4: 3.253529
A5: =IF(([2]原始数据录入!$L$17-[2]租赁后续计量表!C5)>=0,1,0) -> 0 | B5: =IF(([2]原始数据录入!$L$18-[2]租赁后续计量表!C5)>=0,2,0) -> 0 | C5: =[2]租赁初始计量表!D42 -> 46295 | D5: =ROUND(V4,2) -> 542895.72 | E5: =ROUND(W4,2) -> 0 | F5: =ROUND(X4,2) -> 0 | G5: =ROUND(Y4,2) -> 0 | H5: =ROUND(Z4,2) -> 0 | I5: 542895.72 | J5: 34557.52 | K5: 1172.65 | L5: 0 | M5: 0 | N5: 0 | O5: 0 | P5: 0 | Q5: 0 | R5: 0 | S5: 0 | T5: 34557.52 | U5: 1172.65 | V5: 509510.85 | W5: 0 | X5: 0 | Y5: 0 | Z5: 0 | AA5: 509510.85 | AB5: 31290.68 | AC5: =(U5+AB5)/10000 -> 3.246333 | AD5: 3.246333
A6: =IF(([2]原始数据录入!$L$17-[2]租赁后续计量表!C6)>=0,1,0) -> 0 | B6: =IF(([2]原始数据录入!$L$18-[2]租赁后续计量表!C6)>=0,2,0) -> 0 | C6: =[2]租赁初始计量表!D43 -> 46326 | D6: =ROUND(V5,2) -> 509510.85 | E6: =ROUND(W5,2) -> 0 | F6: =ROUND(X5,2) -> 0 | G6: =ROUND(Y5,2) -> 0 | H6: =ROUND(Z5,2) -> 0 | I6: 509510.85 | J6: 34557.52 | K6: 1100.54 | L6: 0 | M6: 0 | N6: 0 | O6: 0 | P6: 0 | Q6: 0 | R6: 0 | S6: 0 | T6: 34557.52 | U6: 1100.54 | V6: 476053.87 | W6: 0 | X6: 0 | Y6: 0 | Z6: 0 | AA6: 476053.87 | AB6: 31290.68 | AC6: =(U6+AB6)/10000 -> 3.239122 | AD6: 3.239122
A7: =IF(([2]原始数据录入!$L$17-[2]租赁后续计量表!C7)>=0,1,0) -> 0 | B7: =IF(([2]原始数据录入!$L$18-[2]租赁后续计量表!C7)>=0,2,0) -> 0 | C7: =[2]租赁初始计量表!D44 -> 46356 | D7: =ROUND(V6,2) -> 476053.87 | E7: =ROUND(W6,2) -> 0 | F7: =ROUND(X6,2) -> 0 | G7: =ROUND(Y6,2) -> 0 | H7: =ROUND(Z6,2) -> 0 | I7: 476053.87 | J7: 34557.52 | K7: 1028.28 | L7: 0 | M7: 0 | N7: 0 | O7: 0 | P7: 0 | Q7: 0 | R7: 0 | S7: 0 | T7: 34557.52 | U7: 1028.28 | V7: 442524.63 | W7: 0 | X7: 0 | Y7: 0 | Z7: 0 | AA7: 442524.63 | AB7: 31290.68 | AC7: =(U7+AB7)/10000 -> 3.231896 | AD7: 3.231896
A8: =IF(([2]原始数据录入!$L$17-[2]租赁后续计量表!C8)>=0,1,0) -> 0 | B8: =IF(([2]原始数据录入!$L$18-[2]租赁后续计量表!C8)>=0,2,0) -> 0 | C8: =[2]租赁初始计量表!D45 -> 46387 | D8: =ROUND(V7,2) -> 442524.63 | E8: =ROUND(W7,2) -> 0 | F8: =ROUND(X7,2) -> 0 | G8: =ROUND(Y7,2) -> 0 | H8: =ROUND(Z7,2) -> 0 | I8: 442524.63 | J8: 34557.52 | K8: 955.85 | L8: 0 | M8: 0 | N8: 0 | O8: 0 | P8: 0 | Q8: 0 | R8: 0 | S8: 0 | T8: 34557.52 | U8: 955.85 | V8: 408922.96 | W8: 0 | X8: 0 | Y8: 0 | Z8: 0 | AA8: 408922.96 | AB8: 31290.68 | AC8: =(U8+AB8)/10000 -> 3.224653 | AD8: 3.224653
A9: =IF(([2]原始数据录入!$L$17-[2]租赁后续计量表!C9)>=0,1,0) -> 0 | B9: =IF(([2]原始数据录入!$L$18-[2]租赁后续计量表!C9)>=0,2,0) -> 0 | C9: =[2]租赁初始计量表!D46 -> 46418 | D9: =ROUND(V8,2) -> 408922.96 | E9: =ROUND(W8,2) -> 0 | F9: =ROUND(X8,2) -> 0 | G9: =ROUND(Y8,2) -> 0 | H9: =ROUND(Z8,2) -> 0 | I9: 408922.96 | J9: 34557.52 | K9: 883.27 | L9: 0 | M9: 0 | N9: 0 | O9: 0 | P9: 0 | Q9: 0 | R9: 0 | S9: 0 | T9: 34557.52 | U9: 883.27 | V9: 375248.71 | W9: 0 | X9: 0 | Y9: 0 | Z9: 0 | AA9: 375248.71 | AB9: 31290.68 | AC9: =(U9+AB9)/10000 -> 3.217395 | AD9: 3.217395
A10: =IF(([2]原始数据录入!$L$17-[2]租赁后续计量表!C10)>=0,1,0) -> 0 | B10: =IF(([2]原始数据录入!$L$18-[2]租赁后续计量表!C10)>=0,2,0) -> 0 | C10: =[2]租赁初始计量表!D47 -> 46446 | D10: =ROUND(V9,2) -> 375248.71 | E10: =ROUND(W9,2) -> 0 | F10: =ROUND(X9,2) -> 0 | G10: =ROUND(Y9,2) -> 0 | H10: =ROUND(Z9,2) -> 0 | I10: 375248.71 | J10: 34557.52 | K10: 810.54 | L10: 0 | M10: 0 | N10: 0 | O10: 0 | P10: 0 | Q10: 0 | R10: 0 | S10: 0 | T10: 34557.52 | U10: 810.54 | V10: 341501.73 | W10: 0 | X10: 0 | Y10: 0 | Z10: 0 | AA10: 341501.73 | AB10: 31290.68 | AC10: =(U10+AB10)/10000 -> 3.210122 | AD10: 3.210122
A11: =IF(([2]原始数据录入!$L$17-[2]租赁后续计量表!C11)>=0,1,0) -> 0 | B11: =IF(([2]原始数据录入!$L$18-[2]租赁后续计量表!C11)>=0,2,0) -> 0 | C11: =[2]租赁初始计量表!D48 -> 46477 | D11: =ROUND(V10,2) -> 341501.73 | E11: =ROUND(W10,2) -> 0 | F11: =ROUND(X10,2) -> 0 | G11: =ROUND(Y10,2) -> 0 | H11: =ROUND(Z10,2) -> 0 | I11: 341501.73 | J11: 34557.52 | K11: 737.64 | L11: 0 | M11: 0 | N11: 0 | O11: 0 | P11: 0 | Q11: 0 | R11: 0 | S11: 0 | T11: 34557.52 | U11: 737.64 | V11: 307681.85 | W11: 0 | X11: 0 | Y11: 0 | Z11: 0 | AA11: 307681.85 | AB11: 31290.68 | AC11: =(U11+AB11)/10000 -> 3.202832 | AD11: 3.202832
A12: =IF(([2]原始数据录入!$L$17-[2]租赁后续计量表!C12)>=0,1,0) -> 0 | B12: =IF(([2]原始数据录入!$L$18-[2]租赁后续计量表!C12)>=0,2,0) -> 0 | C12: =[2]租赁初始计量表!D49 -> 46507 | D12: =ROUND(V11,2) -> 307681.85 | E12: =ROUND(W11,2) -> 0 | F12: =ROUND(X11,2) -> 0 | G12: =ROUND(Y11,2) -> 0 | H12: =ROUND(Z11,2) -> 0 | I12: 307681.85 | J12: 34557.52 | K12: 664.59 | L12: 0 | M12: 0 | N12: 0 | O12: 0 | P12: 0 | Q12: 0 | R12: 0 | S12: 0 | T12: 34557.52 | U12: 664.59 | V12: 273788.92 | W12: 0 | X12: 0 | Y12: 0 | Z12: 0 | AA12: 273788.92 | AB12: 31290.68 | AC12: =(U12+AB12)/10000 -> 3.195527 | AD12: 3.195527
A13: =IF(([2]原始数据录入!$L$17-[2]租赁后续计量表!C13)>=0,1,0) -> 0 | B13: =IF(([2]原始数据录入!$L$18-[2]租赁后续计量表!C13)>=0,2,0) -> 0 | C13: =[2]租赁初始计量表!D50 -> 46538 | D13: =ROUND(V12,2) -> 273788.92 | E13: =ROUND(W12,2) -> 0 | F13: =ROUND(X12,2) -> 0 | G13: =ROUND(Y12,2) -> 0 | H13: =ROUND(Z12,2) -> 0 | I13: 273788.92 | J13: 34557.52 | K13: 591.38 | L13: 0 | M13: 0 | N13: 0 | O13: 0 | P13: 0 | Q13: 0 | R13: 0 | S13: 0 | T13: 34557.52 | U13: 591.38 | V13: 239822.78 | W13: 0 | X13: 0 | Y13: 0 | Z13: 0 | AA13: 239822.78 | AB13: 31290.68 | AC13: =(U13+AB13)/10000 -> 3.188206 | AD13: 3.188206
A14: =IF(([2]原始数据录入!$L$17-[2]租赁后续计量表!C14)>=0,1,0) -> 0 | B14: =IF(([2]原始数据录入!$L$18-[2]租赁后续计量表!C14)>=0,2,0) -> 0 | C14: =[2]租赁初始计量表!D51 -> 46568 | D14: =ROUND(V13,2) -> 239822.78 | E14: =ROUND(W13,2) -> 0 | F14: =ROUND(X13,2) -> 0 | G14: =ROUND(Y13,2) -> 0 | H14: =ROUND(Z13,2) -> 0 | I14: 239822.78 | J14: 34557.52 | K14: 518.02 | L14: 0 | M14: 0 | N14: 0 | O14: 0 | P14: 0 | Q14: 0 | R14: 0 | S14: 0 | T14: 34557.52 | U14: 518.02 | V14: 205783.28 | W14: 0 | X14: 0 | Y14: 0 | Z14: 0 | AA14: 205783.28 | AB14: 31290.68 | AC14: =(U14+AB14)/10000 -> 3.18087 | AD14: 3.18087
A15: =IF(([2]原始数据录入!$L$17-[2]租赁后续计量表!C15)>=0,1,0) -> 0 | B15: =IF(([2]原始数据录入!$L$18-[2]租赁后续计量表!C15)>=0,2,0) -> 0 | C15: =[2]租赁初始计量表!D52 -> 46599 | D15: =ROUND(V14,2) -> 205783.28 | E15: =ROUND(W14,2) -> 0 | F15: =ROUND(X14,2) -> 0 | G15: =ROUND(Y14,2) -> 0 | H15: =ROUND(Z14,2) -> 0 | I15: 205783.28 | J15: 34557.52 | K15: 444.49 | L15: 0 | M15: 0 | N15: 0 | O15: 0 | P15: 0 | Q15: 0 | R15: 0 | S15: 0 | T15: 34557.52 | U15: 444.49 | V15: 171670.25 | W15: 0 | X15: 0 | Y15: 0 | Z15: 0 | AA15: 171670.25 | AB15: 31290.68 | AC15: =(U15+AB15)/10000 -> 3.173517 | AD15: 3.173517
... A19: =IF(([2]原始数据录入!$L$17-[2]租赁后续计量表!C19)>=0,1,0) -> 0 | B19: =IF(([2]原始数据录入!$L$18-[2]租赁后续计量表!C19)>=0,2,0) -> 0 | C19: =[2]租赁初始计量表!D56 -> 46721 | D19: =ROUND(V18,2) -> 68888.42 | E19: =ROUND(W18,2) -> 0 | F19: =ROUND(X18,2) -> 0 | G19: =ROUND(Y18,2) -> 0 | H19: =ROUND(Z18,2) -> 0 | I19: 68888.42 | J19: 34557.52 | K19: 148.8 | L19: 0 | M19: 0 | N19: 0 | O19: 0 | P19: 0 | Q19: 0 | R19: 0 | S19: 0 | T19: 34557.52 | U19: 148.8 | V19: 34479.7 | W19: 0 | X19: 0 | Y19: 0 | Z19: 0 | AA19: 34479.7 | AB19: 31290.68 | AC19: =(U19+AB19)/10000 -> 3.143948 | AD19: 3.143948
A20: =IF(([2]原始数据录入!$L$17-[2]租赁后续计量表!C20)>=0,1,0) -> 0 | B20: =IF(([2]原始数据录入!$L$18-[2]租赁后续计量表!C20)>=0,2,0) -> 0 | C20: =[2]租赁初始计量表!D57 -> 46752 | D20: =ROUND(V19,2) -> 34479.7 | E20: =ROUND(W19,2) -> 0 | F20: =ROUND(X19,2) -> 0 | G20: =ROUND(Y19,2) -> 0 | H20: =ROUND(Z19,2) -> 0 | I20: 34479.7 | J20: 34557.52 | K20: 74.48 | L20: 0 | M20: 0 | N20: 0 | O20: 0 | P20: 0 | Q20: 0 | R20: 0 | S20: 0 | T20: 34557.52 | U20: =74.48-3.34 -> 71.14 | V20: -3.34 | W20: 0 | X20: 0 | Y20: 0 | Z20: 0 | AA20: 0 | AB20: 31290.68 | AC20: =(U20+AB20)/10000 -> 3.136182 | AD20: 3.136182

Sheet 租赁成本
A1: 云游戏配置方案（50路并发）租赁成本
A2: 序号 | B2: 设备名称 | C2: 规格 | D2: 数量 （台/套） | E2: 单价 （万元/年） | F2: 金额 （万元/年）
A3: 一 | B3: 硬件设备
A4: 1 | B4: PCFarm算力服务器（4U3卡） | C4: CPUI7/内存 32GB*2/显卡RTX4070/NVME 固态 1T/网卡10GbE*1/BMC带外*1 | D4: 20 | E4: 1.98 | F4: =D4*E4 -> 39.6
A5: 2 | B5: 游戏管理及存储服务器 | C5: CPU金牌 6130 *2/内存32*2GB/系统盘 256G SATA SSD*2 raid1 /数据盘 3.84T SSD*6 raid5/网卡10GbE*2/冗余双电 | D5: 3 | E5: 1.008 | F5: =D5*E5 -> 3.024
A6: 3 | B6: 接入交换机 | C6: 48*10G光+6*40G光 | D6: 2 | E6: 0.18 | F6: =D6*E6 -> 0.36
A7: 4 | B7: 带外接入交换机 | C7: 48*1G电+4*10G光 | D7: 2 | E7: 0.126 | F7: =D7*E7 -> 0.252
A8: 5 | B8: 代理服务器 | C8: Intel Xeon Silver 4310*1/64GB DDR4 ECC/480GB SATA SSD*2 raid1/ 双端口万兆（10GE）光口 | D8: 2 | E8: 0.18 | F8: =D8*E8 -> 0.36
A9: 6 | B9: 防火墙 | C9: ＞10G吞吐量 | D9: 2 | E9: 0.6 | F9: =D9*E9 -> 1.2
A10: 7 | B10: 网络辅材 | C10: 40G光模块\10G光模块\光纤跳纤\算力跳线 | D10: 60 | E10: 0.0144 | F10: =D10*E10 -> 0.864
A11: 二 | B11: 设备安装
A12: 1 | B12: 设备安装费用 | C12: 一次性上架安装费用 | D12: 1 | E12: 1.2 | F12: =D12*E12 -> 1.2
A13: 三 | B13: IDC 机架租赁费用 | C13: 规格 | D13: 数量 | E13: 机架租赁单价（万元/年） | F13: 机架租赁金额 （万元/年）
A14: 1 | B14: 机柜 | C14: 5000W 20A 标准机柜 | D14: 4 | E14: 6 | F14: =D14*E14 -> 24
A15: 四 | B15: 网络及带宽费用 | C15: 规格 | D15: 数量 | E15: 网络及带宽费用单价 （万元/年） | F15: 网络及带宽费用 （万元）
A16: 1 | B16: 专网带宽 | C16: 2GB主备 | D16: 0 | E16: 0 | F16: 0
A17: 2 | B17: 互联网宽带 | C17: 100M独享 | D17: 1 | E17: 3.6 | F17: =D17*E17 -> 3.6
A18: 五 | B18: 软件购置费 | D18: 数量（套） | E18: 单价（万元/年） | F18: 金额（万元/年）
A19: 1 | B19: 云渲染软件 | C19: 游戏云化软件 | D19: 60 | E19: 0.06 | F19: =D19*E19 -> 3.6
A20: 六 | B20: 管理费用 | D20: 数量（套） | E20: 单价（万元/年） | F20: 金额（万元/年）
A21: 1 | B21: 硬件维护费用 | C21: 硬件维护、安全防护 | D21: 60 | E21: 0.06 | F21: =D21*E21 -> 3.6
B23: 合计 | F23: =SUM(F4:F21) -> 81.66

Sheet 采购成本（参考）
A1: 云游戏配置方案（50路并发）采购成本
A2: 序号 | B2: 设备名称 | C2: 规格 | D2: 数量 （台/套） | E2: 单价 （万元） | F2: 金额 （万元）
A3: 一 | B3: 硬件设备
A4: 1 | B4: PCFarm算力服务器（4U3卡） | C4: CPUI7/内存 32GB*2/显卡RTX4070/NVME 固态 1T/网卡10GbE*1/BMC带外*1 | D4: 20 | E4: 5.873868 | F4: =D4*E4 -> 117.47736
A5: 2 | B5: 游戏管理及存储服务器 | C5: CPU金牌 6130 *2/内存32*2GB/系统盘 256G SATA SSD*2 raid1 /数据盘 3.84T SSD*6 raid5/网卡10GbE*2/冗余双电 | D5: 3 | E5: 5.04 | F5: =D5*E5 -> 15.12
A6: 3 | B6: 接入交换机 | C6: 48*10G光+6*40G光 | D6: 2 | E6: 1.6 | F6: =D6*E6 -> 3.2
A7: 4 | B7: 带外接入交换机 | C7: 48*1G电+4*10G光 | D7: 2 | E7: 1.2 | F7: =D7*E7 -> 2.4
A8: 5 | B8: 代理服务器 | C8: Intel Xeon Silver 4310*1/64GB DDR4 ECC/480GB SATA SSD*2 raid1/ 双端口万兆（10GE）光口 | D8: 2 | E8: 3.25 | F8: =D8*E8 -> 6.5
A9: 6 | B9: 防火墙 | C9: ＞10G吞吐量 | D9: 2 | E9: 5 | F9: =D9*E9 -> 10
A10: 7 | B10: 网络辅材 | C10: 40G光模块\10G光模块\光纤跳纤\算力跳线 | D10: 60 | E10: 0.036 | F10: =D10*E10 -> 2.16
A11: 二 | B11: 设备安装
A12: 1 | B12: 设备安装费用 | C12: 一次性上架安装费用 | D12: 1 | E12: 1.2 | F12: =D12*E12 -> 1.2
A13: 三 | B13: IDC 机架租赁费用 | C13: 规格 | D13: 数量 | E13: 机架租赁单价 （万元/年） | F13: 机架租赁金额 （万元/年）
A14: 1 | B14: 机柜 | C14: 5000W 20A 标准机柜 | D14: 4 | E14: 6 | F14: =D14*E14 -> 24
A15: 四 | B15: 网络及带宽费用 | C15: 规格 | D15: 数量 | E15: 网络及带宽费用单价 （万元/年） | F15: 网络及带宽费用 （万元/年）
A16: 1 | B16: 专网带宽 | C16: 2GB主备 | D16: 0 | E16: 0 | F16: 0
A17: 2 | B17: 互联网宽带 | C17: 200M独享 | D17: 1 | E17: 3.6 | F17: =D17*E17 -> 3.6
A18: 五 | B18: 软件购置费 | D18: 数量（套） | E18: 单价（万元/年） | F18: 金额（万元/年）
A19: 1 | B19: 云渲染软件 | C19: 游戏云化软件 | D19: 60 | E19: 0.06 | F19: =D19*E19 -> 3.6
A20: 六 | B20: 管理费用 | D20: 数量（套） | E20: 单价（万元/年） | F20: 金额（万元/年）
A21: 1 | B21: 硬件维护费用 | C21: 硬件维护、安全防护 | D21: 60 | E21: 0.06 | F21: =D21*E21 -> 3.6
B23: 合计 | F23: =SUM(F4:F21) -> 192.85736
